{"schema": {"openapi": "3.0.0", "info": {"description": "This is a sample Petstore server.  You can find\nout more about Swagger at\n[http://swagger.io](http://swagger.io) or on\n[irc.freenode.net, #swagger](http://swagger.io/irc/).\n", "version": "1.0.0", "title": "Swagger Petstore", "termsOfService": "http://swagger.io/terms/", "contact": {"email": "apiteam@swagger.io"}, "license": {"name": "Apache 2.0", "url": "http://www.apache.org/licenses/LICENSE-2.0.html"}}, "servers": [{"description": "SwaggerHub API Auto Mocking", "url": "https://virtserver.swaggerhub.com/AAYUSHGARGBU/api_petstore/1.0.0"}, {"url": "https://petstore.swagger.io/v2"}], "tags": [{"name": "pet", "description": "Everything about your Pets", "externalDocs": {"description": "Find out more", "url": "http://swagger.io"}}, {"name": "store", "description": "Access to Petstore orders"}, {"name": "user", "description": "Operations about user", "externalDocs": {"description": "Find out more about our store", "url": "http://swagger.io"}}], "paths": {"/pet": {"post": {"tags": ["pet"], "summary": "Add a new pet to the store", "operationId": "addPet", "responses": {"405": {"description": "Invalid input"}}, "security": [{"petstore_auth": ["write:pets", "read:pets"]}], "requestBody": {"$ref": "#/components/requestBodies/Pet"}}, "put": {"tags": ["pet"], "summary": "Update an existing pet", "operationId": "updatePet", "responses": {"400": {"description": "Invalid ID supplied"}, "404": {"description": "Pet not found"}, "405": {"description": "Validation exception"}}, "security": [{"petstore_auth": ["write:pets", "read:pets"]}], "requestBody": {"$ref": "#/components/requestBodies/Pet"}}}, "/pet/findByStatus": {"get": {"tags": ["pet"], "summary": "Finds Pets by status", "description": "Multiple status values can be provided with comma separated strings", "operationId": "findPetsByStatus", "parameters": [{"name": "status", "in": "query", "description": "Status values that need to be considered for filter", "required": true, "explode": true, "schema": {"type": "array", "items": {"type": "string", "enum": ["available", "pending", "sold"], "default": "available"}}}], "responses": {"200": {"description": "successful operation", "content": {"application/json": {"schema": {"type": "array", "items": {"$ref": "#/components/schemas/Pet"}}}, "application/xml": {"schema": {"type": "array", "items": {"$ref": "#/components/schemas/Pet"}}}}}, "400": {"description": "Invalid status value"}}, "security": [{"petstore_auth": ["write:pets", "read:pets"]}]}}, "/pet/findByTags": {"get": {"tags": ["pet"], "summary": "Finds Pets by tags", "description": "Muliple tags can be provided with comma separated strings. Use\\ \\ tag1, tag2, tag3 for testing.", "operationId": "findPetsByTags", "parameters": [{"name": "tags", "in": "query", "description": "Tags to filter by", "required": true, "explode": true, "schema": {"type": "array", "items": {"type": "string"}}}], "responses": {"200": {"description": "successful operation", "content": {"application/json": {"schema": {"type": "array", "items": {"$ref": "#/components/schemas/Pet"}}}, "application/xml": {"schema": {"type": "array", "items": {"$ref": "#/components/schemas/Pet"}}}}}, "400": {"description": "Invalid tag value"}}, "security": [{"petstore_auth": ["write:pets", "read:pets"]}], "deprecated": true}}, "/pet/{petId}": {"get": {"tags": ["pet"], "summary": "Find pet by ID", "description": "Returns a single pet", "operationId": "getPetById", "parameters": [{"name": "petId", "in": "path", "description": "ID of pet to return", "required": true, "schema": {"type": "integer", "format": "int64"}}], "responses": {"200": {"description": "successful operation", "content": {"application/json": {"schema": {"$ref": "#/components/schemas/Pet"}}, "application/xml": {"schema": {"$ref": "#/components/schemas/Pet"}}}}, "400": {"description": "Invalid ID supplied"}, "404": {"description": "Pet not found"}}, "security": [{"api_key": []}]}, "post": {"tags": ["pet"], "summary": "Updates a pet in the store with form data", "operationId": "updatePetWithForm", "parameters": [{"name": "petId", "in": "path", "description": "ID of pet that needs to be updated", "required": true, "schema": {"type": "integer", "format": "int64"}}], "responses": {"405": {"description": "Invalid input"}}, "security": [{"petstore_auth": ["write:pets", "read:pets"]}], "requestBody": {"content": {"application/x-www-form-urlencoded": {"schema": {"type": "object", "properties": {"name": {"description": "Updated name of the pet", "type": "string"}, "status": {"description": "Updated status of the pet", "type": "string"}}}}}}}, "delete": {"tags": ["pet"], "summary": "Deletes a pet", "operationId": "deletePet", "parameters": [{"name": "api_key", "in": "header", "required": false, "schema": {"type": "string"}}, {"name": "petId", "in": "path", "description": "Pet id to delete", "required": true, "schema": {"type": "integer", "format": "int64"}}], "responses": {"400": {"description": "Invalid ID supplied"}, "404": {"description": "Pet not found"}}, "security": [{"petstore_auth": ["write:pets", "read:pets"]}]}}, "/pet/{petId}/uploadImage": {"post": {"tags": ["pet"], "summary": "uploads an image", "operationId": "uploadFile", "parameters": [{"name": "petId", "in": "path", "description": "ID of pet to update", "required": true, "schema": {"type": "integer", "format": "int64"}}], "responses": {"200": {"description": "successful operation", "content": {"application/json": {"schema": {"$ref": "#/components/schemas/ApiResponse"}}}}}, "security": [{"petstore_auth": ["write:pets", "read:pets"]}], "requestBody": {"content": {"application/octet-stream": {"schema": {"type": "string", "format": "binary"}}}}}}, "/store/inventory": {"get": {"tags": ["store"], "summary": "Returns pet inventories by status", "description": "Returns a map of status codes to quantities", "operationId": "getInventory", "responses": {"200": {"description": "successful operation", "content": {"application/json": {"schema": {"type": "object", "additionalProperties": {"type": "integer", "format": "int32"}}}}}}, "security": [{"api_key": []}]}}, "/store/order": {"post": {"tags": ["store"], "summary": "Place an order for a pet", "operationId": "placeOrder", "responses": {"200": {"description": "successful operation", "content": {"application/json": {"schema": {"$ref": "#/components/schemas/Order"}}, "application/xml": {"schema": {"$ref": "#/components/schemas/Order"}}}}, "400": {"description": "Invalid Order"}}, "requestBody": {"content": {"application/json": {"schema": {"$ref": "#/components/schemas/Order"}}}, "description": "order placed for purchasing the pet", "required": true}}}, "/store/order/{orderId}": {"get": {"tags": ["store"], "summary": "Find purchase order by ID", "description": "For valid response try integer IDs with value >= 1 and <= 10.\\ \\ Other values will generated exceptions", "operationId": "getOrderById", "parameters": [{"name": "orderId", "in": "path", "description": "ID of pet that needs to be fetched", "required": true, "schema": {"type": "integer", "format": "int64", "minimum": 1, "maximum": 10}}], "responses": {"200": {"description": "successful operation", "content": {"application/json": {"schema": {"$ref": "#/components/schemas/Order"}}, "application/xml": {"schema": {"$ref": "#/components/schemas/Order"}}}}, "400": {"description": "Invalid ID supplied"}, "404": {"description": "Order not found"}}}, "delete": {"tags": ["store"], "summary": "Delete purchase order by ID", "description": "For valid response try integer IDs with positive integer value.\\ \\ Negative or non-integer values will generate API errors", "operationId": "deleteOrder", "parameters": [{"name": "orderId", "in": "path", "description": "ID of the order that needs to be deleted", "required": true, "schema": {"type": "integer", "format": "int64", "minimum": 1}}], "responses": {"400": {"description": "Invalid ID supplied"}, "404": {"description": "Order not found"}}}}, "/user": {"post": {"tags": ["user"], "summary": "Create user", "description": "This can only be done by the logged in user.", "operationId": "createUser", "responses": {"default": {"description": "successful operation"}}, "requestBody": {"content": {"application/json": {"schema": {"$ref": "#/components/schemas/User"}}}, "description": "Created user object", "required": true}}}, "/user/createWithArray": {"post": {"tags": ["user"], "summary": "Creates list of users with given input array", "operationId": "createUsersWithArrayInput", "responses": {"default": {"description": "successful operation"}}, "requestBody": {"$ref": "#/components/requestBodies/UserArray"}}}, "/user/createWithList": {"post": {"tags": ["user"], "summary": "Creates list of users with given input array", "operationId": "createUsersWithListInput", "responses": {"default": {"description": "successful operation"}}, "requestBody": {"$ref": "#/components/requestBodies/UserArray"}}}, "/user/login": {"get": {"tags": ["user"], "summary": "Logs user into the system", "operationId": "loginUser", "parameters": [{"name": "username", "in": "query", "description": "The user name for login", "required": true, "schema": {"type": "string"}}, {"name": "password", "in": "query", "description": "The password for login in clear text", "required": true, "schema": {"type": "string"}}], "responses": {"200": {"description": "successful operation", "headers": {"X-Rate-Limit": {"description": "calls per hour allowed by the user", "schema": {"type": "integer", "format": "int32"}}, "X-Expires-After": {"description": "date in UTC when token expires", "schema": {"type": "string", "format": "date-time"}}}, "content": {"application/json": {"schema": {"type": "string"}}, "application/xml": {"schema": {"type": "string"}}}}, "400": {"description": "Invalid username/password supplied"}}}}, "/user/logout": {"get": {"tags": ["user"], "summary": "Logs out current logged in user session", "operationId": "logoutUser", "responses": {"default": {"description": "successful operation"}}}}, "/user/{username}": {"get": {"tags": ["user"], "summary": "Get user by user name", "operationId": "getUserByName", "parameters": [{"name": "username", "in": "path", "description": "The name that needs to be fetched. Use user1 for testing.", "required": true, "schema": {"type": "string"}}], "responses": {"200": {"description": "successful operation", "content": {"application/json": {"schema": {"$ref": "#/components/schemas/User"}}, "application/xml": {"schema": {"$ref": "#/components/schemas/User"}}}}, "400": {"description": "Invalid username supplied"}, "404": {"description": "User not found"}}}, "put": {"tags": ["user"], "summary": "Updated user", "description": "This can only be done by the logged in user.", "operationId": "updateUser", "parameters": [{"name": "username", "in": "path", "description": "name that need to be updated", "required": true, "schema": {"type": "string"}}], "responses": {"400": {"description": "Invalid user supplied"}, "404": {"description": "User not found"}}, "requestBody": {"content": {"application/json": {"schema": {"$ref": "#/components/schemas/User"}}}, "description": "Updated user object", "required": true}}, "delete": {"tags": ["user"], "summary": "Delete user", "description": "This can only be done by the logged in user.", "operationId": "deleteUser", "parameters": [{"name": "username", "in": "path", "description": "The name that needs to be deleted", "required": true, "schema": {"type": "string"}}], "responses": {"400": {"description": "Invalid username supplied"}, "404": {"description": "User not found"}}}}}, "externalDocs": {"description": "Find out more about Swagger", "url": "http://swagger.io"}, "components": {"schemas": {"Order": {"type": "object", "properties": {"id": {"type": "integer", "format": "int64"}, "petId": {"type": "integer", "format": "int64"}, "quantity": {"type": "integer", "format": "int32"}, "shipDate": {"type": "string", "format": "date-time"}, "status": {"type": "string", "description": "Order Status", "enum": ["placed", "approved", "delivered"]}, "complete": {"type": "boolean", "default": false}}, "xml": {"name": "Order"}}, "Category": {"type": "object", "properties": {"id": {"type": "integer", "format": "int64"}, "name": {"type": "string"}}, "xml": {"name": "Category"}}, "User": {"type": "object", "properties": {"id": {"type": "integer", "format": "int64"}, "username": {"type": "string"}, "firstName": {"type": "string"}, "lastName": {"type": "string"}, "email": {"type": "string"}, "password": {"type": "string"}, "phone": {"type": "string"}, "userStatus": {"type": "integer", "format": "int32", "description": "User Status"}}, "xml": {"name": "User"}}, "Tag": {"type": "object", "properties": {"id": {"type": "integer", "format": "int64"}, "name": {"type": "string"}}, "xml": {"name": "Tag"}}, "Pet": {"type": "object", "required": ["name", "photoUrls"], "properties": {"id": {"type": "integer", "format": "int64"}, "category": {"$ref": "#/components/schemas/Category"}, "name": {"type": "string", "example": "doggie"}, "photoUrls": {"type": "array", "xml": {"name": "photoUrl", "wrapped": true}, "items": {"type": "string"}}, "tags": {"type": "array", "xml": {"name": "tag", "wrapped": true}, "items": {"$ref": "#/components/schemas/Tag"}}, "status": {"type": "string", "description": "pet status in the store", "enum": ["available", "pending", "sold"]}}, "xml": {"name": "Pet"}}, "ApiResponse": {"type": "object", "properties": {"code": {"type": "integer", "format": "int32"}, "type": {"type": "string"}, "message": {"type": "string"}}}}, "requestBodies": {"Pet": {"content": {"application/json": {"schema": {"$ref": "#/components/schemas/Pet"}}, "application/xml": {"schema": {"$ref": "#/components/schemas/Pet"}}}, "description": "Pet object that needs to be added to the store", "required": true}, "UserArray": {"content": {"application/json": {"schema": {"type": "array", "items": {"$ref": "#/components/schemas/User"}}}}, "description": "List of user object", "required": true}}, "securitySchemes": {"petstore_auth": {"type": "oauth2", "flows": {"implicit": {"authorizationUrl": "http://petstore.swagger.io/oauth/dialog", "scopes": {"write:pets": "modify pets in your account", "read:pets": "read your pets"}}}}, "api_key": {"type": "apiKey", "name": "api_key", "in": "header"}}}}, "operations_count": 20, "links_count": 0, "location": "file:///mnt/d/ag/github/lazarus_target_apis/data/api_petstore/api_petstore.json", "seed": 57932623809996008151663850801588433753, "base_url": "https://virtserver.swaggerhub.com/AAYUSHGARGBU/api_petstore/1.0.0", "specification_name": "Open API 3.0.0", "start_time": 553910.5441962, "started_at": "2024-05-28T10:18:09.624363+02:00", "thread_id": 140638996727616, "event_type": "Initialized"}
{"event_type": "BeforeProbing"}
{"probes": [{"name": "NULL_BYTE_IN_HEADER", "outcome": "error", "request": {"method": "GET", "uri": "https://virtserver.swaggerhub.com/AAYUSHGARGBU/api_petstore/1.0.0", "body": null, "headers": {"User-Agent": ["schemathesis/3.27.1"], "Accept-Encoding": ["gzip, deflate"], "Accept": ["*/*"], "Connection": ["keep-alive"], "X-Schemathesis-Probe-Null": ["\u0000"], "X-Schemathesis-Probe": ["NULL_BYTE_IN_HEADER"]}}, "response": null, "error": "requests.exceptions.ConnectionError: HTTPSConnectionPool(host='virtserver.swaggerhub.com', port=443): Max retries exceeded with url: /AAYUSHGARGBU/api_petstore/1.0.0 (Caused by NewConnectionError('<urllib3.connection.VerifiedHTTPSConnection object at 0x7fe90e915a90>: Failed to establish a new connection: [Errno -3] Temporary failure in name resolution'))"}], "events_type": "AfterProbing"}
{"event_type": "BeforeAnalysis"}
{"analysis": null, "event_type": "AfterAnalysis"}
{"method": "POST", "path": "/AAYUSHGARGBU/api_petstore/1.0.0/pet", "verbose_name": "POST /AAYUSHGARGBU/api_petstore/1.0.0/pet", "relative_path": "/pet", "recursion_level": 0, "data_generation_method": ["positive", "negative"], "correlation_id": "816fea1fd68f4da2a3b7b7d6f765b794", "thread_id": 140638996727616, "event_type": "BeforeExecution"}
{"method": "POST", "path": "/AAYUSHGARGBU/api_petstore/1.0.0/pet", "relative_path": "/pet", "verbose_name": "POST /AAYUSHGARGBU/api_petstore/1.0.0/pet", "status": "error", "data_generation_method": ["positive"], "result": {"method": "POST", "path": "/AAYUSHGARGBU/api_petstore/1.0.0/pet", "verbose_name": "POST /AAYUSHGARGBU/api_petstore/1.0.0/pet", "has_failures": false, "has_errors": true, "has_logs": false, "is_errored": false, "is_flaky": false, "is_skipped": false, "skip_reason": null, "seed": 57932623809996008151663850801588433753, "data_generation_method": ["P"], "checks": [], "logs": [], "errors": [{"type": "connection_other", "title": "Network Error", "message": "Connection failed", "extras": ["Failed to establish a new connection: [Errno -3] Temporary failure in name resolution"], "exception": "requests.exceptions.ConnectionError: HTTPSConnectionPool(host='virtserver.swaggerhub.com', port=443): Max retries exceeded with url: /AAYUSHGARGBU/api_petstore/1.0.0/pet (Caused by NewConnectionError('<urllib3.connection.VerifiedHTTPSConnection object at 0x7fe90e8444f0>: Failed to establish a new connection: [Errno -3] Temporary failure in name resolution'))", "exception_with_traceback": "Traceback (most recent call last):\n  File \"/usr/lib/python3/dist-packages/urllib3/connection.py\", line 156, in _new_conn\n    conn = connection.create_connection(\n  File \"/usr/lib/python3/dist-packages/urllib3/util/connection.py\", line 61, in create_connection\n    for res in socket.getaddrinfo(host, port, family, socket.SOCK_STREAM):\n  File \"/usr/lib/python3.8/socket.py\", line 918, in getaddrinfo\n    for res in _socket.getaddrinfo(host, port, family, type, proto, flags):\nsocket.gaierror: [Errno -3] Temporary failure in name resolution\n\nDuring handling of the above exception, another exception occurred:\n\nTraceback (most recent call last):\n  File \"/usr/lib/python3/dist-packages/urllib3/connectionpool.py\", line 665, in urlopen\n    httplib_response = self._make_request(\n  File \"/usr/lib/python3/dist-packages/urllib3/connectionpool.py\", line 376, in _make_request\n    self._validate_conn(conn)\n  File \"/usr/lib/python3/dist-packages/urllib3/connectionpool.py\", line 996, in _validate_conn\n    conn.connect()\n  File \"/usr/lib/python3/dist-packages/urllib3/connection.py\", line 300, in connect\n    conn = self._new_conn()\n  File \"/usr/lib/python3/dist-packages/urllib3/connection.py\", line 168, in _new_conn\n    raise NewConnectionError(\nurllib3.exceptions.NewConnectionError: <urllib3.connection.VerifiedHTTPSConnection object at 0x7fe90e8444f0>: Failed to establish a new connection: [Errno -3] Temporary failure in name resolution\n\nDuring handling of the above exception, another exception occurred:\n\nTraceback (most recent call last):\n  File \"/usr/local/lib/python3.8/dist-packages/requests/adapters.py\", line 486, in send\n    resp = conn.urlopen(\n  File \"/usr/lib/python3/dist-packages/urllib3/connectionpool.py\", line 719, in urlopen\n    retries = retries.increment(\n  File \"/usr/lib/python3/dist-packages/urllib3/util/retry.py\", line 436, in increment\n    raise MaxRetryError(_pool, url, error or ResponseError(cause))\nurllib3.exceptions.MaxRetryError: HTTPSConnectionPool(host='virtserver.swaggerhub.com', port=443): Max retries exceeded with url: /AAYUSHGARGBU/api_petstore/1.0.0/pet (Caused by NewConnectionError('<urllib3.connection.VerifiedHTTPSConnection object at 0x7fe90e8444f0>: Failed to establish a new connection: [Errno -3] Temporary failure in name resolution'))\n\nDuring handling of the above exception, another exception occurred:\n\nTraceback (most recent call last):\n  File \"/usr/local/lib/python3.8/dist-packages/schemathesis/runner/impl/core.py\", line 816, in network_test\n    response = _network_test(case, *args)\n  File \"/usr/local/lib/python3.8/dist-packages/schemathesis/runner/impl/core.py\", line 848, in _network_test\n    response = case.call(**kwargs)\n  File \"/usr/local/lib/python3.8/dist-packages/schemathesis/models.py\", line 310, in call\n    response = self.operation.schema.transport.send(\n  File \"/usr/local/lib/python3.8/dist-packages/schemathesis/transports/__init__.py\", line 143, in send\n    response = session.request(**data)  # type: ignore\n  File \"/usr/local/lib/python3.8/dist-packages/requests/sessions.py\", line 589, in request\n    resp = self.send(prep, **send_kwargs)\n  File \"/usr/local/lib/python3.8/dist-packages/requests/sessions.py\", line 703, in send\n    r = adapter.send(request, **kwargs)\n  File \"/usr/local/lib/python3.8/dist-packages/requests/adapters.py\", line 519, in send\n    raise ConnectionError(e, request=request)\nrequests.exceptions.ConnectionError: HTTPSConnectionPool(host='virtserver.swaggerhub.com', port=443): Max retries exceeded with url: /AAYUSHGARGBU/api_petstore/1.0.0/pet (Caused by NewConnectionError('<urllib3.connection.VerifiedHTTPSConnection object at 0x7fe90e8444f0>: Failed to establish a new connection: [Errno -3] Temporary failure in name resolution'))"}], "interactions": []}, "elapsed_time": 44.05695340002421, "correlation_id": "816fea1fd68f4da2a3b7b7d6f765b794", "thread_id": 140638996727616, "hypothesis_output": [], "event_type": "AfterExecution"}
{"method": "PUT", "path": "/AAYUSHGARGBU/api_petstore/1.0.0/pet", "verbose_name": "PUT /AAYUSHGARGBU/api_petstore/1.0.0/pet", "relative_path": "/pet", "recursion_level": 0, "data_generation_method": ["positive", "negative"], "correlation_id": "50ebee5a0e304048be48c64186c72c44", "thread_id": 140638996727616, "event_type": "BeforeExecution"}
{"method": "PUT", "path": "/AAYUSHGARGBU/api_petstore/1.0.0/pet", "relative_path": "/pet", "verbose_name": "PUT /AAYUSHGARGBU/api_petstore/1.0.0/pet", "status": "error", "data_generation_method": ["positive"], "result": {"method": "PUT", "path": "/AAYUSHGARGBU/api_petstore/1.0.0/pet", "verbose_name": "PUT /AAYUSHGARGBU/api_petstore/1.0.0/pet", "has_failures": false, "has_errors": true, "has_logs": false, "is_errored": false, "is_flaky": false, "is_skipped": false, "skip_reason": null, "seed": 57932623809996008151663850801588433753, "data_generation_method": ["P"], "checks": [], "logs": [], "errors": [{"type": "connection_other", "title": "Network Error", "message": "Connection failed", "extras": ["Failed to establish a new connection: [Errno -3] Temporary failure in name resolution"], "exception": "requests.exceptions.ConnectionError: HTTPSConnectionPool(host='virtserver.swaggerhub.com', port=443): Max retries exceeded with url: /AAYUSHGARGBU/api_petstore/1.0.0/pet (Caused by NewConnectionError('<urllib3.connection.VerifiedHTTPSConnection object at 0x7fe90e86d700>: Failed to establish a new connection: [Errno -3] Temporary failure in name resolution'))", "exception_with_traceback": "Traceback (most recent call last):\n  File \"/usr/lib/python3/dist-packages/urllib3/connection.py\", line 156, in _new_conn\n    conn = connection.create_connection(\n  File \"/usr/lib/python3/dist-packages/urllib3/util/connection.py\", line 61, in create_connection\n    for res in socket.getaddrinfo(host, port, family, socket.SOCK_STREAM):\n  File \"/usr/lib/python3.8/socket.py\", line 918, in getaddrinfo\n    for res in _socket.getaddrinfo(host, port, family, type, proto, flags):\nsocket.gaierror: [Errno -3] Temporary failure in name resolution\n\nDuring handling of the above exception, another exception occurred:\n\nTraceback (most recent call last):\n  File \"/usr/lib/python3/dist-packages/urllib3/connectionpool.py\", line 665, in urlopen\n    httplib_response = self._make_request(\n  File \"/usr/lib/python3/dist-packages/urllib3/connectionpool.py\", line 376, in _make_request\n    self._validate_conn(conn)\n  File \"/usr/lib/python3/dist-packages/urllib3/connectionpool.py\", line 996, in _validate_conn\n    conn.connect()\n  File \"/usr/lib/python3/dist-packages/urllib3/connection.py\", line 300, in connect\n    conn = self._new_conn()\n  File \"/usr/lib/python3/dist-packages/urllib3/connection.py\", line 168, in _new_conn\n    raise NewConnectionError(\nurllib3.exceptions.NewConnectionError: <urllib3.connection.VerifiedHTTPSConnection object at 0x7fe90e86d700>: Failed to establish a new connection: [Errno -3] Temporary failure in name resolution\n\nDuring handling of the above exception, another exception occurred:\n\nTraceback (most recent call last):\n  File \"/usr/local/lib/python3.8/dist-packages/requests/adapters.py\", line 486, in send\n    resp = conn.urlopen(\n  File \"/usr/lib/python3/dist-packages/urllib3/connectionpool.py\", line 719, in urlopen\n    retries = retries.increment(\n  File \"/usr/lib/python3/dist-packages/urllib3/util/retry.py\", line 436, in increment\n    raise MaxRetryError(_pool, url, error or ResponseError(cause))\nurllib3.exceptions.MaxRetryError: HTTPSConnectionPool(host='virtserver.swaggerhub.com', port=443): Max retries exceeded with url: /AAYUSHGARGBU/api_petstore/1.0.0/pet (Caused by NewConnectionError('<urllib3.connection.VerifiedHTTPSConnection object at 0x7fe90e86d700>: Failed to establish a new connection: [Errno -3] Temporary failure in name resolution'))\n\nDuring handling of the above exception, another exception occurred:\n\nTraceback (most recent call last):\n  File \"/usr/local/lib/python3.8/dist-packages/schemathesis/runner/impl/core.py\", line 816, in network_test\n    response = _network_test(case, *args)\n  File \"/usr/local/lib/python3.8/dist-packages/schemathesis/runner/impl/core.py\", line 848, in _network_test\n    response = case.call(**kwargs)\n  File \"/usr/local/lib/python3.8/dist-packages/schemathesis/models.py\", line 310, in call\n    response = self.operation.schema.transport.send(\n  File \"/usr/local/lib/python3.8/dist-packages/schemathesis/transports/__init__.py\", line 143, in send\n    response = session.request(**data)  # type: ignore\n  File \"/usr/local/lib/python3.8/dist-packages/requests/sessions.py\", line 589, in request\n    resp = self.send(prep, **send_kwargs)\n  File \"/usr/local/lib/python3.8/dist-packages/requests/sessions.py\", line 703, in send\n    r = adapter.send(request, **kwargs)\n  File \"/usr/local/lib/python3.8/dist-packages/requests/adapters.py\", line 519, in send\n    raise ConnectionError(e, request=request)\nrequests.exceptions.ConnectionError: HTTPSConnectionPool(host='virtserver.swaggerhub.com', port=443): Max retries exceeded with url: /AAYUSHGARGBU/api_petstore/1.0.0/pet (Caused by NewConnectionError('<urllib3.connection.VerifiedHTTPSConnection object at 0x7fe90e86d700>: Failed to establish a new connection: [Errno -3] Temporary failure in name resolution'))"}], "interactions": []}, "elapsed_time": 44.017900999984704, "correlation_id": "50ebee5a0e304048be48c64186c72c44", "thread_id": 140638996727616, "hypothesis_output": [], "event_type": "AfterExecution"}
{"method": "GET", "path": "/AAYUSHGARGBU/api_petstore/1.0.0/pet/findByStatus", "verbose_name": "GET /AAYUSHGARGBU/api_petstore/1.0.0/pet/findByStatus", "relative_path": "/pet/findByStatus", "recursion_level": 0, "data_generation_method": ["positive", "negative"], "correlation_id": "b8087ff872364cbf87dc040c33c0dc58", "thread_id": 140638996727616, "event_type": "BeforeExecution"}
{"method": "GET", "path": "/AAYUSHGARGBU/api_petstore/1.0.0/pet/findByStatus", "relative_path": "/pet/findByStatus", "verbose_name": "GET /AAYUSHGARGBU/api_petstore/1.0.0/pet/findByStatus", "status": "error", "data_generation_method": ["positive"], "result": {"method": "GET", "path": "/AAYUSHGARGBU/api_petstore/1.0.0/pet/findByStatus", "verbose_name": "GET /AAYUSHGARGBU/api_petstore/1.0.0/pet/findByStatus", "has_failures": false, "has_errors": true, "has_logs": false, "is_errored": true, "is_flaky": false, "is_skipped": false, "skip_reason": null, "seed": 57932623809996008151663850801588433753, "data_generation_method": ["P"], "checks": [], "logs": [], "errors": [{"type": "connection_other", "title": "Network Error", "message": "Connection failed", "extras": ["Failed to establish a new connection: [Errno -3] Temporary failure in name resolution"], "exception": "requests.exceptions.ConnectionError: HTTPSConnectionPool(host='virtserver.swaggerhub.com', port=443): Max retries exceeded with url: /AAYUSHGARGBU/api_petstore/1.0.0/pet/findByStatus (Caused by NewConnectionError('<urllib3.connection.VerifiedHTTPSConnection object at 0x7fe90e749100>: Failed to establish a new connection: [Errno -3] Temporary failure in name resolution'))", "exception_with_traceback": "Traceback (most recent call last):\n  File \"/usr/lib/python3/dist-packages/urllib3/connection.py\", line 156, in _new_conn\n    conn = connection.create_connection(\n  File \"/usr/lib/python3/dist-packages/urllib3/util/connection.py\", line 61, in create_connection\n    for res in socket.getaddrinfo(host, port, family, socket.SOCK_STREAM):\n  File \"/usr/lib/python3.8/socket.py\", line 918, in getaddrinfo\n    for res in _socket.getaddrinfo(host, port, family, type, proto, flags):\nsocket.gaierror: [Errno -3] Temporary failure in name resolution\n\nDuring handling of the above exception, another exception occurred:\n\nTraceback (most recent call last):\n  File \"/usr/lib/python3/dist-packages/urllib3/connectionpool.py\", line 665, in urlopen\n    httplib_response = self._make_request(\n  File \"/usr/lib/python3/dist-packages/urllib3/connectionpool.py\", line 376, in _make_request\n    self._validate_conn(conn)\n  File \"/usr/lib/python3/dist-packages/urllib3/connectionpool.py\", line 996, in _validate_conn\n    conn.connect()\n  File \"/usr/lib/python3/dist-packages/urllib3/connection.py\", line 300, in connect\n    conn = self._new_conn()\n  File \"/usr/lib/python3/dist-packages/urllib3/connection.py\", line 168, in _new_conn\n    raise NewConnectionError(\nurllib3.exceptions.NewConnectionError: <urllib3.connection.VerifiedHTTPSConnection object at 0x7fe90e749100>: Failed to establish a new connection: [Errno -3] Temporary failure in name resolution\n\nDuring handling of the above exception, another exception occurred:\n\nTraceback (most recent call last):\n  File \"/usr/local/lib/python3.8/dist-packages/requests/adapters.py\", line 486, in send\n    resp = conn.urlopen(\n  File \"/usr/lib/python3/dist-packages/urllib3/connectionpool.py\", line 719, in urlopen\n    retries = retries.increment(\n  File \"/usr/lib/python3/dist-packages/urllib3/util/retry.py\", line 436, in increment\n    raise MaxRetryError(_pool, url, error or ResponseError(cause))\nurllib3.exceptions.MaxRetryError: HTTPSConnectionPool(host='virtserver.swaggerhub.com', port=443): Max retries exceeded with url: /AAYUSHGARGBU/api_petstore/1.0.0/pet/findByStatus (Caused by NewConnectionError('<urllib3.connection.VerifiedHTTPSConnection object at 0x7fe90e749100>: Failed to establish a new connection: [Errno -3] Temporary failure in name resolution'))\n\nDuring handling of the above exception, another exception occurred:\n\nTraceback (most recent call last):\n  File \"/usr/local/lib/python3.8/dist-packages/schemathesis/runner/impl/core.py\", line 816, in network_test\n    response = _network_test(case, *args)\n  File \"/usr/local/lib/python3.8/dist-packages/schemathesis/runner/impl/core.py\", line 848, in _network_test\n    response = case.call(**kwargs)\n  File \"/usr/local/lib/python3.8/dist-packages/schemathesis/models.py\", line 310, in call\n    response = self.operation.schema.transport.send(\n  File \"/usr/local/lib/python3.8/dist-packages/schemathesis/transports/__init__.py\", line 143, in send\n    response = session.request(**data)  # type: ignore\n  File \"/usr/local/lib/python3.8/dist-packages/requests/sessions.py\", line 589, in request\n    resp = self.send(prep, **send_kwargs)\n  File \"/usr/local/lib/python3.8/dist-packages/requests/sessions.py\", line 703, in send\n    r = adapter.send(request, **kwargs)\n  File \"/usr/local/lib/python3.8/dist-packages/requests/adapters.py\", line 519, in send\n    raise ConnectionError(e, request=request)\nrequests.exceptions.ConnectionError: HTTPSConnectionPool(host='virtserver.swaggerhub.com', port=443): Max retries exceeded with url: /AAYUSHGARGBU/api_petstore/1.0.0/pet/findByStatus (Caused by NewConnectionError('<urllib3.connection.VerifiedHTTPSConnection object at 0x7fe90e749100>: Failed to establish a new connection: [Errno -3] Temporary failure in name resolution'))"}], "interactions": []}, "elapsed_time": 132.08625940000638, "correlation_id": "b8087ff872364cbf87dc040c33c0dc58", "thread_id": 140638996727616, "hypothesis_output": [], "event_type": "AfterExecution"}
{"method": "GET", "path": "/AAYUSHGARGBU/api_petstore/1.0.0/pet/findByTags", "verbose_name": "GET /AAYUSHGARGBU/api_petstore/1.0.0/pet/findByTags", "relative_path": "/pet/findByTags", "recursion_level": 0, "data_generation_method": ["positive", "negative"], "correlation_id": "7e2518ab43c64e7ead141774354df363", "thread_id": 140638996727616, "event_type": "BeforeExecution"}
{"method": "GET", "path": "/AAYUSHGARGBU/api_petstore/1.0.0/pet/findByTags", "relative_path": "/pet/findByTags", "verbose_name": "GET /AAYUSHGARGBU/api_petstore/1.0.0/pet/findByTags", "status": "error", "data_generation_method": ["positive"], "result": {"method": "GET", "path": "/AAYUSHGARGBU/api_petstore/1.0.0/pet/findByTags", "verbose_name": "GET /AAYUSHGARGBU/api_petstore/1.0.0/pet/findByTags", "has_failures": false, "has_errors": true, "has_logs": false, "is_errored": true, "is_flaky": false, "is_skipped": false, "skip_reason": null, "seed": 57932623809996008151663850801588433753, "data_generation_method": ["P"], "checks": [], "logs": [], "errors": [{"type": "connection_other", "title": "Network Error", "message": "Connection failed", "extras": ["Failed to establish a new connection: [Errno -3] Temporary failure in name resolution"], "exception": "requests.exceptions.ConnectionError: HTTPSConnectionPool(host='virtserver.swaggerhub.com', port=443): Max retries exceeded with url: /AAYUSHGARGBU/api_petstore/1.0.0/pet/findByTags (Caused by NewConnectionError('<urllib3.connection.VerifiedHTTPSConnection object at 0x7fe90e710c40>: Failed to establish a new connection: [Errno -3] Temporary failure in name resolution'))", "exception_with_traceback": "Traceback (most recent call last):\n  File \"/usr/lib/python3/dist-packages/urllib3/connection.py\", line 156, in _new_conn\n    conn = connection.create_connection(\n  File \"/usr/lib/python3/dist-packages/urllib3/util/connection.py\", line 61, in create_connection\n    for res in socket.getaddrinfo(host, port, family, socket.SOCK_STREAM):\n  File \"/usr/lib/python3.8/socket.py\", line 918, in getaddrinfo\n    for res in _socket.getaddrinfo(host, port, family, type, proto, flags):\nsocket.gaierror: [Errno -3] Temporary failure in name resolution\n\nDuring handling of the above exception, another exception occurred:\n\nTraceback (most recent call last):\n  File \"/usr/lib/python3/dist-packages/urllib3/connectionpool.py\", line 665, in urlopen\n    httplib_response = self._make_request(\n  File \"/usr/lib/python3/dist-packages/urllib3/connectionpool.py\", line 376, in _make_request\n    self._validate_conn(conn)\n  File \"/usr/lib/python3/dist-packages/urllib3/connectionpool.py\", line 996, in _validate_conn\n    conn.connect()\n  File \"/usr/lib/python3/dist-packages/urllib3/connection.py\", line 300, in connect\n    conn = self._new_conn()\n  File \"/usr/lib/python3/dist-packages/urllib3/connection.py\", line 168, in _new_conn\n    raise NewConnectionError(\nurllib3.exceptions.NewConnectionError: <urllib3.connection.VerifiedHTTPSConnection object at 0x7fe90e710c40>: Failed to establish a new connection: [Errno -3] Temporary failure in name resolution\n\nDuring handling of the above exception, another exception occurred:\n\nTraceback (most recent call last):\n  File \"/usr/local/lib/python3.8/dist-packages/requests/adapters.py\", line 486, in send\n    resp = conn.urlopen(\n  File \"/usr/lib/python3/dist-packages/urllib3/connectionpool.py\", line 719, in urlopen\n    retries = retries.increment(\n  File \"/usr/lib/python3/dist-packages/urllib3/util/retry.py\", line 436, in increment\n    raise MaxRetryError(_pool, url, error or ResponseError(cause))\nurllib3.exceptions.MaxRetryError: HTTPSConnectionPool(host='virtserver.swaggerhub.com', port=443): Max retries exceeded with url: /AAYUSHGARGBU/api_petstore/1.0.0/pet/findByTags (Caused by NewConnectionError('<urllib3.connection.VerifiedHTTPSConnection object at 0x7fe90e710c40>: Failed to establish a new connection: [Errno -3] Temporary failure in name resolution'))\n\nDuring handling of the above exception, another exception occurred:\n\nTraceback (most recent call last):\n  File \"/usr/local/lib/python3.8/dist-packages/schemathesis/runner/impl/core.py\", line 816, in network_test\n    response = _network_test(case, *args)\n  File \"/usr/local/lib/python3.8/dist-packages/schemathesis/runner/impl/core.py\", line 848, in _network_test\n    response = case.call(**kwargs)\n  File \"/usr/local/lib/python3.8/dist-packages/schemathesis/models.py\", line 310, in call\n    response = self.operation.schema.transport.send(\n  File \"/usr/local/lib/python3.8/dist-packages/schemathesis/transports/__init__.py\", line 143, in send\n    response = session.request(**data)  # type: ignore\n  File \"/usr/local/lib/python3.8/dist-packages/requests/sessions.py\", line 589, in request\n    resp = self.send(prep, **send_kwargs)\n  File \"/usr/local/lib/python3.8/dist-packages/requests/sessions.py\", line 703, in send\n    r = adapter.send(request, **kwargs)\n  File \"/usr/local/lib/python3.8/dist-packages/requests/adapters.py\", line 519, in send\n    raise ConnectionError(e, request=request)\nrequests.exceptions.ConnectionError: HTTPSConnectionPool(host='virtserver.swaggerhub.com', port=443): Max retries exceeded with url: /AAYUSHGARGBU/api_petstore/1.0.0/pet/findByTags (Caused by NewConnectionError('<urllib3.connection.VerifiedHTTPSConnection object at 0x7fe90e710c40>: Failed to establish a new connection: [Errno -3] Temporary failure in name resolution'))"}], "interactions": []}, "elapsed_time": 154.1068368999986, "correlation_id": "7e2518ab43c64e7ead141774354df363", "thread_id": 140638996727616, "hypothesis_output": [], "event_type": "AfterExecution"}
{"method": "GET", "path": "/AAYUSHGARGBU/api_petstore/1.0.0/pet/{petId}", "verbose_name": "GET /AAYUSHGARGBU/api_petstore/1.0.0/pet/{petId}", "relative_path": "/pet/{petId}", "recursion_level": 0, "data_generation_method": ["positive", "negative"], "correlation_id": "51c8c902b72f4941818e83bf128ea3fe", "thread_id": 140638996727616, "event_type": "BeforeExecution"}
{"method": "GET", "path": "/AAYUSHGARGBU/api_petstore/1.0.0/pet/{petId}", "relative_path": "/pet/{petId}", "verbose_name": "GET /AAYUSHGARGBU/api_petstore/1.0.0/pet/{petId}", "status": "error", "data_generation_method": ["positive"], "result": {"method": "GET", "path": "/AAYUSHGARGBU/api_petstore/1.0.0/pet/{petId}", "verbose_name": "GET /AAYUSHGARGBU/api_petstore/1.0.0/pet/{petId}", "has_failures": false, "has_errors": true, "has_logs": false, "is_errored": true, "is_flaky": false, "is_skipped": false, "skip_reason": null, "seed": 57932623809996008151663850801588433753, "data_generation_method": ["P"], "checks": [], "logs": [], "errors": [{"type": "connection_other", "title": "Network Error", "message": "Connection failed", "extras": ["Failed to establish a new connection: [Errno -3] Temporary failure in name resolution"], "exception": "requests.exceptions.ConnectionError: HTTPSConnectionPool(host='virtserver.swaggerhub.com', port=443): Max retries exceeded with url: /AAYUSHGARGBU/api_petstore/1.0.0/pet/0 (Caused by NewConnectionError('<urllib3.connection.VerifiedHTTPSConnection object at 0x7fe90e6ee670>: Failed to establish a new connection: [Errno -3] Temporary failure in name resolution'))", "exception_with_traceback": "Traceback (most recent call last):\n  File \"/usr/lib/python3/dist-packages/urllib3/connection.py\", line 156, in _new_conn\n    conn = connection.create_connection(\n  File \"/usr/lib/python3/dist-packages/urllib3/util/connection.py\", line 61, in create_connection\n    for res in socket.getaddrinfo(host, port, family, socket.SOCK_STREAM):\n  File \"/usr/lib/python3.8/socket.py\", line 918, in getaddrinfo\n    for res in _socket.getaddrinfo(host, port, family, type, proto, flags):\nsocket.gaierror: [Errno -3] Temporary failure in name resolution\n\nDuring handling of the above exception, another exception occurred:\n\nTraceback (most recent call last):\n  File \"/usr/lib/python3/dist-packages/urllib3/connectionpool.py\", line 665, in urlopen\n    httplib_response = self._make_request(\n  File \"/usr/lib/python3/dist-packages/urllib3/connectionpool.py\", line 376, in _make_request\n    self._validate_conn(conn)\n  File \"/usr/lib/python3/dist-packages/urllib3/connectionpool.py\", line 996, in _validate_conn\n    conn.connect()\n  File \"/usr/lib/python3/dist-packages/urllib3/connection.py\", line 300, in connect\n    conn = self._new_conn()\n  File \"/usr/lib/python3/dist-packages/urllib3/connection.py\", line 168, in _new_conn\n    raise NewConnectionError(\nurllib3.exceptions.NewConnectionError: <urllib3.connection.VerifiedHTTPSConnection object at 0x7fe90e6ee670>: Failed to establish a new connection: [Errno -3] Temporary failure in name resolution\n\nDuring handling of the above exception, another exception occurred:\n\nTraceback (most recent call last):\n  File \"/usr/local/lib/python3.8/dist-packages/requests/adapters.py\", line 486, in send\n    resp = conn.urlopen(\n  File \"/usr/lib/python3/dist-packages/urllib3/connectionpool.py\", line 719, in urlopen\n    retries = retries.increment(\n  File \"/usr/lib/python3/dist-packages/urllib3/util/retry.py\", line 436, in increment\n    raise MaxRetryError(_pool, url, error or ResponseError(cause))\nurllib3.exceptions.MaxRetryError: HTTPSConnectionPool(host='virtserver.swaggerhub.com', port=443): Max retries exceeded with url: /AAYUSHGARGBU/api_petstore/1.0.0/pet/0 (Caused by NewConnectionError('<urllib3.connection.VerifiedHTTPSConnection object at 0x7fe90e6ee670>: Failed to establish a new connection: [Errno -3] Temporary failure in name resolution'))\n\nDuring handling of the above exception, another exception occurred:\n\nTraceback (most recent call last):\n  File \"/usr/local/lib/python3.8/dist-packages/schemathesis/runner/impl/core.py\", line 816, in network_test\n    response = _network_test(case, *args)\n  File \"/usr/local/lib/python3.8/dist-packages/schemathesis/runner/impl/core.py\", line 848, in _network_test\n    response = case.call(**kwargs)\n  File \"/usr/local/lib/python3.8/dist-packages/schemathesis/models.py\", line 310, in call\n    response = self.operation.schema.transport.send(\n  File \"/usr/local/lib/python3.8/dist-packages/schemathesis/transports/__init__.py\", line 143, in send\n    response = session.request(**data)  # type: ignore\n  File \"/usr/local/lib/python3.8/dist-packages/requests/sessions.py\", line 589, in request\n    resp = self.send(prep, **send_kwargs)\n  File \"/usr/local/lib/python3.8/dist-packages/requests/sessions.py\", line 703, in send\n    r = adapter.send(request, **kwargs)\n  File \"/usr/local/lib/python3.8/dist-packages/requests/adapters.py\", line 519, in send\n    raise ConnectionError(e, request=request)\nrequests.exceptions.ConnectionError: HTTPSConnectionPool(host='virtserver.swaggerhub.com', port=443): Max retries exceeded with url: /AAYUSHGARGBU/api_petstore/1.0.0/pet/0 (Caused by NewConnectionError('<urllib3.connection.VerifiedHTTPSConnection object at 0x7fe90e6ee670>: Failed to establish a new connection: [Errno -3] Temporary failure in name resolution'))"}], "interactions": []}, "elapsed_time": 88.06289649999235, "correlation_id": "51c8c902b72f4941818e83bf128ea3fe", "thread_id": 140638996727616, "hypothesis_output": [], "event_type": "AfterExecution"}
{"method": "POST", "path": "/AAYUSHGARGBU/api_petstore/1.0.0/pet/{petId}", "verbose_name": "POST /AAYUSHGARGBU/api_petstore/1.0.0/pet/{petId}", "relative_path": "/pet/{petId}", "recursion_level": 0, "data_generation_method": ["positive", "negative"], "correlation_id": "13fd5c5585d248279e52f0013c162715", "thread_id": 140638996727616, "event_type": "BeforeExecution"}
{"method": "POST", "path": "/AAYUSHGARGBU/api_petstore/1.0.0/pet/{petId}", "relative_path": "/pet/{petId}", "verbose_name": "POST /AAYUSHGARGBU/api_petstore/1.0.0/pet/{petId}", "status": "error", "data_generation_method": ["positive"], "result": {"method": "POST", "path": "/AAYUSHGARGBU/api_petstore/1.0.0/pet/{petId}", "verbose_name": "POST /AAYUSHGARGBU/api_petstore/1.0.0/pet/{petId}", "has_failures": false, "has_errors": true, "has_logs": false, "is_errored": true, "is_flaky": false, "is_skipped": false, "skip_reason": null, "seed": 57932623809996008151663850801588433753, "data_generation_method": ["P"], "checks": [], "logs": [], "errors": [{"type": "connection_other", "title": "Network Error", "message": "Connection failed", "extras": ["Failed to establish a new connection: [Errno -3] Temporary failure in name resolution"], "exception": "requests.exceptions.ConnectionError: HTTPSConnectionPool(host='virtserver.swaggerhub.com', port=443): Max retries exceeded with url: /AAYUSHGARGBU/api_petstore/1.0.0/pet/0 (Caused by NewConnectionError('<urllib3.connection.VerifiedHTTPSConnection object at 0x7fe90e696be0>: Failed to establish a new connection: [Errno -3] Temporary failure in name resolution'))", "exception_with_traceback": "Traceback (most recent call last):\n  File \"/usr/lib/python3/dist-packages/urllib3/connection.py\", line 156, in _new_conn\n    conn = connection.create_connection(\n  File \"/usr/lib/python3/dist-packages/urllib3/util/connection.py\", line 61, in create_connection\n    for res in socket.getaddrinfo(host, port, family, socket.SOCK_STREAM):\n  File \"/usr/lib/python3.8/socket.py\", line 918, in getaddrinfo\n    for res in _socket.getaddrinfo(host, port, family, type, proto, flags):\nsocket.gaierror: [Errno -3] Temporary failure in name resolution\n\nDuring handling of the above exception, another exception occurred:\n\nTraceback (most recent call last):\n  File \"/usr/lib/python3/dist-packages/urllib3/connectionpool.py\", line 665, in urlopen\n    httplib_response = self._make_request(\n  File \"/usr/lib/python3/dist-packages/urllib3/connectionpool.py\", line 376, in _make_request\n    self._validate_conn(conn)\n  File \"/usr/lib/python3/dist-packages/urllib3/connectionpool.py\", line 996, in _validate_conn\n    conn.connect()\n  File \"/usr/lib/python3/dist-packages/urllib3/connection.py\", line 300, in connect\n    conn = self._new_conn()\n  File \"/usr/lib/python3/dist-packages/urllib3/connection.py\", line 168, in _new_conn\n    raise NewConnectionError(\nurllib3.exceptions.NewConnectionError: <urllib3.connection.VerifiedHTTPSConnection object at 0x7fe90e696be0>: Failed to establish a new connection: [Errno -3] Temporary failure in name resolution\n\nDuring handling of the above exception, another exception occurred:\n\nTraceback (most recent call last):\n  File \"/usr/local/lib/python3.8/dist-packages/requests/adapters.py\", line 486, in send\n    resp = conn.urlopen(\n  File \"/usr/lib/python3/dist-packages/urllib3/connectionpool.py\", line 719, in urlopen\n    retries = retries.increment(\n  File \"/usr/lib/python3/dist-packages/urllib3/util/retry.py\", line 436, in increment\n    raise MaxRetryError(_pool, url, error or ResponseError(cause))\nurllib3.exceptions.MaxRetryError: HTTPSConnectionPool(host='virtserver.swaggerhub.com', port=443): Max retries exceeded with url: /AAYUSHGARGBU/api_petstore/1.0.0/pet/0 (Caused by NewConnectionError('<urllib3.connection.VerifiedHTTPSConnection object at 0x7fe90e696be0>: Failed to establish a new connection: [Errno -3] Temporary failure in name resolution'))\n\nDuring handling of the above exception, another exception occurred:\n\nTraceback (most recent call last):\n  File \"/usr/local/lib/python3.8/dist-packages/schemathesis/runner/impl/core.py\", line 816, in network_test\n    response = _network_test(case, *args)\n  File \"/usr/local/lib/python3.8/dist-packages/schemathesis/runner/impl/core.py\", line 848, in _network_test\n    response = case.call(**kwargs)\n  File \"/usr/local/lib/python3.8/dist-packages/schemathesis/models.py\", line 310, in call\n    response = self.operation.schema.transport.send(\n  File \"/usr/local/lib/python3.8/dist-packages/schemathesis/transports/__init__.py\", line 143, in send\n    response = session.request(**data)  # type: ignore\n  File \"/usr/local/lib/python3.8/dist-packages/requests/sessions.py\", line 589, in request\n    resp = self.send(prep, **send_kwargs)\n  File \"/usr/local/lib/python3.8/dist-packages/requests/sessions.py\", line 703, in send\n    r = adapter.send(request, **kwargs)\n  File \"/usr/local/lib/python3.8/dist-packages/requests/adapters.py\", line 519, in send\n    raise ConnectionError(e, request=request)\nrequests.exceptions.ConnectionError: HTTPSConnectionPool(host='virtserver.swaggerhub.com', port=443): Max retries exceeded with url: /AAYUSHGARGBU/api_petstore/1.0.0/pet/0 (Caused by NewConnectionError('<urllib3.connection.VerifiedHTTPSConnection object at 0x7fe90e696be0>: Failed to establish a new connection: [Errno -3] Temporary failure in name resolution'))"}], "interactions": []}, "elapsed_time": 176.116527199978, "correlation_id": "13fd5c5585d248279e52f0013c162715", "thread_id": 140638996727616, "hypothesis_output": [], "event_type": "AfterExecution"}
{"method": "DELETE", "path": "/AAYUSHGARGBU/api_petstore/1.0.0/pet/{petId}", "verbose_name": "DELETE /AAYUSHGARGBU/api_petstore/1.0.0/pet/{petId}", "relative_path": "/pet/{petId}", "recursion_level": 0, "data_generation_method": ["positive", "negative"], "correlation_id": "8972402533264bbea1f5684105e78698", "thread_id": 140638996727616, "event_type": "BeforeExecution"}
{"method": "DELETE", "path": "/AAYUSHGARGBU/api_petstore/1.0.0/pet/{petId}", "relative_path": "/pet/{petId}", "verbose_name": "DELETE /AAYUSHGARGBU/api_petstore/1.0.0/pet/{petId}", "status": "error", "data_generation_method": ["positive"], "result": {"method": "DELETE", "path": "/AAYUSHGARGBU/api_petstore/1.0.0/pet/{petId}", "verbose_name": "DELETE /AAYUSHGARGBU/api_petstore/1.0.0/pet/{petId}", "has_failures": false, "has_errors": true, "has_logs": false, "is_errored": true, "is_flaky": false, "is_skipped": false, "skip_reason": null, "seed": 57932623809996008151663850801588433753, "data_generation_method": ["P"], "checks": [], "logs": [], "errors": [{"type": "connection_other", "title": "Network Error", "message": "Connection failed", "extras": ["Failed to establish a new connection: [Errno -3] Temporary failure in name resolution"], "exception": "requests.exceptions.ConnectionError: HTTPSConnectionPool(host='virtserver.swaggerhub.com', port=443): Max retries exceeded with url: /AAYUSHGARGBU/api_petstore/1.0.0/pet/0 (Caused by NewConnectionError('<urllib3.connection.VerifiedHTTPSConnection object at 0x7fe90e605be0>: Failed to establish a new connection: [Errno -3] Temporary failure in name resolution'))", "exception_with_traceback": "Traceback (most recent call last):\n  File \"/usr/lib/python3/dist-packages/urllib3/connection.py\", line 156, in _new_conn\n    conn = connection.create_connection(\n  File \"/usr/lib/python3/dist-packages/urllib3/util/connection.py\", line 61, in create_connection\n    for res in socket.getaddrinfo(host, port, family, socket.SOCK_STREAM):\n  File \"/usr/lib/python3.8/socket.py\", line 918, in getaddrinfo\n    for res in _socket.getaddrinfo(host, port, family, type, proto, flags):\nsocket.gaierror: [Errno -3] Temporary failure in name resolution\n\nDuring handling of the above exception, another exception occurred:\n\nTraceback (most recent call last):\n  File \"/usr/lib/python3/dist-packages/urllib3/connectionpool.py\", line 665, in urlopen\n    httplib_response = self._make_request(\n  File \"/usr/lib/python3/dist-packages/urllib3/connectionpool.py\", line 376, in _make_request\n    self._validate_conn(conn)\n  File \"/usr/lib/python3/dist-packages/urllib3/connectionpool.py\", line 996, in _validate_conn\n    conn.connect()\n  File \"/usr/lib/python3/dist-packages/urllib3/connection.py\", line 300, in connect\n    conn = self._new_conn()\n  File \"/usr/lib/python3/dist-packages/urllib3/connection.py\", line 168, in _new_conn\n    raise NewConnectionError(\nurllib3.exceptions.NewConnectionError: <urllib3.connection.VerifiedHTTPSConnection object at 0x7fe90e605be0>: Failed to establish a new connection: [Errno -3] Temporary failure in name resolution\n\nDuring handling of the above exception, another exception occurred:\n\nTraceback (most recent call last):\n  File \"/usr/local/lib/python3.8/dist-packages/requests/adapters.py\", line 486, in send\n    resp = conn.urlopen(\n  File \"/usr/lib/python3/dist-packages/urllib3/connectionpool.py\", line 719, in urlopen\n    retries = retries.increment(\n  File \"/usr/lib/python3/dist-packages/urllib3/util/retry.py\", line 436, in increment\n    raise MaxRetryError(_pool, url, error or ResponseError(cause))\nurllib3.exceptions.MaxRetryError: HTTPSConnectionPool(host='virtserver.swaggerhub.com', port=443): Max retries exceeded with url: /AAYUSHGARGBU/api_petstore/1.0.0/pet/0 (Caused by NewConnectionError('<urllib3.connection.VerifiedHTTPSConnection object at 0x7fe90e605be0>: Failed to establish a new connection: [Errno -3] Temporary failure in name resolution'))\n\nDuring handling of the above exception, another exception occurred:\n\nTraceback (most recent call last):\n  File \"/usr/local/lib/python3.8/dist-packages/schemathesis/runner/impl/core.py\", line 816, in network_test\n    response = _network_test(case, *args)\n  File \"/usr/local/lib/python3.8/dist-packages/schemathesis/runner/impl/core.py\", line 848, in _network_test\n    response = case.call(**kwargs)\n  File \"/usr/local/lib/python3.8/dist-packages/schemathesis/models.py\", line 310, in call\n    response = self.operation.schema.transport.send(\n  File \"/usr/local/lib/python3.8/dist-packages/schemathesis/transports/__init__.py\", line 143, in send\n    response = session.request(**data)  # type: ignore\n  File \"/usr/local/lib/python3.8/dist-packages/requests/sessions.py\", line 589, in request\n    resp = self.send(prep, **send_kwargs)\n  File \"/usr/local/lib/python3.8/dist-packages/requests/sessions.py\", line 703, in send\n    r = adapter.send(request, **kwargs)\n  File \"/usr/local/lib/python3.8/dist-packages/requests/adapters.py\", line 519, in send\n    raise ConnectionError(e, request=request)\nrequests.exceptions.ConnectionError: HTTPSConnectionPool(host='virtserver.swaggerhub.com', port=443): Max retries exceeded with url: /AAYUSHGARGBU/api_petstore/1.0.0/pet/0 (Caused by NewConnectionError('<urllib3.connection.VerifiedHTTPSConnection object at 0x7fe90e605be0>: Failed to establish a new connection: [Errno -3] Temporary failure in name resolution'))"}], "interactions": []}, "elapsed_time": 88.05647039995529, "correlation_id": "8972402533264bbea1f5684105e78698", "thread_id": 140638996727616, "hypothesis_output": [], "event_type": "AfterExecution"}
{"method": "POST", "path": "/AAYUSHGARGBU/api_petstore/1.0.0/pet/{petId}/uploadImage", "verbose_name": "POST /AAYUSHGARGBU/api_petstore/1.0.0/pet/{petId}/uploadImage", "relative_path": "/pet/{petId}/uploadImage", "recursion_level": 0, "data_generation_method": ["positive", "negative"], "correlation_id": "3f646dd2858c49f6b176cbbbd89d7685", "thread_id": 140638996727616, "event_type": "BeforeExecution"}
{"method": "POST", "path": "/AAYUSHGARGBU/api_petstore/1.0.0/pet/{petId}/uploadImage", "relative_path": "/pet/{petId}/uploadImage", "verbose_name": "POST /AAYUSHGARGBU/api_petstore/1.0.0/pet/{petId}/uploadImage", "status": "error", "data_generation_method": ["positive"], "result": {"method": "POST", "path": "/AAYUSHGARGBU/api_petstore/1.0.0/pet/{petId}/uploadImage", "verbose_name": "POST /AAYUSHGARGBU/api_petstore/1.0.0/pet/{petId}/uploadImage", "has_failures": false, "has_errors": true, "has_logs": false, "is_errored": true, "is_flaky": false, "is_skipped": false, "skip_reason": null, "seed": 57932623809996008151663850801588433753, "data_generation_method": ["P"], "checks": [], "logs": [], "errors": [{"type": "connection_other", "title": "Network Error", "message": "Connection failed", "extras": ["Failed to establish a new connection: [Errno -3] Temporary failure in name resolution"], "exception": "requests.exceptions.ConnectionError: HTTPSConnectionPool(host='virtserver.swaggerhub.com', port=443): Max retries exceeded with url: /AAYUSHGARGBU/api_petstore/1.0.0/pet/0/uploadImage (Caused by NewConnectionError('<urllib3.connection.VerifiedHTTPSConnection object at 0x7fe90e5bd5e0>: Failed to establish a new connection: [Errno -3] Temporary failure in name resolution'))", "exception_with_traceback": "Traceback (most recent call last):\n  File \"/usr/lib/python3/dist-packages/urllib3/connection.py\", line 156, in _new_conn\n    conn = connection.create_connection(\n  File \"/usr/lib/python3/dist-packages/urllib3/util/connection.py\", line 61, in create_connection\n    for res in socket.getaddrinfo(host, port, family, socket.SOCK_STREAM):\n  File \"/usr/lib/python3.8/socket.py\", line 918, in getaddrinfo\n    for res in _socket.getaddrinfo(host, port, family, type, proto, flags):\nsocket.gaierror: [Errno -3] Temporary failure in name resolution\n\nDuring handling of the above exception, another exception occurred:\n\nTraceback (most recent call last):\n  File \"/usr/lib/python3/dist-packages/urllib3/connectionpool.py\", line 665, in urlopen\n    httplib_response = self._make_request(\n  File \"/usr/lib/python3/dist-packages/urllib3/connectionpool.py\", line 376, in _make_request\n    self._validate_conn(conn)\n  File \"/usr/lib/python3/dist-packages/urllib3/connectionpool.py\", line 996, in _validate_conn\n    conn.connect()\n  File \"/usr/lib/python3/dist-packages/urllib3/connection.py\", line 300, in connect\n    conn = self._new_conn()\n  File \"/usr/lib/python3/dist-packages/urllib3/connection.py\", line 168, in _new_conn\n    raise NewConnectionError(\nurllib3.exceptions.NewConnectionError: <urllib3.connection.VerifiedHTTPSConnection object at 0x7fe90e5bd5e0>: Failed to establish a new connection: [Errno -3] Temporary failure in name resolution\n\nDuring handling of the above exception, another exception occurred:\n\nTraceback (most recent call last):\n  File \"/usr/local/lib/python3.8/dist-packages/requests/adapters.py\", line 486, in send\n    resp = conn.urlopen(\n  File \"/usr/lib/python3/dist-packages/urllib3/connectionpool.py\", line 719, in urlopen\n    retries = retries.increment(\n  File \"/usr/lib/python3/dist-packages/urllib3/util/retry.py\", line 436, in increment\n    raise MaxRetryError(_pool, url, error or ResponseError(cause))\nurllib3.exceptions.MaxRetryError: HTTPSConnectionPool(host='virtserver.swaggerhub.com', port=443): Max retries exceeded with url: /AAYUSHGARGBU/api_petstore/1.0.0/pet/0/uploadImage (Caused by NewConnectionError('<urllib3.connection.VerifiedHTTPSConnection object at 0x7fe90e5bd5e0>: Failed to establish a new connection: [Errno -3] Temporary failure in name resolution'))\n\nDuring handling of the above exception, another exception occurred:\n\nTraceback (most recent call last):\n  File \"/usr/local/lib/python3.8/dist-packages/schemathesis/runner/impl/core.py\", line 816, in network_test\n    response = _network_test(case, *args)\n  File \"/usr/local/lib/python3.8/dist-packages/schemathesis/runner/impl/core.py\", line 848, in _network_test\n    response = case.call(**kwargs)\n  File \"/usr/local/lib/python3.8/dist-packages/schemathesis/models.py\", line 310, in call\n    response = self.operation.schema.transport.send(\n  File \"/usr/local/lib/python3.8/dist-packages/schemathesis/transports/__init__.py\", line 143, in send\n    response = session.request(**data)  # type: ignore\n  File \"/usr/local/lib/python3.8/dist-packages/requests/sessions.py\", line 589, in request\n    resp = self.send(prep, **send_kwargs)\n  File \"/usr/local/lib/python3.8/dist-packages/requests/sessions.py\", line 703, in send\n    r = adapter.send(request, **kwargs)\n  File \"/usr/local/lib/python3.8/dist-packages/requests/adapters.py\", line 519, in send\n    raise ConnectionError(e, request=request)\nrequests.exceptions.ConnectionError: HTTPSConnectionPool(host='virtserver.swaggerhub.com', port=443): Max retries exceeded with url: /AAYUSHGARGBU/api_petstore/1.0.0/pet/0/uploadImage (Caused by NewConnectionError('<urllib3.connection.VerifiedHTTPSConnection object at 0x7fe90e5bd5e0>: Failed to establish a new connection: [Errno -3] Temporary failure in name resolution'))"}], "interactions": []}, "elapsed_time": 154.1050517000258, "correlation_id": "3f646dd2858c49f6b176cbbbd89d7685", "thread_id": 140638996727616, "hypothesis_output": [], "event_type": "AfterExecution"}
{"method": "GET", "path": "/AAYUSHGARGBU/api_petstore/1.0.0/store/inventory", "verbose_name": "GET /AAYUSHGARGBU/api_petstore/1.0.0/store/inventory", "relative_path": "/store/inventory", "recursion_level": 0, "data_generation_method": ["positive", "negative"], "correlation_id": "16b8bd808aff472ca29ce89bf1d95ea1", "thread_id": 140638996727616, "event_type": "BeforeExecution"}
{"method": "GET", "path": "/AAYUSHGARGBU/api_petstore/1.0.0/store/inventory", "relative_path": "/store/inventory", "verbose_name": "GET /AAYUSHGARGBU/api_petstore/1.0.0/store/inventory", "status": "error", "data_generation_method": ["positive"], "result": {"method": "GET", "path": "/AAYUSHGARGBU/api_petstore/1.0.0/store/inventory", "verbose_name": "GET /AAYUSHGARGBU/api_petstore/1.0.0/store/inventory", "has_failures": false, "has_errors": true, "has_logs": false, "is_errored": true, "is_flaky": false, "is_skipped": false, "skip_reason": null, "seed": 57932623809996008151663850801588433753, "data_generation_method": ["P"], "checks": [], "logs": [], "errors": [{"type": "connection_other", "title": "Network Error", "message": "Connection failed", "extras": ["Failed to establish a new connection: [Errno -3] Temporary failure in name resolution"], "exception": "requests.exceptions.ConnectionError: HTTPSConnectionPool(host='virtserver.swaggerhub.com', port=443): Max retries exceeded with url: /AAYUSHGARGBU/api_petstore/1.0.0/store/inventory (Caused by NewConnectionError('<urllib3.connection.VerifiedHTTPSConnection object at 0x7fe90e596280>: Failed to establish a new connection: [Errno -3] Temporary failure in name resolution'))", "exception_with_traceback": "Traceback (most recent call last):\n  File \"/usr/lib/python3/dist-packages/urllib3/connection.py\", line 156, in _new_conn\n    conn = connection.create_connection(\n  File \"/usr/lib/python3/dist-packages/urllib3/util/connection.py\", line 61, in create_connection\n    for res in socket.getaddrinfo(host, port, family, socket.SOCK_STREAM):\n  File \"/usr/lib/python3.8/socket.py\", line 918, in getaddrinfo\n    for res in _socket.getaddrinfo(host, port, family, type, proto, flags):\nsocket.gaierror: [Errno -3] Temporary failure in name resolution\n\nDuring handling of the above exception, another exception occurred:\n\nTraceback (most recent call last):\n  File \"/usr/lib/python3/dist-packages/urllib3/connectionpool.py\", line 665, in urlopen\n    httplib_response = self._make_request(\n  File \"/usr/lib/python3/dist-packages/urllib3/connectionpool.py\", line 376, in _make_request\n    self._validate_conn(conn)\n  File \"/usr/lib/python3/dist-packages/urllib3/connectionpool.py\", line 996, in _validate_conn\n    conn.connect()\n  File \"/usr/lib/python3/dist-packages/urllib3/connection.py\", line 300, in connect\n    conn = self._new_conn()\n  File \"/usr/lib/python3/dist-packages/urllib3/connection.py\", line 168, in _new_conn\n    raise NewConnectionError(\nurllib3.exceptions.NewConnectionError: <urllib3.connection.VerifiedHTTPSConnection object at 0x7fe90e596280>: Failed to establish a new connection: [Errno -3] Temporary failure in name resolution\n\nDuring handling of the above exception, another exception occurred:\n\nTraceback (most recent call last):\n  File \"/usr/local/lib/python3.8/dist-packages/requests/adapters.py\", line 486, in send\n    resp = conn.urlopen(\n  File \"/usr/lib/python3/dist-packages/urllib3/connectionpool.py\", line 719, in urlopen\n    retries = retries.increment(\n  File \"/usr/lib/python3/dist-packages/urllib3/util/retry.py\", line 436, in increment\n    raise MaxRetryError(_pool, url, error or ResponseError(cause))\nurllib3.exceptions.MaxRetryError: HTTPSConnectionPool(host='virtserver.swaggerhub.com', port=443): Max retries exceeded with url: /AAYUSHGARGBU/api_petstore/1.0.0/store/inventory (Caused by NewConnectionError('<urllib3.connection.VerifiedHTTPSConnection object at 0x7fe90e596280>: Failed to establish a new connection: [Errno -3] Temporary failure in name resolution'))\n\nDuring handling of the above exception, another exception occurred:\n\nTraceback (most recent call last):\n  File \"/usr/local/lib/python3.8/dist-packages/schemathesis/runner/impl/core.py\", line 816, in network_test\n    response = _network_test(case, *args)\n  File \"/usr/local/lib/python3.8/dist-packages/schemathesis/runner/impl/core.py\", line 848, in _network_test\n    response = case.call(**kwargs)\n  File \"/usr/local/lib/python3.8/dist-packages/schemathesis/models.py\", line 310, in call\n    response = self.operation.schema.transport.send(\n  File \"/usr/local/lib/python3.8/dist-packages/schemathesis/transports/__init__.py\", line 143, in send\n    response = session.request(**data)  # type: ignore\n  File \"/usr/local/lib/python3.8/dist-packages/requests/sessions.py\", line 589, in request\n    resp = self.send(prep, **send_kwargs)\n  File \"/usr/local/lib/python3.8/dist-packages/requests/sessions.py\", line 703, in send\n    r = adapter.send(request, **kwargs)\n  File \"/usr/local/lib/python3.8/dist-packages/requests/adapters.py\", line 519, in send\n    raise ConnectionError(e, request=request)\nrequests.exceptions.ConnectionError: HTTPSConnectionPool(host='virtserver.swaggerhub.com', port=443): Max retries exceeded with url: /AAYUSHGARGBU/api_petstore/1.0.0/store/inventory (Caused by NewConnectionError('<urllib3.connection.VerifiedHTTPSConnection object at 0x7fe90e596280>: Failed to establish a new connection: [Errno -3] Temporary failure in name resolution'))"}], "interactions": []}, "elapsed_time": 264.19403989997227, "correlation_id": "16b8bd808aff472ca29ce89bf1d95ea1", "thread_id": 140638996727616, "hypothesis_output": [], "event_type": "AfterExecution"}
{"method": "POST", "path": "/AAYUSHGARGBU/api_petstore/1.0.0/store/order", "verbose_name": "POST /AAYUSHGARGBU/api_petstore/1.0.0/store/order", "relative_path": "/store/order", "recursion_level": 0, "data_generation_method": ["positive", "negative"], "correlation_id": "7e870e7566f84d49ad902350e6b61483", "thread_id": 140638996727616, "event_type": "BeforeExecution"}
{"method": "POST", "path": "/AAYUSHGARGBU/api_petstore/1.0.0/store/order", "relative_path": "/store/order", "verbose_name": "POST /AAYUSHGARGBU/api_petstore/1.0.0/store/order", "status": "error", "data_generation_method": ["positive"], "result": {"method": "POST", "path": "/AAYUSHGARGBU/api_petstore/1.0.0/store/order", "verbose_name": "POST /AAYUSHGARGBU/api_petstore/1.0.0/store/order", "has_failures": false, "has_errors": true, "has_logs": false, "is_errored": true, "is_flaky": false, "is_skipped": false, "skip_reason": null, "seed": 57932623809996008151663850801588433753, "data_generation_method": ["P"], "checks": [], "logs": [], "errors": [{"type": "connection_other", "title": "Network Error", "message": "Connection failed", "extras": ["Failed to establish a new connection: [Errno -3] Temporary failure in name resolution"], "exception": "requests.exceptions.ConnectionError: HTTPSConnectionPool(host='virtserver.swaggerhub.com', port=443): Max retries exceeded with url: /AAYUSHGARGBU/api_petstore/1.0.0/store/order (Caused by NewConnectionError('<urllib3.connection.VerifiedHTTPSConnection object at 0x7fe90e566df0>: Failed to establish a new connection: [Errno -3] Temporary failure in name resolution'))", "exception_with_traceback": "Traceback (most recent call last):\n  File \"/usr/lib/python3/dist-packages/urllib3/connection.py\", line 156, in _new_conn\n    conn = connection.create_connection(\n  File \"/usr/lib/python3/dist-packages/urllib3/util/connection.py\", line 61, in create_connection\n    for res in socket.getaddrinfo(host, port, family, socket.SOCK_STREAM):\n  File \"/usr/lib/python3.8/socket.py\", line 918, in getaddrinfo\n    for res in _socket.getaddrinfo(host, port, family, type, proto, flags):\nsocket.gaierror: [Errno -3] Temporary failure in name resolution\n\nDuring handling of the above exception, another exception occurred:\n\nTraceback (most recent call last):\n  File \"/usr/lib/python3/dist-packages/urllib3/connectionpool.py\", line 665, in urlopen\n    httplib_response = self._make_request(\n  File \"/usr/lib/python3/dist-packages/urllib3/connectionpool.py\", line 376, in _make_request\n    self._validate_conn(conn)\n  File \"/usr/lib/python3/dist-packages/urllib3/connectionpool.py\", line 996, in _validate_conn\n    conn.connect()\n  File \"/usr/lib/python3/dist-packages/urllib3/connection.py\", line 300, in connect\n    conn = self._new_conn()\n  File \"/usr/lib/python3/dist-packages/urllib3/connection.py\", line 168, in _new_conn\n    raise NewConnectionError(\nurllib3.exceptions.NewConnectionError: <urllib3.connection.VerifiedHTTPSConnection object at 0x7fe90e566df0>: Failed to establish a new connection: [Errno -3] Temporary failure in name resolution\n\nDuring handling of the above exception, another exception occurred:\n\nTraceback (most recent call last):\n  File \"/usr/local/lib/python3.8/dist-packages/requests/adapters.py\", line 486, in send\n    resp = conn.urlopen(\n  File \"/usr/lib/python3/dist-packages/urllib3/connectionpool.py\", line 719, in urlopen\n    retries = retries.increment(\n  File \"/usr/lib/python3/dist-packages/urllib3/util/retry.py\", line 436, in increment\n    raise MaxRetryError(_pool, url, error or ResponseError(cause))\nurllib3.exceptions.MaxRetryError: HTTPSConnectionPool(host='virtserver.swaggerhub.com', port=443): Max retries exceeded with url: /AAYUSHGARGBU/api_petstore/1.0.0/store/order (Caused by NewConnectionError('<urllib3.connection.VerifiedHTTPSConnection object at 0x7fe90e566df0>: Failed to establish a new connection: [Errno -3] Temporary failure in name resolution'))\n\nDuring handling of the above exception, another exception occurred:\n\nTraceback (most recent call last):\n  File \"/usr/local/lib/python3.8/dist-packages/schemathesis/runner/impl/core.py\", line 816, in network_test\n    response = _network_test(case, *args)\n  File \"/usr/local/lib/python3.8/dist-packages/schemathesis/runner/impl/core.py\", line 848, in _network_test\n    response = case.call(**kwargs)\n  File \"/usr/local/lib/python3.8/dist-packages/schemathesis/models.py\", line 310, in call\n    response = self.operation.schema.transport.send(\n  File \"/usr/local/lib/python3.8/dist-packages/schemathesis/transports/__init__.py\", line 143, in send\n    response = session.request(**data)  # type: ignore\n  File \"/usr/local/lib/python3.8/dist-packages/requests/sessions.py\", line 589, in request\n    resp = self.send(prep, **send_kwargs)\n  File \"/usr/local/lib/python3.8/dist-packages/requests/sessions.py\", line 703, in send\n    r = adapter.send(request, **kwargs)\n  File \"/usr/local/lib/python3.8/dist-packages/requests/adapters.py\", line 519, in send\n    raise ConnectionError(e, request=request)\nrequests.exceptions.ConnectionError: HTTPSConnectionPool(host='virtserver.swaggerhub.com', port=443): Max retries exceeded with url: /AAYUSHGARGBU/api_petstore/1.0.0/store/order (Caused by NewConnectionError('<urllib3.connection.VerifiedHTTPSConnection object at 0x7fe90e566df0>: Failed to establish a new connection: [Errno -3] Temporary failure in name resolution'))"}], "interactions": []}, "elapsed_time": 88.087680800003, "correlation_id": "7e870e7566f84d49ad902350e6b61483", "thread_id": 140638996727616, "hypothesis_output": [], "event_type": "AfterExecution"}
{"method": "GET", "path": "/AAYUSHGARGBU/api_petstore/1.0.0/store/order/{orderId}", "verbose_name": "GET /AAYUSHGARGBU/api_petstore/1.0.0/store/order/{orderId}", "relative_path": "/store/order/{orderId}", "recursion_level": 0, "data_generation_method": ["positive", "negative"], "correlation_id": "dcfaf912e48a4731bce3bdeba69baea5", "thread_id": 140638996727616, "event_type": "BeforeExecution"}
{"method": "GET", "path": "/AAYUSHGARGBU/api_petstore/1.0.0/store/order/{orderId}", "relative_path": "/store/order/{orderId}", "verbose_name": "GET /AAYUSHGARGBU/api_petstore/1.0.0/store/order/{orderId}", "status": "error", "data_generation_method": ["positive"], "result": {"method": "GET", "path": "/AAYUSHGARGBU/api_petstore/1.0.0/store/order/{orderId}", "verbose_name": "GET /AAYUSHGARGBU/api_petstore/1.0.0/store/order/{orderId}", "has_failures": false, "has_errors": true, "has_logs": false, "is_errored": true, "is_flaky": false, "is_skipped": false, "skip_reason": null, "seed": 57932623809996008151663850801588433753, "data_generation_method": ["P"], "checks": [], "logs": [], "errors": [{"type": "connection_other", "title": "Network Error", "message": "Connection failed", "extras": ["Failed to establish a new connection: [Errno -3] Temporary failure in name resolution"], "exception": "requests.exceptions.ConnectionError: HTTPSConnectionPool(host='virtserver.swaggerhub.com', port=443): Max retries exceeded with url: /AAYUSHGARGBU/api_petstore/1.0.0/store/order/1 (Caused by NewConnectionError('<urllib3.connection.VerifiedHTTPSConnection object at 0x7fe90e430460>: Failed to establish a new connection: [Errno -3] Temporary failure in name resolution'))", "exception_with_traceback": "Traceback (most recent call last):\n  File \"/usr/lib/python3/dist-packages/urllib3/connection.py\", line 156, in _new_conn\n    conn = connection.create_connection(\n  File \"/usr/lib/python3/dist-packages/urllib3/util/connection.py\", line 61, in create_connection\n    for res in socket.getaddrinfo(host, port, family, socket.SOCK_STREAM):\n  File \"/usr/lib/python3.8/socket.py\", line 918, in getaddrinfo\n    for res in _socket.getaddrinfo(host, port, family, type, proto, flags):\nsocket.gaierror: [Errno -3] Temporary failure in name resolution\n\nDuring handling of the above exception, another exception occurred:\n\nTraceback (most recent call last):\n  File \"/usr/lib/python3/dist-packages/urllib3/connectionpool.py\", line 665, in urlopen\n    httplib_response = self._make_request(\n  File \"/usr/lib/python3/dist-packages/urllib3/connectionpool.py\", line 376, in _make_request\n    self._validate_conn(conn)\n  File \"/usr/lib/python3/dist-packages/urllib3/connectionpool.py\", line 996, in _validate_conn\n    conn.connect()\n  File \"/usr/lib/python3/dist-packages/urllib3/connection.py\", line 300, in connect\n    conn = self._new_conn()\n  File \"/usr/lib/python3/dist-packages/urllib3/connection.py\", line 168, in _new_conn\n    raise NewConnectionError(\nurllib3.exceptions.NewConnectionError: <urllib3.connection.VerifiedHTTPSConnection object at 0x7fe90e430460>: Failed to establish a new connection: [Errno -3] Temporary failure in name resolution\n\nDuring handling of the above exception, another exception occurred:\n\nTraceback (most recent call last):\n  File \"/usr/local/lib/python3.8/dist-packages/requests/adapters.py\", line 486, in send\n    resp = conn.urlopen(\n  File \"/usr/lib/python3/dist-packages/urllib3/connectionpool.py\", line 719, in urlopen\n    retries = retries.increment(\n  File \"/usr/lib/python3/dist-packages/urllib3/util/retry.py\", line 436, in increment\n    raise MaxRetryError(_pool, url, error or ResponseError(cause))\nurllib3.exceptions.MaxRetryError: HTTPSConnectionPool(host='virtserver.swaggerhub.com', port=443): Max retries exceeded with url: /AAYUSHGARGBU/api_petstore/1.0.0/store/order/1 (Caused by NewConnectionError('<urllib3.connection.VerifiedHTTPSConnection object at 0x7fe90e430460>: Failed to establish a new connection: [Errno -3] Temporary failure in name resolution'))\n\nDuring handling of the above exception, another exception occurred:\n\nTraceback (most recent call last):\n  File \"/usr/local/lib/python3.8/dist-packages/schemathesis/runner/impl/core.py\", line 816, in network_test\n    response = _network_test(case, *args)\n  File \"/usr/local/lib/python3.8/dist-packages/schemathesis/runner/impl/core.py\", line 848, in _network_test\n    response = case.call(**kwargs)\n  File \"/usr/local/lib/python3.8/dist-packages/schemathesis/models.py\", line 310, in call\n    response = self.operation.schema.transport.send(\n  File \"/usr/local/lib/python3.8/dist-packages/schemathesis/transports/__init__.py\", line 143, in send\n    response = session.request(**data)  # type: ignore\n  File \"/usr/local/lib/python3.8/dist-packages/requests/sessions.py\", line 589, in request\n    resp = self.send(prep, **send_kwargs)\n  File \"/usr/local/lib/python3.8/dist-packages/requests/sessions.py\", line 703, in send\n    r = adapter.send(request, **kwargs)\n  File \"/usr/local/lib/python3.8/dist-packages/requests/adapters.py\", line 519, in send\n    raise ConnectionError(e, request=request)\nrequests.exceptions.ConnectionError: HTTPSConnectionPool(host='virtserver.swaggerhub.com', port=443): Max retries exceeded with url: /AAYUSHGARGBU/api_petstore/1.0.0/store/order/1 (Caused by NewConnectionError('<urllib3.connection.VerifiedHTTPSConnection object at 0x7fe90e430460>: Failed to establish a new connection: [Errno -3] Temporary failure in name resolution'))"}, {"type": "connection_other", "title": "Network Error", "message": "Connection failed", "extras": ["Failed to establish a new connection: [Errno -2] Name or service not known"], "exception": "requests.exceptions.ConnectionError: HTTPSConnectionPool(host='virtserver.swaggerhub.com', port=443): Max retries exceeded with url: /AAYUSHGARGBU/api_petstore/1.0.0/store/order/1 (Caused by NewConnectionError('<urllib3.connection.VerifiedHTTPSConnection object at 0x7fe90e44dee0>: Failed to establish a new connection: [Errno -2] Name or service not known'))", "exception_with_traceback": "Traceback (most recent call last):\n  File \"/usr/lib/python3/dist-packages/urllib3/connection.py\", line 156, in _new_conn\n    conn = connection.create_connection(\n  File \"/usr/lib/python3/dist-packages/urllib3/util/connection.py\", line 61, in create_connection\n    for res in socket.getaddrinfo(host, port, family, socket.SOCK_STREAM):\n  File \"/usr/lib/python3.8/socket.py\", line 918, in getaddrinfo\n    for res in _socket.getaddrinfo(host, port, family, type, proto, flags):\nsocket.gaierror: [Errno -2] Name or service not known\n\nDuring handling of the above exception, another exception occurred:\n\nTraceback (most recent call last):\n  File \"/usr/lib/python3/dist-packages/urllib3/connectionpool.py\", line 665, in urlopen\n    httplib_response = self._make_request(\n  File \"/usr/lib/python3/dist-packages/urllib3/connectionpool.py\", line 376, in _make_request\n    self._validate_conn(conn)\n  File \"/usr/lib/python3/dist-packages/urllib3/connectionpool.py\", line 996, in _validate_conn\n    conn.connect()\n  File \"/usr/lib/python3/dist-packages/urllib3/connection.py\", line 300, in connect\n    conn = self._new_conn()\n  File \"/usr/lib/python3/dist-packages/urllib3/connection.py\", line 168, in _new_conn\n    raise NewConnectionError(\nurllib3.exceptions.NewConnectionError: <urllib3.connection.VerifiedHTTPSConnection object at 0x7fe90e44dee0>: Failed to establish a new connection: [Errno -2] Name or service not known\n\nDuring handling of the above exception, another exception occurred:\n\nTraceback (most recent call last):\n  File \"/usr/local/lib/python3.8/dist-packages/requests/adapters.py\", line 486, in send\n    resp = conn.urlopen(\n  File \"/usr/lib/python3/dist-packages/urllib3/connectionpool.py\", line 719, in urlopen\n    retries = retries.increment(\n  File \"/usr/lib/python3/dist-packages/urllib3/util/retry.py\", line 436, in increment\n    raise MaxRetryError(_pool, url, error or ResponseError(cause))\nurllib3.exceptions.MaxRetryError: HTTPSConnectionPool(host='virtserver.swaggerhub.com', port=443): Max retries exceeded with url: /AAYUSHGARGBU/api_petstore/1.0.0/store/order/1 (Caused by NewConnectionError('<urllib3.connection.VerifiedHTTPSConnection object at 0x7fe90e44dee0>: Failed to establish a new connection: [Errno -2] Name or service not known'))\n\nDuring handling of the above exception, another exception occurred:\n\nTraceback (most recent call last):\n  File \"/usr/local/lib/python3.8/dist-packages/schemathesis/runner/impl/core.py\", line 816, in network_test\n    response = _network_test(case, *args)\n  File \"/usr/local/lib/python3.8/dist-packages/schemathesis/runner/impl/core.py\", line 848, in _network_test\n    response = case.call(**kwargs)\n  File \"/usr/local/lib/python3.8/dist-packages/schemathesis/models.py\", line 310, in call\n    response = self.operation.schema.transport.send(\n  File \"/usr/local/lib/python3.8/dist-packages/schemathesis/transports/__init__.py\", line 143, in send\n    response = session.request(**data)  # type: ignore\n  File \"/usr/local/lib/python3.8/dist-packages/requests/sessions.py\", line 589, in request\n    resp = self.send(prep, **send_kwargs)\n  File \"/usr/local/lib/python3.8/dist-packages/requests/sessions.py\", line 703, in send\n    r = adapter.send(request, **kwargs)\n  File \"/usr/local/lib/python3.8/dist-packages/requests/adapters.py\", line 519, in send\n    raise ConnectionError(e, request=request)\nrequests.exceptions.ConnectionError: HTTPSConnectionPool(host='virtserver.swaggerhub.com', port=443): Max retries exceeded with url: /AAYUSHGARGBU/api_petstore/1.0.0/store/order/1 (Caused by NewConnectionError('<urllib3.connection.VerifiedHTTPSConnection object at 0x7fe90e44dee0>: Failed to establish a new connection: [Errno -2] Name or service not known'))"}], "interactions": []}, "elapsed_time": 66.05397300003096, "correlation_id": "dcfaf912e48a4731bce3bdeba69baea5", "thread_id": 140638996727616, "hypothesis_output": [], "event_type": "AfterExecution"}
{"method": "DELETE", "path": "/AAYUSHGARGBU/api_petstore/1.0.0/store/order/{orderId}", "verbose_name": "DELETE /AAYUSHGARGBU/api_petstore/1.0.0/store/order/{orderId}", "relative_path": "/store/order/{orderId}", "recursion_level": 0, "data_generation_method": ["positive", "negative"], "correlation_id": "95b67783792249bda7dd9a92c04187ba", "thread_id": 140638996727616, "event_type": "BeforeExecution"}
{"method": "DELETE", "path": "/AAYUSHGARGBU/api_petstore/1.0.0/store/order/{orderId}", "relative_path": "/store/order/{orderId}", "verbose_name": "DELETE /AAYUSHGARGBU/api_petstore/1.0.0/store/order/{orderId}", "status": "error", "data_generation_method": ["positive"], "result": {"method": "DELETE", "path": "/AAYUSHGARGBU/api_petstore/1.0.0/store/order/{orderId}", "verbose_name": "DELETE /AAYUSHGARGBU/api_petstore/1.0.0/store/order/{orderId}", "has_failures": false, "has_errors": true, "has_logs": false, "is_errored": true, "is_flaky": false, "is_skipped": false, "skip_reason": null, "seed": 57932623809996008151663850801588433753, "data_generation_method": ["P"], "checks": [], "logs": [], "errors": [{"type": "connection_other", "title": "Network Error", "message": "Connection failed", "extras": ["Failed to establish a new connection: [Errno -2] Name or service not known"], "exception": "requests.exceptions.ConnectionError: HTTPSConnectionPool(host='virtserver.swaggerhub.com', port=443): Max retries exceeded with url: /AAYUSHGARGBU/api_petstore/1.0.0/store/order/1 (Caused by NewConnectionError('<urllib3.connection.VerifiedHTTPSConnection object at 0x7fe90e45fe20>: Failed to establish a new connection: [Errno -2] Name or service not known'))", "exception_with_traceback": "Traceback (most recent call last):\n  File \"/usr/lib/python3/dist-packages/urllib3/connection.py\", line 156, in _new_conn\n    conn = connection.create_connection(\n  File \"/usr/lib/python3/dist-packages/urllib3/util/connection.py\", line 61, in create_connection\n    for res in socket.getaddrinfo(host, port, family, socket.SOCK_STREAM):\n  File \"/usr/lib/python3.8/socket.py\", line 918, in getaddrinfo\n    for res in _socket.getaddrinfo(host, port, family, type, proto, flags):\nsocket.gaierror: [Errno -2] Name or service not known\n\nDuring handling of the above exception, another exception occurred:\n\nTraceback (most recent call last):\n  File \"/usr/lib/python3/dist-packages/urllib3/connectionpool.py\", line 665, in urlopen\n    httplib_response = self._make_request(\n  File \"/usr/lib/python3/dist-packages/urllib3/connectionpool.py\", line 376, in _make_request\n    self._validate_conn(conn)\n  File \"/usr/lib/python3/dist-packages/urllib3/connectionpool.py\", line 996, in _validate_conn\n    conn.connect()\n  File \"/usr/lib/python3/dist-packages/urllib3/connection.py\", line 300, in connect\n    conn = self._new_conn()\n  File \"/usr/lib/python3/dist-packages/urllib3/connection.py\", line 168, in _new_conn\n    raise NewConnectionError(\nurllib3.exceptions.NewConnectionError: <urllib3.connection.VerifiedHTTPSConnection object at 0x7fe90e45fe20>: Failed to establish a new connection: [Errno -2] Name or service not known\n\nDuring handling of the above exception, another exception occurred:\n\nTraceback (most recent call last):\n  File \"/usr/local/lib/python3.8/dist-packages/requests/adapters.py\", line 486, in send\n    resp = conn.urlopen(\n  File \"/usr/lib/python3/dist-packages/urllib3/connectionpool.py\", line 719, in urlopen\n    retries = retries.increment(\n  File \"/usr/lib/python3/dist-packages/urllib3/util/retry.py\", line 436, in increment\n    raise MaxRetryError(_pool, url, error or ResponseError(cause))\nurllib3.exceptions.MaxRetryError: HTTPSConnectionPool(host='virtserver.swaggerhub.com', port=443): Max retries exceeded with url: /AAYUSHGARGBU/api_petstore/1.0.0/store/order/1 (Caused by NewConnectionError('<urllib3.connection.VerifiedHTTPSConnection object at 0x7fe90e45fe20>: Failed to establish a new connection: [Errno -2] Name or service not known'))\n\nDuring handling of the above exception, another exception occurred:\n\nTraceback (most recent call last):\n  File \"/usr/local/lib/python3.8/dist-packages/schemathesis/runner/impl/core.py\", line 816, in network_test\n    response = _network_test(case, *args)\n  File \"/usr/local/lib/python3.8/dist-packages/schemathesis/runner/impl/core.py\", line 848, in _network_test\n    response = case.call(**kwargs)\n  File \"/usr/local/lib/python3.8/dist-packages/schemathesis/models.py\", line 310, in call\n    response = self.operation.schema.transport.send(\n  File \"/usr/local/lib/python3.8/dist-packages/schemathesis/transports/__init__.py\", line 143, in send\n    response = session.request(**data)  # type: ignore\n  File \"/usr/local/lib/python3.8/dist-packages/requests/sessions.py\", line 589, in request\n    resp = self.send(prep, **send_kwargs)\n  File \"/usr/local/lib/python3.8/dist-packages/requests/sessions.py\", line 703, in send\n    r = adapter.send(request, **kwargs)\n  File \"/usr/local/lib/python3.8/dist-packages/requests/adapters.py\", line 519, in send\n    raise ConnectionError(e, request=request)\nrequests.exceptions.ConnectionError: HTTPSConnectionPool(host='virtserver.swaggerhub.com', port=443): Max retries exceeded with url: /AAYUSHGARGBU/api_petstore/1.0.0/store/order/1 (Caused by NewConnectionError('<urllib3.connection.VerifiedHTTPSConnection object at 0x7fe90e45fe20>: Failed to establish a new connection: [Errno -2] Name or service not known'))"}], "interactions": []}, "elapsed_time": 0.08540809992700815, "correlation_id": "95b67783792249bda7dd9a92c04187ba", "thread_id": 140638996727616, "hypothesis_output": [], "event_type": "AfterExecution"}
{"method": "POST", "path": "/AAYUSHGARGBU/api_petstore/1.0.0/user", "verbose_name": "POST /AAYUSHGARGBU/api_petstore/1.0.0/user", "relative_path": "/user", "recursion_level": 0, "data_generation_method": ["positive", "negative"], "correlation_id": "bac83b5d415848e8b7fee4a1f7b04118", "thread_id": 140638996727616, "event_type": "BeforeExecution"}
{"method": "POST", "path": "/AAYUSHGARGBU/api_petstore/1.0.0/user", "relative_path": "/user", "verbose_name": "POST /AAYUSHGARGBU/api_petstore/1.0.0/user", "status": "error", "data_generation_method": ["positive"], "result": {"method": "POST", "path": "/AAYUSHGARGBU/api_petstore/1.0.0/user", "verbose_name": "POST /AAYUSHGARGBU/api_petstore/1.0.0/user", "has_failures": false, "has_errors": true, "has_logs": false, "is_errored": true, "is_flaky": false, "is_skipped": false, "skip_reason": null, "seed": 57932623809996008151663850801588433753, "data_generation_method": ["P"], "checks": [], "logs": [], "errors": [{"type": "connection_other", "title": "Network Error", "message": "Connection failed", "extras": ["Failed to establish a new connection: [Errno -2] Name or service not known"], "exception": "requests.exceptions.ConnectionError: HTTPSConnectionPool(host='virtserver.swaggerhub.com', port=443): Max retries exceeded with url: /AAYUSHGARGBU/api_petstore/1.0.0/user (Caused by NewConnectionError('<urllib3.connection.VerifiedHTTPSConnection object at 0x7fe90e3e7820>: Failed to establish a new connection: [Errno -2] Name or service not known'))", "exception_with_traceback": "Traceback (most recent call last):\n  File \"/usr/lib/python3/dist-packages/urllib3/connection.py\", line 156, in _new_conn\n    conn = connection.create_connection(\n  File \"/usr/lib/python3/dist-packages/urllib3/util/connection.py\", line 61, in create_connection\n    for res in socket.getaddrinfo(host, port, family, socket.SOCK_STREAM):\n  File \"/usr/lib/python3.8/socket.py\", line 918, in getaddrinfo\n    for res in _socket.getaddrinfo(host, port, family, type, proto, flags):\nsocket.gaierror: [Errno -2] Name or service not known\n\nDuring handling of the above exception, another exception occurred:\n\nTraceback (most recent call last):\n  File \"/usr/lib/python3/dist-packages/urllib3/connectionpool.py\", line 665, in urlopen\n    httplib_response = self._make_request(\n  File \"/usr/lib/python3/dist-packages/urllib3/connectionpool.py\", line 376, in _make_request\n    self._validate_conn(conn)\n  File \"/usr/lib/python3/dist-packages/urllib3/connectionpool.py\", line 996, in _validate_conn\n    conn.connect()\n  File \"/usr/lib/python3/dist-packages/urllib3/connection.py\", line 300, in connect\n    conn = self._new_conn()\n  File \"/usr/lib/python3/dist-packages/urllib3/connection.py\", line 168, in _new_conn\n    raise NewConnectionError(\nurllib3.exceptions.NewConnectionError: <urllib3.connection.VerifiedHTTPSConnection object at 0x7fe90e3e7820>: Failed to establish a new connection: [Errno -2] Name or service not known\n\nDuring handling of the above exception, another exception occurred:\n\nTraceback (most recent call last):\n  File \"/usr/local/lib/python3.8/dist-packages/requests/adapters.py\", line 486, in send\n    resp = conn.urlopen(\n  File \"/usr/lib/python3/dist-packages/urllib3/connectionpool.py\", line 719, in urlopen\n    retries = retries.increment(\n  File \"/usr/lib/python3/dist-packages/urllib3/util/retry.py\", line 436, in increment\n    raise MaxRetryError(_pool, url, error or ResponseError(cause))\nurllib3.exceptions.MaxRetryError: HTTPSConnectionPool(host='virtserver.swaggerhub.com', port=443): Max retries exceeded with url: /AAYUSHGARGBU/api_petstore/1.0.0/user (Caused by NewConnectionError('<urllib3.connection.VerifiedHTTPSConnection object at 0x7fe90e3e7820>: Failed to establish a new connection: [Errno -2] Name or service not known'))\n\nDuring handling of the above exception, another exception occurred:\n\nTraceback (most recent call last):\n  File \"/usr/local/lib/python3.8/dist-packages/schemathesis/runner/impl/core.py\", line 816, in network_test\n    response = _network_test(case, *args)\n  File \"/usr/local/lib/python3.8/dist-packages/schemathesis/runner/impl/core.py\", line 848, in _network_test\n    response = case.call(**kwargs)\n  File \"/usr/local/lib/python3.8/dist-packages/schemathesis/models.py\", line 310, in call\n    response = self.operation.schema.transport.send(\n  File \"/usr/local/lib/python3.8/dist-packages/schemathesis/transports/__init__.py\", line 143, in send\n    response = session.request(**data)  # type: ignore\n  File \"/usr/local/lib/python3.8/dist-packages/requests/sessions.py\", line 589, in request\n    resp = self.send(prep, **send_kwargs)\n  File \"/usr/local/lib/python3.8/dist-packages/requests/sessions.py\", line 703, in send\n    r = adapter.send(request, **kwargs)\n  File \"/usr/local/lib/python3.8/dist-packages/requests/adapters.py\", line 519, in send\n    raise ConnectionError(e, request=request)\nrequests.exceptions.ConnectionError: HTTPSConnectionPool(host='virtserver.swaggerhub.com', port=443): Max retries exceeded with url: /AAYUSHGARGBU/api_petstore/1.0.0/user (Caused by NewConnectionError('<urllib3.connection.VerifiedHTTPSConnection object at 0x7fe90e3e7820>: Failed to establish a new connection: [Errno -2] Name or service not known'))"}], "interactions": []}, "elapsed_time": 0.01914230000693351, "correlation_id": "bac83b5d415848e8b7fee4a1f7b04118", "thread_id": 140638996727616, "hypothesis_output": [], "event_type": "AfterExecution"}
{"method": "POST", "path": "/AAYUSHGARGBU/api_petstore/1.0.0/user/createWithArray", "verbose_name": "POST /AAYUSHGARGBU/api_petstore/1.0.0/user/createWithArray", "relative_path": "/user/createWithArray", "recursion_level": 0, "data_generation_method": ["positive", "negative"], "correlation_id": "0c60f23d6d514ac1b16de142b84231c1", "thread_id": 140638996727616, "event_type": "BeforeExecution"}
{"method": "POST", "path": "/AAYUSHGARGBU/api_petstore/1.0.0/user/createWithArray", "relative_path": "/user/createWithArray", "verbose_name": "POST /AAYUSHGARGBU/api_petstore/1.0.0/user/createWithArray", "status": "error", "data_generation_method": ["positive"], "result": {"method": "POST", "path": "/AAYUSHGARGBU/api_petstore/1.0.0/user/createWithArray", "verbose_name": "POST /AAYUSHGARGBU/api_petstore/1.0.0/user/createWithArray", "has_failures": false, "has_errors": true, "has_logs": false, "is_errored": true, "is_flaky": false, "is_skipped": false, "skip_reason": null, "seed": 57932623809996008151663850801588433753, "data_generation_method": ["P"], "checks": [], "logs": [], "errors": [{"type": "connection_other", "title": "Network Error", "message": "Connection failed", "extras": ["Failed to establish a new connection: [Errno -2] Name or service not known"], "exception": "requests.exceptions.ConnectionError: HTTPSConnectionPool(host='virtserver.swaggerhub.com', port=443): Max retries exceeded with url: /AAYUSHGARGBU/api_petstore/1.0.0/user/createWithArray (Caused by NewConnectionError('<urllib3.connection.VerifiedHTTPSConnection object at 0x7fe90e376cd0>: Failed to establish a new connection: [Errno -2] Name or service not known'))", "exception_with_traceback": "Traceback (most recent call last):\n  File \"/usr/lib/python3/dist-packages/urllib3/connection.py\", line 156, in _new_conn\n    conn = connection.create_connection(\n  File \"/usr/lib/python3/dist-packages/urllib3/util/connection.py\", line 61, in create_connection\n    for res in socket.getaddrinfo(host, port, family, socket.SOCK_STREAM):\n  File \"/usr/lib/python3.8/socket.py\", line 918, in getaddrinfo\n    for res in _socket.getaddrinfo(host, port, family, type, proto, flags):\nsocket.gaierror: [Errno -2] Name or service not known\n\nDuring handling of the above exception, another exception occurred:\n\nTraceback (most recent call last):\n  File \"/usr/lib/python3/dist-packages/urllib3/connectionpool.py\", line 665, in urlopen\n    httplib_response = self._make_request(\n  File \"/usr/lib/python3/dist-packages/urllib3/connectionpool.py\", line 376, in _make_request\n    self._validate_conn(conn)\n  File \"/usr/lib/python3/dist-packages/urllib3/connectionpool.py\", line 996, in _validate_conn\n    conn.connect()\n  File \"/usr/lib/python3/dist-packages/urllib3/connection.py\", line 300, in connect\n    conn = self._new_conn()\n  File \"/usr/lib/python3/dist-packages/urllib3/connection.py\", line 168, in _new_conn\n    raise NewConnectionError(\nurllib3.exceptions.NewConnectionError: <urllib3.connection.VerifiedHTTPSConnection object at 0x7fe90e376cd0>: Failed to establish a new connection: [Errno -2] Name or service not known\n\nDuring handling of the above exception, another exception occurred:\n\nTraceback (most recent call last):\n  File \"/usr/local/lib/python3.8/dist-packages/requests/adapters.py\", line 486, in send\n    resp = conn.urlopen(\n  File \"/usr/lib/python3/dist-packages/urllib3/connectionpool.py\", line 719, in urlopen\n    retries = retries.increment(\n  File \"/usr/lib/python3/dist-packages/urllib3/util/retry.py\", line 436, in increment\n    raise MaxRetryError(_pool, url, error or ResponseError(cause))\nurllib3.exceptions.MaxRetryError: HTTPSConnectionPool(host='virtserver.swaggerhub.com', port=443): Max retries exceeded with url: /AAYUSHGARGBU/api_petstore/1.0.0/user/createWithArray (Caused by NewConnectionError('<urllib3.connection.VerifiedHTTPSConnection object at 0x7fe90e376cd0>: Failed to establish a new connection: [Errno -2] Name or service not known'))\n\nDuring handling of the above exception, another exception occurred:\n\nTraceback (most recent call last):\n  File \"/usr/local/lib/python3.8/dist-packages/schemathesis/runner/impl/core.py\", line 816, in network_test\n    response = _network_test(case, *args)\n  File \"/usr/local/lib/python3.8/dist-packages/schemathesis/runner/impl/core.py\", line 848, in _network_test\n    response = case.call(**kwargs)\n  File \"/usr/local/lib/python3.8/dist-packages/schemathesis/models.py\", line 310, in call\n    response = self.operation.schema.transport.send(\n  File \"/usr/local/lib/python3.8/dist-packages/schemathesis/transports/__init__.py\", line 143, in send\n    response = session.request(**data)  # type: ignore\n  File \"/usr/local/lib/python3.8/dist-packages/requests/sessions.py\", line 589, in request\n    resp = self.send(prep, **send_kwargs)\n  File \"/usr/local/lib/python3.8/dist-packages/requests/sessions.py\", line 703, in send\n    r = adapter.send(request, **kwargs)\n  File \"/usr/local/lib/python3.8/dist-packages/requests/adapters.py\", line 519, in send\n    raise ConnectionError(e, request=request)\nrequests.exceptions.ConnectionError: HTTPSConnectionPool(host='virtserver.swaggerhub.com', port=443): Max retries exceeded with url: /AAYUSHGARGBU/api_petstore/1.0.0/user/createWithArray (Caused by NewConnectionError('<urllib3.connection.VerifiedHTTPSConnection object at 0x7fe90e376cd0>: Failed to establish a new connection: [Errno -2] Name or service not known'))"}], "interactions": []}, "elapsed_time": 0.018265399965457618, "correlation_id": "0c60f23d6d514ac1b16de142b84231c1", "thread_id": 140638996727616, "hypothesis_output": [], "event_type": "AfterExecution"}
{"method": "POST", "path": "/AAYUSHGARGBU/api_petstore/1.0.0/user/createWithList", "verbose_name": "POST /AAYUSHGARGBU/api_petstore/1.0.0/user/createWithList", "relative_path": "/user/createWithList", "recursion_level": 0, "data_generation_method": ["positive", "negative"], "correlation_id": "5506148025b64af784ecef2a9551a059", "thread_id": 140638996727616, "event_type": "BeforeExecution"}
{"method": "POST", "path": "/AAYUSHGARGBU/api_petstore/1.0.0/user/createWithList", "relative_path": "/user/createWithList", "verbose_name": "POST /AAYUSHGARGBU/api_petstore/1.0.0/user/createWithList", "status": "error", "data_generation_method": ["positive"], "result": {"method": "POST", "path": "/AAYUSHGARGBU/api_petstore/1.0.0/user/createWithList", "verbose_name": "POST /AAYUSHGARGBU/api_petstore/1.0.0/user/createWithList", "has_failures": false, "has_errors": true, "has_logs": false, "is_errored": true, "is_flaky": false, "is_skipped": false, "skip_reason": null, "seed": 57932623809996008151663850801588433753, "data_generation_method": ["P"], "checks": [], "logs": [], "errors": [{"type": "connection_other", "title": "Network Error", "message": "Connection failed", "extras": ["Failed to establish a new connection: [Errno -2] Name or service not known"], "exception": "requests.exceptions.ConnectionError: HTTPSConnectionPool(host='virtserver.swaggerhub.com', port=443): Max retries exceeded with url: /AAYUSHGARGBU/api_petstore/1.0.0/user/createWithList (Caused by NewConnectionError('<urllib3.connection.VerifiedHTTPSConnection object at 0x7fe90e3add90>: Failed to establish a new connection: [Errno -2] Name or service not known'))", "exception_with_traceback": "Traceback (most recent call last):\n  File \"/usr/lib/python3/dist-packages/urllib3/connection.py\", line 156, in _new_conn\n    conn = connection.create_connection(\n  File \"/usr/lib/python3/dist-packages/urllib3/util/connection.py\", line 61, in create_connection\n    for res in socket.getaddrinfo(host, port, family, socket.SOCK_STREAM):\n  File \"/usr/lib/python3.8/socket.py\", line 918, in getaddrinfo\n    for res in _socket.getaddrinfo(host, port, family, type, proto, flags):\nsocket.gaierror: [Errno -2] Name or service not known\n\nDuring handling of the above exception, another exception occurred:\n\nTraceback (most recent call last):\n  File \"/usr/lib/python3/dist-packages/urllib3/connectionpool.py\", line 665, in urlopen\n    httplib_response = self._make_request(\n  File \"/usr/lib/python3/dist-packages/urllib3/connectionpool.py\", line 376, in _make_request\n    self._validate_conn(conn)\n  File \"/usr/lib/python3/dist-packages/urllib3/connectionpool.py\", line 996, in _validate_conn\n    conn.connect()\n  File \"/usr/lib/python3/dist-packages/urllib3/connection.py\", line 300, in connect\n    conn = self._new_conn()\n  File \"/usr/lib/python3/dist-packages/urllib3/connection.py\", line 168, in _new_conn\n    raise NewConnectionError(\nurllib3.exceptions.NewConnectionError: <urllib3.connection.VerifiedHTTPSConnection object at 0x7fe90e3add90>: Failed to establish a new connection: [Errno -2] Name or service not known\n\nDuring handling of the above exception, another exception occurred:\n\nTraceback (most recent call last):\n  File \"/usr/local/lib/python3.8/dist-packages/requests/adapters.py\", line 486, in send\n    resp = conn.urlopen(\n  File \"/usr/lib/python3/dist-packages/urllib3/connectionpool.py\", line 719, in urlopen\n    retries = retries.increment(\n  File \"/usr/lib/python3/dist-packages/urllib3/util/retry.py\", line 436, in increment\n    raise MaxRetryError(_pool, url, error or ResponseError(cause))\nurllib3.exceptions.MaxRetryError: HTTPSConnectionPool(host='virtserver.swaggerhub.com', port=443): Max retries exceeded with url: /AAYUSHGARGBU/api_petstore/1.0.0/user/createWithList (Caused by NewConnectionError('<urllib3.connection.VerifiedHTTPSConnection object at 0x7fe90e3add90>: Failed to establish a new connection: [Errno -2] Name or service not known'))\n\nDuring handling of the above exception, another exception occurred:\n\nTraceback (most recent call last):\n  File \"/usr/local/lib/python3.8/dist-packages/schemathesis/runner/impl/core.py\", line 816, in network_test\n    response = _network_test(case, *args)\n  File \"/usr/local/lib/python3.8/dist-packages/schemathesis/runner/impl/core.py\", line 848, in _network_test\n    response = case.call(**kwargs)\n  File \"/usr/local/lib/python3.8/dist-packages/schemathesis/models.py\", line 310, in call\n    response = self.operation.schema.transport.send(\n  File \"/usr/local/lib/python3.8/dist-packages/schemathesis/transports/__init__.py\", line 143, in send\n    response = session.request(**data)  # type: ignore\n  File \"/usr/local/lib/python3.8/dist-packages/requests/sessions.py\", line 589, in request\n    resp = self.send(prep, **send_kwargs)\n  File \"/usr/local/lib/python3.8/dist-packages/requests/sessions.py\", line 703, in send\n    r = adapter.send(request, **kwargs)\n  File \"/usr/local/lib/python3.8/dist-packages/requests/adapters.py\", line 519, in send\n    raise ConnectionError(e, request=request)\nrequests.exceptions.ConnectionError: HTTPSConnectionPool(host='virtserver.swaggerhub.com', port=443): Max retries exceeded with url: /AAYUSHGARGBU/api_petstore/1.0.0/user/createWithList (Caused by NewConnectionError('<urllib3.connection.VerifiedHTTPSConnection object at 0x7fe90e3add90>: Failed to establish a new connection: [Errno -2] Name or service not known'))"}], "interactions": []}, "elapsed_time": 0.01958560000639409, "correlation_id": "5506148025b64af784ecef2a9551a059", "thread_id": 140638996727616, "hypothesis_output": [], "event_type": "AfterExecution"}
{"method": "GET", "path": "/AAYUSHGARGBU/api_petstore/1.0.0/user/login", "verbose_name": "GET /AAYUSHGARGBU/api_petstore/1.0.0/user/login", "relative_path": "/user/login", "recursion_level": 0, "data_generation_method": ["positive", "negative"], "correlation_id": "d06cd0915c714e568cc05783f20dd0da", "thread_id": 140638996727616, "event_type": "BeforeExecution"}
{"method": "GET", "path": "/AAYUSHGARGBU/api_petstore/1.0.0/user/login", "relative_path": "/user/login", "verbose_name": "GET /AAYUSHGARGBU/api_petstore/1.0.0/user/login", "status": "error", "data_generation_method": ["positive"], "result": {"method": "GET", "path": "/AAYUSHGARGBU/api_petstore/1.0.0/user/login", "verbose_name": "GET /AAYUSHGARGBU/api_petstore/1.0.0/user/login", "has_failures": false, "has_errors": true, "has_logs": false, "is_errored": true, "is_flaky": false, "is_skipped": false, "skip_reason": null, "seed": 57932623809996008151663850801588433753, "data_generation_method": ["P"], "checks": [], "logs": [], "errors": [{"type": "connection_other", "title": "Network Error", "message": "Connection failed", "extras": ["Failed to establish a new connection: [Errno -2] Name or service not known"], "exception": "requests.exceptions.ConnectionError: HTTPSConnectionPool(host='virtserver.swaggerhub.com', port=443): Max retries exceeded with url: /AAYUSHGARGBU/api_petstore/1.0.0/user/login?password=&username= (Caused by NewConnectionError('<urllib3.connection.VerifiedHTTPSConnection object at 0x7fe90e3524f0>: Failed to establish a new connection: [Errno -2] Name or service not known'))", "exception_with_traceback": "Traceback (most recent call last):\n  File \"/usr/lib/python3/dist-packages/urllib3/connection.py\", line 156, in _new_conn\n    conn = connection.create_connection(\n  File \"/usr/lib/python3/dist-packages/urllib3/util/connection.py\", line 61, in create_connection\n    for res in socket.getaddrinfo(host, port, family, socket.SOCK_STREAM):\n  File \"/usr/lib/python3.8/socket.py\", line 918, in getaddrinfo\n    for res in _socket.getaddrinfo(host, port, family, type, proto, flags):\nsocket.gaierror: [Errno -2] Name or service not known\n\nDuring handling of the above exception, another exception occurred:\n\nTraceback (most recent call last):\n  File \"/usr/lib/python3/dist-packages/urllib3/connectionpool.py\", line 665, in urlopen\n    httplib_response = self._make_request(\n  File \"/usr/lib/python3/dist-packages/urllib3/connectionpool.py\", line 376, in _make_request\n    self._validate_conn(conn)\n  File \"/usr/lib/python3/dist-packages/urllib3/connectionpool.py\", line 996, in _validate_conn\n    conn.connect()\n  File \"/usr/lib/python3/dist-packages/urllib3/connection.py\", line 300, in connect\n    conn = self._new_conn()\n  File \"/usr/lib/python3/dist-packages/urllib3/connection.py\", line 168, in _new_conn\n    raise NewConnectionError(\nurllib3.exceptions.NewConnectionError: <urllib3.connection.VerifiedHTTPSConnection object at 0x7fe90e3524f0>: Failed to establish a new connection: [Errno -2] Name or service not known\n\nDuring handling of the above exception, another exception occurred:\n\nTraceback (most recent call last):\n  File \"/usr/local/lib/python3.8/dist-packages/requests/adapters.py\", line 486, in send\n    resp = conn.urlopen(\n  File \"/usr/lib/python3/dist-packages/urllib3/connectionpool.py\", line 719, in urlopen\n    retries = retries.increment(\n  File \"/usr/lib/python3/dist-packages/urllib3/util/retry.py\", line 436, in increment\n    raise MaxRetryError(_pool, url, error or ResponseError(cause))\nurllib3.exceptions.MaxRetryError: HTTPSConnectionPool(host='virtserver.swaggerhub.com', port=443): Max retries exceeded with url: /AAYUSHGARGBU/api_petstore/1.0.0/user/login?password=&username= (Caused by NewConnectionError('<urllib3.connection.VerifiedHTTPSConnection object at 0x7fe90e3524f0>: Failed to establish a new connection: [Errno -2] Name or service not known'))\n\nDuring handling of the above exception, another exception occurred:\n\nTraceback (most recent call last):\n  File \"/usr/local/lib/python3.8/dist-packages/schemathesis/runner/impl/core.py\", line 816, in network_test\n    response = _network_test(case, *args)\n  File \"/usr/local/lib/python3.8/dist-packages/schemathesis/runner/impl/core.py\", line 848, in _network_test\n    response = case.call(**kwargs)\n  File \"/usr/local/lib/python3.8/dist-packages/schemathesis/models.py\", line 310, in call\n    response = self.operation.schema.transport.send(\n  File \"/usr/local/lib/python3.8/dist-packages/schemathesis/transports/__init__.py\", line 143, in send\n    response = session.request(**data)  # type: ignore\n  File \"/usr/local/lib/python3.8/dist-packages/requests/sessions.py\", line 589, in request\n    resp = self.send(prep, **send_kwargs)\n  File \"/usr/local/lib/python3.8/dist-packages/requests/sessions.py\", line 703, in send\n    r = adapter.send(request, **kwargs)\n  File \"/usr/local/lib/python3.8/dist-packages/requests/adapters.py\", line 519, in send\n    raise ConnectionError(e, request=request)\nrequests.exceptions.ConnectionError: HTTPSConnectionPool(host='virtserver.swaggerhub.com', port=443): Max retries exceeded with url: /AAYUSHGARGBU/api_petstore/1.0.0/user/login?password=&username= (Caused by NewConnectionError('<urllib3.connection.VerifiedHTTPSConnection object at 0x7fe90e3524f0>: Failed to establish a new connection: [Errno -2] Name or service not known'))"}], "interactions": []}, "elapsed_time": 0.019403900019824505, "correlation_id": "d06cd0915c714e568cc05783f20dd0da", "thread_id": 140638996727616, "hypothesis_output": [], "event_type": "AfterExecution"}
{"method": "GET", "path": "/AAYUSHGARGBU/api_petstore/1.0.0/user/logout", "verbose_name": "GET /AAYUSHGARGBU/api_petstore/1.0.0/user/logout", "relative_path": "/user/logout", "recursion_level": 0, "data_generation_method": ["positive", "negative"], "correlation_id": "3f5881e01c57465d8ec95b5c621d6a10", "thread_id": 140638996727616, "event_type": "BeforeExecution"}
{"method": "GET", "path": "/AAYUSHGARGBU/api_petstore/1.0.0/user/logout", "relative_path": "/user/logout", "verbose_name": "GET /AAYUSHGARGBU/api_petstore/1.0.0/user/logout", "status": "error", "data_generation_method": ["positive"], "result": {"method": "GET", "path": "/AAYUSHGARGBU/api_petstore/1.0.0/user/logout", "verbose_name": "GET /AAYUSHGARGBU/api_petstore/1.0.0/user/logout", "has_failures": false, "has_errors": true, "has_logs": false, "is_errored": true, "is_flaky": false, "is_skipped": false, "skip_reason": null, "seed": 57932623809996008151663850801588433753, "data_generation_method": ["P"], "checks": [], "logs": [], "errors": [{"type": "connection_other", "title": "Network Error", "message": "Connection failed", "extras": ["Failed to establish a new connection: [Errno -2] Name or service not known"], "exception": "requests.exceptions.ConnectionError: HTTPSConnectionPool(host='virtserver.swaggerhub.com', port=443): Max retries exceeded with url: /AAYUSHGARGBU/api_petstore/1.0.0/user/logout (Caused by NewConnectionError('<urllib3.connection.VerifiedHTTPSConnection object at 0x7fe90e363670>: Failed to establish a new connection: [Errno -2] Name or service not known'))", "exception_with_traceback": "Traceback (most recent call last):\n  File \"/usr/lib/python3/dist-packages/urllib3/connection.py\", line 156, in _new_conn\n    conn = connection.create_connection(\n  File \"/usr/lib/python3/dist-packages/urllib3/util/connection.py\", line 61, in create_connection\n    for res in socket.getaddrinfo(host, port, family, socket.SOCK_STREAM):\n  File \"/usr/lib/python3.8/socket.py\", line 918, in getaddrinfo\n    for res in _socket.getaddrinfo(host, port, family, type, proto, flags):\nsocket.gaierror: [Errno -2] Name or service not known\n\nDuring handling of the above exception, another exception occurred:\n\nTraceback (most recent call last):\n  File \"/usr/lib/python3/dist-packages/urllib3/connectionpool.py\", line 665, in urlopen\n    httplib_response = self._make_request(\n  File \"/usr/lib/python3/dist-packages/urllib3/connectionpool.py\", line 376, in _make_request\n    self._validate_conn(conn)\n  File \"/usr/lib/python3/dist-packages/urllib3/connectionpool.py\", line 996, in _validate_conn\n    conn.connect()\n  File \"/usr/lib/python3/dist-packages/urllib3/connection.py\", line 300, in connect\n    conn = self._new_conn()\n  File \"/usr/lib/python3/dist-packages/urllib3/connection.py\", line 168, in _new_conn\n    raise NewConnectionError(\nurllib3.exceptions.NewConnectionError: <urllib3.connection.VerifiedHTTPSConnection object at 0x7fe90e363670>: Failed to establish a new connection: [Errno -2] Name or service not known\n\nDuring handling of the above exception, another exception occurred:\n\nTraceback (most recent call last):\n  File \"/usr/local/lib/python3.8/dist-packages/requests/adapters.py\", line 486, in send\n    resp = conn.urlopen(\n  File \"/usr/lib/python3/dist-packages/urllib3/connectionpool.py\", line 719, in urlopen\n    retries = retries.increment(\n  File \"/usr/lib/python3/dist-packages/urllib3/util/retry.py\", line 436, in increment\n    raise MaxRetryError(_pool, url, error or ResponseError(cause))\nurllib3.exceptions.MaxRetryError: HTTPSConnectionPool(host='virtserver.swaggerhub.com', port=443): Max retries exceeded with url: /AAYUSHGARGBU/api_petstore/1.0.0/user/logout (Caused by NewConnectionError('<urllib3.connection.VerifiedHTTPSConnection object at 0x7fe90e363670>: Failed to establish a new connection: [Errno -2] Name or service not known'))\n\nDuring handling of the above exception, another exception occurred:\n\nTraceback (most recent call last):\n  File \"/usr/local/lib/python3.8/dist-packages/schemathesis/runner/impl/core.py\", line 816, in network_test\n    response = _network_test(case, *args)\n  File \"/usr/local/lib/python3.8/dist-packages/schemathesis/runner/impl/core.py\", line 848, in _network_test\n    response = case.call(**kwargs)\n  File \"/usr/local/lib/python3.8/dist-packages/schemathesis/models.py\", line 310, in call\n    response = self.operation.schema.transport.send(\n  File \"/usr/local/lib/python3.8/dist-packages/schemathesis/transports/__init__.py\", line 143, in send\n    response = session.request(**data)  # type: ignore\n  File \"/usr/local/lib/python3.8/dist-packages/requests/sessions.py\", line 589, in request\n    resp = self.send(prep, **send_kwargs)\n  File \"/usr/local/lib/python3.8/dist-packages/requests/sessions.py\", line 703, in send\n    r = adapter.send(request, **kwargs)\n  File \"/usr/local/lib/python3.8/dist-packages/requests/adapters.py\", line 519, in send\n    raise ConnectionError(e, request=request)\nrequests.exceptions.ConnectionError: HTTPSConnectionPool(host='virtserver.swaggerhub.com', port=443): Max retries exceeded with url: /AAYUSHGARGBU/api_petstore/1.0.0/user/logout (Caused by NewConnectionError('<urllib3.connection.VerifiedHTTPSConnection object at 0x7fe90e363670>: Failed to establish a new connection: [Errno -2] Name or service not known'))"}], "interactions": []}, "elapsed_time": 0.01533449999988079, "correlation_id": "3f5881e01c57465d8ec95b5c621d6a10", "thread_id": 140638996727616, "hypothesis_output": [], "event_type": "AfterExecution"}
{"method": "GET", "path": "/AAYUSHGARGBU/api_petstore/1.0.0/user/{username}", "verbose_name": "GET /AAYUSHGARGBU/api_petstore/1.0.0/user/{username}", "relative_path": "/user/{username}", "recursion_level": 0, "data_generation_method": ["positive", "negative"], "correlation_id": "b6b112949a154bc681d20dec342af31d", "thread_id": 140638996727616, "event_type": "BeforeExecution"}
{"method": "GET", "path": "/AAYUSHGARGBU/api_petstore/1.0.0/user/{username}", "relative_path": "/user/{username}", "verbose_name": "GET /AAYUSHGARGBU/api_petstore/1.0.0/user/{username}", "status": "error", "data_generation_method": ["positive"], "result": {"method": "GET", "path": "/AAYUSHGARGBU/api_petstore/1.0.0/user/{username}", "verbose_name": "GET /AAYUSHGARGBU/api_petstore/1.0.0/user/{username}", "has_failures": false, "has_errors": true, "has_logs": false, "is_errored": true, "is_flaky": false, "is_skipped": false, "skip_reason": null, "seed": 57932623809996008151663850801588433753, "data_generation_method": ["P"], "checks": [], "logs": [], "errors": [{"type": "connection_other", "title": "Network Error", "message": "Connection failed", "extras": ["Failed to establish a new connection: [Errno -2] Name or service not known"], "exception": "requests.exceptions.ConnectionError: HTTPSConnectionPool(host='virtserver.swaggerhub.com', port=443): Max retries exceeded with url: /AAYUSHGARGBU/api_petstore/1.0.0/user/0 (Caused by NewConnectionError('<urllib3.connection.VerifiedHTTPSConnection object at 0x7fe90e31d070>: Failed to establish a new connection: [Errno -2] Name or service not known'))", "exception_with_traceback": "Traceback (most recent call last):\n  File \"/usr/lib/python3/dist-packages/urllib3/connection.py\", line 156, in _new_conn\n    conn = connection.create_connection(\n  File \"/usr/lib/python3/dist-packages/urllib3/util/connection.py\", line 61, in create_connection\n    for res in socket.getaddrinfo(host, port, family, socket.SOCK_STREAM):\n  File \"/usr/lib/python3.8/socket.py\", line 918, in getaddrinfo\n    for res in _socket.getaddrinfo(host, port, family, type, proto, flags):\nsocket.gaierror: [Errno -2] Name or service not known\n\nDuring handling of the above exception, another exception occurred:\n\nTraceback (most recent call last):\n  File \"/usr/lib/python3/dist-packages/urllib3/connectionpool.py\", line 665, in urlopen\n    httplib_response = self._make_request(\n  File \"/usr/lib/python3/dist-packages/urllib3/connectionpool.py\", line 376, in _make_request\n    self._validate_conn(conn)\n  File \"/usr/lib/python3/dist-packages/urllib3/connectionpool.py\", line 996, in _validate_conn\n    conn.connect()\n  File \"/usr/lib/python3/dist-packages/urllib3/connection.py\", line 300, in connect\n    conn = self._new_conn()\n  File \"/usr/lib/python3/dist-packages/urllib3/connection.py\", line 168, in _new_conn\n    raise NewConnectionError(\nurllib3.exceptions.NewConnectionError: <urllib3.connection.VerifiedHTTPSConnection object at 0x7fe90e31d070>: Failed to establish a new connection: [Errno -2] Name or service not known\n\nDuring handling of the above exception, another exception occurred:\n\nTraceback (most recent call last):\n  File \"/usr/local/lib/python3.8/dist-packages/requests/adapters.py\", line 486, in send\n    resp = conn.urlopen(\n  File \"/usr/lib/python3/dist-packages/urllib3/connectionpool.py\", line 719, in urlopen\n    retries = retries.increment(\n  File \"/usr/lib/python3/dist-packages/urllib3/util/retry.py\", line 436, in increment\n    raise MaxRetryError(_pool, url, error or ResponseError(cause))\nurllib3.exceptions.MaxRetryError: HTTPSConnectionPool(host='virtserver.swaggerhub.com', port=443): Max retries exceeded with url: /AAYUSHGARGBU/api_petstore/1.0.0/user/0 (Caused by NewConnectionError('<urllib3.connection.VerifiedHTTPSConnection object at 0x7fe90e31d070>: Failed to establish a new connection: [Errno -2] Name or service not known'))\n\nDuring handling of the above exception, another exception occurred:\n\nTraceback (most recent call last):\n  File \"/usr/local/lib/python3.8/dist-packages/schemathesis/runner/impl/core.py\", line 816, in network_test\n    response = _network_test(case, *args)\n  File \"/usr/local/lib/python3.8/dist-packages/schemathesis/runner/impl/core.py\", line 848, in _network_test\n    response = case.call(**kwargs)\n  File \"/usr/local/lib/python3.8/dist-packages/schemathesis/models.py\", line 310, in call\n    response = self.operation.schema.transport.send(\n  File \"/usr/local/lib/python3.8/dist-packages/schemathesis/transports/__init__.py\", line 143, in send\n    response = session.request(**data)  # type: ignore\n  File \"/usr/local/lib/python3.8/dist-packages/requests/sessions.py\", line 589, in request\n    resp = self.send(prep, **send_kwargs)\n  File \"/usr/local/lib/python3.8/dist-packages/requests/sessions.py\", line 703, in send\n    r = adapter.send(request, **kwargs)\n  File \"/usr/local/lib/python3.8/dist-packages/requests/adapters.py\", line 519, in send\n    raise ConnectionError(e, request=request)\nrequests.exceptions.ConnectionError: HTTPSConnectionPool(host='virtserver.swaggerhub.com', port=443): Max retries exceeded with url: /AAYUSHGARGBU/api_petstore/1.0.0/user/0 (Caused by NewConnectionError('<urllib3.connection.VerifiedHTTPSConnection object at 0x7fe90e31d070>: Failed to establish a new connection: [Errno -2] Name or service not known'))"}], "interactions": []}, "elapsed_time": 0.05049419996794313, "correlation_id": "b6b112949a154bc681d20dec342af31d", "thread_id": 140638996727616, "hypothesis_output": [], "event_type": "AfterExecution"}
{"method": "PUT", "path": "/AAYUSHGARGBU/api_petstore/1.0.0/user/{username}", "verbose_name": "PUT /AAYUSHGARGBU/api_petstore/1.0.0/user/{username}", "relative_path": "/user/{username}", "recursion_level": 0, "data_generation_method": ["positive", "negative"], "correlation_id": "c05d7bab98964118b259cda6df3fc07d", "thread_id": 140638996727616, "event_type": "BeforeExecution"}
{"method": "PUT", "path": "/AAYUSHGARGBU/api_petstore/1.0.0/user/{username}", "relative_path": "/user/{username}", "verbose_name": "PUT /AAYUSHGARGBU/api_petstore/1.0.0/user/{username}", "status": "error", "data_generation_method": ["positive"], "result": {"method": "PUT", "path": "/AAYUSHGARGBU/api_petstore/1.0.0/user/{username}", "verbose_name": "PUT /AAYUSHGARGBU/api_petstore/1.0.0/user/{username}", "has_failures": false, "has_errors": true, "has_logs": false, "is_errored": true, "is_flaky": false, "is_skipped": false, "skip_reason": null, "seed": 57932623809996008151663850801588433753, "data_generation_method": ["P"], "checks": [], "logs": [], "errors": [{"type": "connection_other", "title": "Network Error", "message": "Connection failed", "extras": ["Failed to establish a new connection: [Errno -2] Name or service not known"], "exception": "requests.exceptions.ConnectionError: HTTPSConnectionPool(host='virtserver.swaggerhub.com', port=443): Max retries exceeded with url: /AAYUSHGARGBU/api_petstore/1.0.0/user/0 (Caused by NewConnectionError('<urllib3.connection.VerifiedHTTPSConnection object at 0x7fe90e32f340>: Failed to establish a new connection: [Errno -2] Name or service not known'))", "exception_with_traceback": "Traceback (most recent call last):\n  File \"/usr/lib/python3/dist-packages/urllib3/connection.py\", line 156, in _new_conn\n    conn = connection.create_connection(\n  File \"/usr/lib/python3/dist-packages/urllib3/util/connection.py\", line 61, in create_connection\n    for res in socket.getaddrinfo(host, port, family, socket.SOCK_STREAM):\n  File \"/usr/lib/python3.8/socket.py\", line 918, in getaddrinfo\n    for res in _socket.getaddrinfo(host, port, family, type, proto, flags):\nsocket.gaierror: [Errno -2] Name or service not known\n\nDuring handling of the above exception, another exception occurred:\n\nTraceback (most recent call last):\n  File \"/usr/lib/python3/dist-packages/urllib3/connectionpool.py\", line 665, in urlopen\n    httplib_response = self._make_request(\n  File \"/usr/lib/python3/dist-packages/urllib3/connectionpool.py\", line 376, in _make_request\n    self._validate_conn(conn)\n  File \"/usr/lib/python3/dist-packages/urllib3/connectionpool.py\", line 996, in _validate_conn\n    conn.connect()\n  File \"/usr/lib/python3/dist-packages/urllib3/connection.py\", line 300, in connect\n    conn = self._new_conn()\n  File \"/usr/lib/python3/dist-packages/urllib3/connection.py\", line 168, in _new_conn\n    raise NewConnectionError(\nurllib3.exceptions.NewConnectionError: <urllib3.connection.VerifiedHTTPSConnection object at 0x7fe90e32f340>: Failed to establish a new connection: [Errno -2] Name or service not known\n\nDuring handling of the above exception, another exception occurred:\n\nTraceback (most recent call last):\n  File \"/usr/local/lib/python3.8/dist-packages/requests/adapters.py\", line 486, in send\n    resp = conn.urlopen(\n  File \"/usr/lib/python3/dist-packages/urllib3/connectionpool.py\", line 719, in urlopen\n    retries = retries.increment(\n  File \"/usr/lib/python3/dist-packages/urllib3/util/retry.py\", line 436, in increment\n    raise MaxRetryError(_pool, url, error or ResponseError(cause))\nurllib3.exceptions.MaxRetryError: HTTPSConnectionPool(host='virtserver.swaggerhub.com', port=443): Max retries exceeded with url: /AAYUSHGARGBU/api_petstore/1.0.0/user/0 (Caused by NewConnectionError('<urllib3.connection.VerifiedHTTPSConnection object at 0x7fe90e32f340>: Failed to establish a new connection: [Errno -2] Name or service not known'))\n\nDuring handling of the above exception, another exception occurred:\n\nTraceback (most recent call last):\n  File \"/usr/local/lib/python3.8/dist-packages/schemathesis/runner/impl/core.py\", line 816, in network_test\n    response = _network_test(case, *args)\n  File \"/usr/local/lib/python3.8/dist-packages/schemathesis/runner/impl/core.py\", line 848, in _network_test\n    response = case.call(**kwargs)\n  File \"/usr/local/lib/python3.8/dist-packages/schemathesis/models.py\", line 310, in call\n    response = self.operation.schema.transport.send(\n  File \"/usr/local/lib/python3.8/dist-packages/schemathesis/transports/__init__.py\", line 143, in send\n    response = session.request(**data)  # type: ignore\n  File \"/usr/local/lib/python3.8/dist-packages/requests/sessions.py\", line 589, in request\n    resp = self.send(prep, **send_kwargs)\n  File \"/usr/local/lib/python3.8/dist-packages/requests/sessions.py\", line 703, in send\n    r = adapter.send(request, **kwargs)\n  File \"/usr/local/lib/python3.8/dist-packages/requests/adapters.py\", line 519, in send\n    raise ConnectionError(e, request=request)\nrequests.exceptions.ConnectionError: HTTPSConnectionPool(host='virtserver.swaggerhub.com', port=443): Max retries exceeded with url: /AAYUSHGARGBU/api_petstore/1.0.0/user/0 (Caused by NewConnectionError('<urllib3.connection.VerifiedHTTPSConnection object at 0x7fe90e32f340>: Failed to establish a new connection: [Errno -2] Name or service not known'))"}], "interactions": []}, "elapsed_time": 0.06070449994876981, "correlation_id": "c05d7bab98964118b259cda6df3fc07d", "thread_id": 140638996727616, "hypothesis_output": [], "event_type": "AfterExecution"}
{"method": "DELETE", "path": "/AAYUSHGARGBU/api_petstore/1.0.0/user/{username}", "verbose_name": "DELETE /AAYUSHGARGBU/api_petstore/1.0.0/user/{username}", "relative_path": "/user/{username}", "recursion_level": 0, "data_generation_method": ["positive", "negative"], "correlation_id": "1b8207b219924005a01667a7d7a946b6", "thread_id": 140638996727616, "event_type": "BeforeExecution"}
{"method": "DELETE", "path": "/AAYUSHGARGBU/api_petstore/1.0.0/user/{username}", "relative_path": "/user/{username}", "verbose_name": "DELETE /AAYUSHGARGBU/api_petstore/1.0.0/user/{username}", "status": "error", "data_generation_method": ["positive"], "result": {"method": "DELETE", "path": "/AAYUSHGARGBU/api_petstore/1.0.0/user/{username}", "verbose_name": "DELETE /AAYUSHGARGBU/api_petstore/1.0.0/user/{username}", "has_failures": false, "has_errors": true, "has_logs": false, "is_errored": true, "is_flaky": false, "is_skipped": false, "skip_reason": null, "seed": 57932623809996008151663850801588433753, "data_generation_method": ["P"], "checks": [], "logs": [], "errors": [{"type": "connection_other", "title": "Network Error", "message": "Connection failed", "extras": ["Failed to establish a new connection: [Errno -2] Name or service not known"], "exception": "requests.exceptions.ConnectionError: HTTPSConnectionPool(host='virtserver.swaggerhub.com', port=443): Max retries exceeded with url: /AAYUSHGARGBU/api_petstore/1.0.0/user/0 (Caused by NewConnectionError('<urllib3.connection.VerifiedHTTPSConnection object at 0x7fe90e1f8610>: Failed to establish a new connection: [Errno -2] Name or service not known'))", "exception_with_traceback": "Traceback (most recent call last):\n  File \"/usr/lib/python3/dist-packages/urllib3/connection.py\", line 156, in _new_conn\n    conn = connection.create_connection(\n  File \"/usr/lib/python3/dist-packages/urllib3/util/connection.py\", line 61, in create_connection\n    for res in socket.getaddrinfo(host, port, family, socket.SOCK_STREAM):\n  File \"/usr/lib/python3.8/socket.py\", line 918, in getaddrinfo\n    for res in _socket.getaddrinfo(host, port, family, type, proto, flags):\nsocket.gaierror: [Errno -2] Name or service not known\n\nDuring handling of the above exception, another exception occurred:\n\nTraceback (most recent call last):\n  File \"/usr/lib/python3/dist-packages/urllib3/connectionpool.py\", line 665, in urlopen\n    httplib_response = self._make_request(\n  File \"/usr/lib/python3/dist-packages/urllib3/connectionpool.py\", line 376, in _make_request\n    self._validate_conn(conn)\n  File \"/usr/lib/python3/dist-packages/urllib3/connectionpool.py\", line 996, in _validate_conn\n    conn.connect()\n  File \"/usr/lib/python3/dist-packages/urllib3/connection.py\", line 300, in connect\n    conn = self._new_conn()\n  File \"/usr/lib/python3/dist-packages/urllib3/connection.py\", line 168, in _new_conn\n    raise NewConnectionError(\nurllib3.exceptions.NewConnectionError: <urllib3.connection.VerifiedHTTPSConnection object at 0x7fe90e1f8610>: Failed to establish a new connection: [Errno -2] Name or service not known\n\nDuring handling of the above exception, another exception occurred:\n\nTraceback (most recent call last):\n  File \"/usr/local/lib/python3.8/dist-packages/requests/adapters.py\", line 486, in send\n    resp = conn.urlopen(\n  File \"/usr/lib/python3/dist-packages/urllib3/connectionpool.py\", line 719, in urlopen\n    retries = retries.increment(\n  File \"/usr/lib/python3/dist-packages/urllib3/util/retry.py\", line 436, in increment\n    raise MaxRetryError(_pool, url, error or ResponseError(cause))\nurllib3.exceptions.MaxRetryError: HTTPSConnectionPool(host='virtserver.swaggerhub.com', port=443): Max retries exceeded with url: /AAYUSHGARGBU/api_petstore/1.0.0/user/0 (Caused by NewConnectionError('<urllib3.connection.VerifiedHTTPSConnection object at 0x7fe90e1f8610>: Failed to establish a new connection: [Errno -2] Name or service not known'))\n\nDuring handling of the above exception, another exception occurred:\n\nTraceback (most recent call last):\n  File \"/usr/local/lib/python3.8/dist-packages/schemathesis/runner/impl/core.py\", line 816, in network_test\n    response = _network_test(case, *args)\n  File \"/usr/local/lib/python3.8/dist-packages/schemathesis/runner/impl/core.py\", line 848, in _network_test\n    response = case.call(**kwargs)\n  File \"/usr/local/lib/python3.8/dist-packages/schemathesis/models.py\", line 310, in call\n    response = self.operation.schema.transport.send(\n  File \"/usr/local/lib/python3.8/dist-packages/schemathesis/transports/__init__.py\", line 143, in send\n    response = session.request(**data)  # type: ignore\n  File \"/usr/local/lib/python3.8/dist-packages/requests/sessions.py\", line 589, in request\n    resp = self.send(prep, **send_kwargs)\n  File \"/usr/local/lib/python3.8/dist-packages/requests/sessions.py\", line 703, in send\n    r = adapter.send(request, **kwargs)\n  File \"/usr/local/lib/python3.8/dist-packages/requests/adapters.py\", line 519, in send\n    raise ConnectionError(e, request=request)\nrequests.exceptions.ConnectionError: HTTPSConnectionPool(host='virtserver.swaggerhub.com', port=443): Max retries exceeded with url: /AAYUSHGARGBU/api_petstore/1.0.0/user/0 (Caused by NewConnectionError('<urllib3.connection.VerifiedHTTPSConnection object at 0x7fe90e1f8610>: Failed to establish a new connection: [Errno -2] Name or service not known'))"}], "interactions": []}, "elapsed_time": 0.07821780000813305, "correlation_id": "1b8207b219924005a01667a7d7a946b6", "thread_id": 140638996727616, "hypothesis_output": [], "event_type": "AfterExecution"}
{"passed_count": 0, "skipped_count": 0, "failed_count": 0, "errored_count": 20, "has_failures": false, "has_errors": true, "has_logs": false, "is_empty": false, "generic_errors": [], "warnings": [], "total": {}, "running_time": 1321.5039245000808, "thread_id": 140638996727616, "event_type": "Finished"}
