{"schema": {"openapi": "3.0.0", "info": {"title": "Simple Item API", "description": "An API to demonstrate basic CRUD operations on items.", "version": "1.0.0"}, "servers": [{"description": "SwaggerHub API Auto Mocking", "url": "https://virtserver.swaggerhub.com/AAYUSHGARGBU/Simple_API/1.0.0"}], "paths": {"/items": {"get": {"summary": "List all items", "operationId": "listItems", "responses": {"200": {"description": "A list of items", "content": {"application/json": {"schema": {"type": "array", "items": {"$ref": "#/components/schemas/Item"}}}}}}}, "post": {"summary": "Create a new item", "operationId": "createItem", "requestBody": {"required": true, "content": {"application/json": {"schema": {"$ref": "#/components/schemas/Item"}}}}, "responses": {"201": {"description": "Created item", "content": {"application/json": {"schema": {"$ref": "#/components/schemas/Item"}}}}}}}, "/items/{itemId}": {"get": {"summary": "Get an item by ID", "operationId": "getItem", "parameters": [{"in": "path", "name": "itemId", "required": true, "schema": {"type": "integer"}}], "responses": {"200": {"description": "An item", "content": {"application/json": {"schema": {"$ref": "#/components/schemas/Item"}}}}}}, "put": {"summary": "Update an item by ID", "operationId": "updateItem", "parameters": [{"in": "path", "name": "itemId", "required": true, "schema": {"type": "integer"}}], "requestBody": {"required": true, "content": {"application/json": {"schema": {"$ref": "#/components/schemas/Item"}}}}, "responses": {"200": {"description": "Updated item", "content": {"application/json": {"schema": {"$ref": "#/components/schemas/Item"}}}}}}, "delete": {"summary": "Delete an item by ID", "operationId": "deleteItem", "parameters": [{"in": "path", "name": "itemId", "required": true, "schema": {"type": "integer"}}], "responses": {"204": {"description": "Item deleted"}}}}}, "components": {"schemas": {"Item": {"type": "object", "required": ["id", "name"], "properties": {"id": {"type": "integer", "description": "Unique identifier of the item"}, "name": {"type": "string", "description": "Name of the item"}}}}}}, "operations_count": 5, "links_count": 0, "location": "file:///mnt/d/ag/github/lazarus_target_apis/data/api_simple_items/api_simple_items.json", "seed": 256044834742398664162804879315084466152, "base_url": "https://virtserver.swaggerhub.com/AAYUSHGARGBU/Simple_API/1.0.0", "specification_name": "Open API 3.0.0", "start_time": 547631.3789583, "started_at": "2024-05-28T08:33:30.458938+02:00", "thread_id": 140412414527296, "event_type": "Initialized"}
{"event_type": "BeforeProbing"}
{"probes": [{"name": "NULL_BYTE_IN_HEADER", "outcome": "error", "request": {"method": "GET", "uri": "https://virtserver.swaggerhub.com/AAYUSHGARGBU/Simple_API/1.0.0", "body": null, "headers": {"User-Agent": ["schemathesis/3.27.1"], "Accept-Encoding": ["gzip, deflate"], "Accept": ["*/*"], "Connection": ["keep-alive"], "X-Schemathesis-Probe-Null": ["\u0000"], "X-Schemathesis-Probe": ["NULL_BYTE_IN_HEADER"]}}, "response": null, "error": "requests.exceptions.ConnectionError: HTTPSConnectionPool(host='virtserver.swaggerhub.com', port=443): Max retries exceeded with url: /AAYUSHGARGBU/Simple_API/1.0.0 (Caused by NewConnectionError('<urllib3.connection.VerifiedHTTPSConnection object at 0x7fb44d413730>: Failed to establish a new connection: [Errno -3] Temporary failure in name resolution'))"}], "events_type": "AfterProbing"}
{"event_type": "BeforeAnalysis"}
{"analysis": null, "event_type": "AfterAnalysis"}
{"method": "GET", "path": "/AAYUSHGARGBU/Simple_API/1.0.0/items", "verbose_name": "GET /AAYUSHGARGBU/Simple_API/1.0.0/items", "relative_path": "/items", "recursion_level": 0, "data_generation_method": ["positive", "negative"], "correlation_id": "cfb3332a79604421aae5e77433f20e94", "thread_id": 140412414527296, "event_type": "BeforeExecution"}
{"method": "GET", "path": "/AAYUSHGARGBU/Simple_API/1.0.0/items", "relative_path": "/items", "verbose_name": "GET /AAYUSHGARGBU/Simple_API/1.0.0/items", "status": "error", "data_generation_method": ["positive"], "result": {"method": "GET", "path": "/AAYUSHGARGBU/Simple_API/1.0.0/items", "verbose_name": "GET /AAYUSHGARGBU/Simple_API/1.0.0/items", "has_failures": false, "has_errors": true, "has_logs": false, "is_errored": true, "is_flaky": false, "is_skipped": false, "skip_reason": null, "seed": 256044834742398664162804879315084466152, "data_generation_method": ["P"], "checks": [], "logs": [], "errors": [{"type": "connection_other", "title": "Network Error", "message": "Connection failed", "extras": ["Failed to establish a new connection: [Errno -3] Temporary failure in name resolution"], "exception": "requests.exceptions.ConnectionError: HTTPSConnectionPool(host='virtserver.swaggerhub.com', port=443): Max retries exceeded with url: /AAYUSHGARGBU/Simple_API/1.0.0/items (Caused by NewConnectionError('<urllib3.connection.VerifiedHTTPSConnection object at 0x7fb44d2a4c10>: Failed to establish a new connection: [Errno -3] Temporary failure in name resolution'))", "exception_with_traceback": "Traceback (most recent call last):\n  File \"/usr/lib/python3/dist-packages/urllib3/connection.py\", line 156, in _new_conn\n    conn = connection.create_connection(\n  File \"/usr/lib/python3/dist-packages/urllib3/util/connection.py\", line 61, in create_connection\n    for res in socket.getaddrinfo(host, port, family, socket.SOCK_STREAM):\n  File \"/usr/lib/python3.8/socket.py\", line 918, in getaddrinfo\n    for res in _socket.getaddrinfo(host, port, family, type, proto, flags):\nsocket.gaierror: [Errno -3] Temporary failure in name resolution\n\nDuring handling of the above exception, another exception occurred:\n\nTraceback (most recent call last):\n  File \"/usr/lib/python3/dist-packages/urllib3/connectionpool.py\", line 665, in urlopen\n    httplib_response = self._make_request(\n  File \"/usr/lib/python3/dist-packages/urllib3/connectionpool.py\", line 376, in _make_request\n    self._validate_conn(conn)\n  File \"/usr/lib/python3/dist-packages/urllib3/connectionpool.py\", line 996, in _validate_conn\n    conn.connect()\n  File \"/usr/lib/python3/dist-packages/urllib3/connection.py\", line 300, in connect\n    conn = self._new_conn()\n  File \"/usr/lib/python3/dist-packages/urllib3/connection.py\", line 168, in _new_conn\n    raise NewConnectionError(\nurllib3.exceptions.NewConnectionError: <urllib3.connection.VerifiedHTTPSConnection object at 0x7fb44d2a4c10>: Failed to establish a new connection: [Errno -3] Temporary failure in name resolution\n\nDuring handling of the above exception, another exception occurred:\n\nTraceback (most recent call last):\n  File \"/usr/local/lib/python3.8/dist-packages/requests/adapters.py\", line 486, in send\n    resp = conn.urlopen(\n  File \"/usr/lib/python3/dist-packages/urllib3/connectionpool.py\", line 719, in urlopen\n    retries = retries.increment(\n  File \"/usr/lib/python3/dist-packages/urllib3/util/retry.py\", line 436, in increment\n    raise MaxRetryError(_pool, url, error or ResponseError(cause))\nurllib3.exceptions.MaxRetryError: HTTPSConnectionPool(host='virtserver.swaggerhub.com', port=443): Max retries exceeded with url: /AAYUSHGARGBU/Simple_API/1.0.0/items (Caused by NewConnectionError('<urllib3.connection.VerifiedHTTPSConnection object at 0x7fb44d2a4c10>: Failed to establish a new connection: [Errno -3] Temporary failure in name resolution'))\n\nDuring handling of the above exception, another exception occurred:\n\nTraceback (most recent call last):\n  File \"/usr/local/lib/python3.8/dist-packages/schemathesis/runner/impl/core.py\", line 816, in network_test\n    response = _network_test(case, *args)\n  File \"/usr/local/lib/python3.8/dist-packages/schemathesis/runner/impl/core.py\", line 848, in _network_test\n    response = case.call(**kwargs)\n  File \"/usr/local/lib/python3.8/dist-packages/schemathesis/models.py\", line 310, in call\n    response = self.operation.schema.transport.send(\n  File \"/usr/local/lib/python3.8/dist-packages/schemathesis/transports/__init__.py\", line 143, in send\n    response = session.request(**data)  # type: ignore\n  File \"/usr/local/lib/python3.8/dist-packages/requests/sessions.py\", line 589, in request\n    resp = self.send(prep, **send_kwargs)\n  File \"/usr/local/lib/python3.8/dist-packages/requests/sessions.py\", line 703, in send\n    r = adapter.send(request, **kwargs)\n  File \"/usr/local/lib/python3.8/dist-packages/requests/adapters.py\", line 519, in send\n    raise ConnectionError(e, request=request)\nrequests.exceptions.ConnectionError: HTTPSConnectionPool(host='virtserver.swaggerhub.com', port=443): Max retries exceeded with url: /AAYUSHGARGBU/Simple_API/1.0.0/items (Caused by NewConnectionError('<urllib3.connection.VerifiedHTTPSConnection object at 0x7fb44d2a4c10>: Failed to establish a new connection: [Errno -3] Temporary failure in name resolution'))"}], "interactions": []}, "elapsed_time": 66.09885920002125, "correlation_id": "cfb3332a79604421aae5e77433f20e94", "thread_id": 140412414527296, "hypothesis_output": [], "event_type": "AfterExecution"}
{"method": "POST", "path": "/AAYUSHGARGBU/Simple_API/1.0.0/items", "verbose_name": "POST /AAYUSHGARGBU/Simple_API/1.0.0/items", "relative_path": "/items", "recursion_level": 0, "data_generation_method": ["positive", "negative"], "correlation_id": "a2d55105e51d41ff942d77c5b077318c", "thread_id": 140412414527296, "event_type": "BeforeExecution"}
{"method": "POST", "path": "/AAYUSHGARGBU/Simple_API/1.0.0/items", "relative_path": "/items", "verbose_name": "POST /AAYUSHGARGBU/Simple_API/1.0.0/items", "status": "error", "data_generation_method": ["positive"], "result": {"method": "POST", "path": "/AAYUSHGARGBU/Simple_API/1.0.0/items", "verbose_name": "POST /AAYUSHGARGBU/Simple_API/1.0.0/items", "has_failures": false, "has_errors": true, "has_logs": false, "is_errored": true, "is_flaky": false, "is_skipped": false, "skip_reason": null, "seed": 256044834742398664162804879315084466152, "data_generation_method": ["P"], "checks": [], "logs": [], "errors": [{"type": "connection_other", "title": "Network Error", "message": "Connection failed", "extras": ["Failed to establish a new connection: [Errno -3] Temporary failure in name resolution"], "exception": "requests.exceptions.ConnectionError: HTTPSConnectionPool(host='virtserver.swaggerhub.com', port=443): Max retries exceeded with url: /AAYUSHGARGBU/Simple_API/1.0.0/items (Caused by NewConnectionError('<urllib3.connection.VerifiedHTTPSConnection object at 0x7fb44d24bdc0>: Failed to establish a new connection: [Errno -3] Temporary failure in name resolution'))", "exception_with_traceback": "Traceback (most recent call last):\n  File \"/usr/lib/python3/dist-packages/urllib3/connection.py\", line 156, in _new_conn\n    conn = connection.create_connection(\n  File \"/usr/lib/python3/dist-packages/urllib3/util/connection.py\", line 61, in create_connection\n    for res in socket.getaddrinfo(host, port, family, socket.SOCK_STREAM):\n  File \"/usr/lib/python3.8/socket.py\", line 918, in getaddrinfo\n    for res in _socket.getaddrinfo(host, port, family, type, proto, flags):\nsocket.gaierror: [Errno -3] Temporary failure in name resolution\n\nDuring handling of the above exception, another exception occurred:\n\nTraceback (most recent call last):\n  File \"/usr/lib/python3/dist-packages/urllib3/connectionpool.py\", line 665, in urlopen\n    httplib_response = self._make_request(\n  File \"/usr/lib/python3/dist-packages/urllib3/connectionpool.py\", line 376, in _make_request\n    self._validate_conn(conn)\n  File \"/usr/lib/python3/dist-packages/urllib3/connectionpool.py\", line 996, in _validate_conn\n    conn.connect()\n  File \"/usr/lib/python3/dist-packages/urllib3/connection.py\", line 300, in connect\n    conn = self._new_conn()\n  File \"/usr/lib/python3/dist-packages/urllib3/connection.py\", line 168, in _new_conn\n    raise NewConnectionError(\nurllib3.exceptions.NewConnectionError: <urllib3.connection.VerifiedHTTPSConnection object at 0x7fb44d24bdc0>: Failed to establish a new connection: [Errno -3] Temporary failure in name resolution\n\nDuring handling of the above exception, another exception occurred:\n\nTraceback (most recent call last):\n  File \"/usr/local/lib/python3.8/dist-packages/requests/adapters.py\", line 486, in send\n    resp = conn.urlopen(\n  File \"/usr/lib/python3/dist-packages/urllib3/connectionpool.py\", line 719, in urlopen\n    retries = retries.increment(\n  File \"/usr/lib/python3/dist-packages/urllib3/util/retry.py\", line 436, in increment\n    raise MaxRetryError(_pool, url, error or ResponseError(cause))\nurllib3.exceptions.MaxRetryError: HTTPSConnectionPool(host='virtserver.swaggerhub.com', port=443): Max retries exceeded with url: /AAYUSHGARGBU/Simple_API/1.0.0/items (Caused by NewConnectionError('<urllib3.connection.VerifiedHTTPSConnection object at 0x7fb44d24bdc0>: Failed to establish a new connection: [Errno -3] Temporary failure in name resolution'))\n\nDuring handling of the above exception, another exception occurred:\n\nTraceback (most recent call last):\n  File \"/usr/local/lib/python3.8/dist-packages/schemathesis/runner/impl/core.py\", line 816, in network_test\n    response = _network_test(case, *args)\n  File \"/usr/local/lib/python3.8/dist-packages/schemathesis/runner/impl/core.py\", line 848, in _network_test\n    response = case.call(**kwargs)\n  File \"/usr/local/lib/python3.8/dist-packages/schemathesis/models.py\", line 310, in call\n    response = self.operation.schema.transport.send(\n  File \"/usr/local/lib/python3.8/dist-packages/schemathesis/transports/__init__.py\", line 143, in send\n    response = session.request(**data)  # type: ignore\n  File \"/usr/local/lib/python3.8/dist-packages/requests/sessions.py\", line 589, in request\n    resp = self.send(prep, **send_kwargs)\n  File \"/usr/local/lib/python3.8/dist-packages/requests/sessions.py\", line 703, in send\n    r = adapter.send(request, **kwargs)\n  File \"/usr/local/lib/python3.8/dist-packages/requests/adapters.py\", line 519, in send\n    raise ConnectionError(e, request=request)\nrequests.exceptions.ConnectionError: HTTPSConnectionPool(host='virtserver.swaggerhub.com', port=443): Max retries exceeded with url: /AAYUSHGARGBU/Simple_API/1.0.0/items (Caused by NewConnectionError('<urllib3.connection.VerifiedHTTPSConnection object at 0x7fb44d24bdc0>: Failed to establish a new connection: [Errno -3] Temporary failure in name resolution'))"}], "interactions": []}, "elapsed_time": 110.14730809989851, "correlation_id": "a2d55105e51d41ff942d77c5b077318c", "thread_id": 140412414527296, "hypothesis_output": [], "event_type": "AfterExecution"}
{"method": "GET", "path": "/AAYUSHGARGBU/Simple_API/1.0.0/items/{itemId}", "verbose_name": "GET /AAYUSHGARGBU/Simple_API/1.0.0/items/{itemId}", "relative_path": "/items/{itemId}", "recursion_level": 0, "data_generation_method": ["positive", "negative"], "correlation_id": "690fddba2bb1437db46741d25b1c1081", "thread_id": 140412414527296, "event_type": "BeforeExecution"}
{"method": "GET", "path": "/AAYUSHGARGBU/Simple_API/1.0.0/items/{itemId}", "relative_path": "/items/{itemId}", "verbose_name": "GET /AAYUSHGARGBU/Simple_API/1.0.0/items/{itemId}", "status": "error", "data_generation_method": ["positive"], "result": {"method": "GET", "path": "/AAYUSHGARGBU/Simple_API/1.0.0/items/{itemId}", "verbose_name": "GET /AAYUSHGARGBU/Simple_API/1.0.0/items/{itemId}", "has_failures": false, "has_errors": true, "has_logs": false, "is_errored": true, "is_flaky": false, "is_skipped": false, "skip_reason": null, "seed": 256044834742398664162804879315084466152, "data_generation_method": ["P"], "checks": [], "logs": [], "errors": [{"type": "connection_other", "title": "Network Error", "message": "Connection failed", "extras": ["Failed to establish a new connection: [Errno -3] Temporary failure in name resolution"], "exception": "requests.exceptions.ConnectionError: HTTPSConnectionPool(host='virtserver.swaggerhub.com', port=443): Max retries exceeded with url: /AAYUSHGARGBU/Simple_API/1.0.0/items/0 (Caused by NewConnectionError('<urllib3.connection.VerifiedHTTPSConnection object at 0x7fb44d1499a0>: Failed to establish a new connection: [Errno -3] Temporary failure in name resolution'))", "exception_with_traceback": "Traceback (most recent call last):\n  File \"/usr/lib/python3/dist-packages/urllib3/connection.py\", line 156, in _new_conn\n    conn = connection.create_connection(\n  File \"/usr/lib/python3/dist-packages/urllib3/util/connection.py\", line 61, in create_connection\n    for res in socket.getaddrinfo(host, port, family, socket.SOCK_STREAM):\n  File \"/usr/lib/python3.8/socket.py\", line 918, in getaddrinfo\n    for res in _socket.getaddrinfo(host, port, family, type, proto, flags):\nsocket.gaierror: [Errno -3] Temporary failure in name resolution\n\nDuring handling of the above exception, another exception occurred:\n\nTraceback (most recent call last):\n  File \"/usr/lib/python3/dist-packages/urllib3/connectionpool.py\", line 665, in urlopen\n    httplib_response = self._make_request(\n  File \"/usr/lib/python3/dist-packages/urllib3/connectionpool.py\", line 376, in _make_request\n    self._validate_conn(conn)\n  File \"/usr/lib/python3/dist-packages/urllib3/connectionpool.py\", line 996, in _validate_conn\n    conn.connect()\n  File \"/usr/lib/python3/dist-packages/urllib3/connection.py\", line 300, in connect\n    conn = self._new_conn()\n  File \"/usr/lib/python3/dist-packages/urllib3/connection.py\", line 168, in _new_conn\n    raise NewConnectionError(\nurllib3.exceptions.NewConnectionError: <urllib3.connection.VerifiedHTTPSConnection object at 0x7fb44d1499a0>: Failed to establish a new connection: [Errno -3] Temporary failure in name resolution\n\nDuring handling of the above exception, another exception occurred:\n\nTraceback (most recent call last):\n  File \"/usr/local/lib/python3.8/dist-packages/requests/adapters.py\", line 486, in send\n    resp = conn.urlopen(\n  File \"/usr/lib/python3/dist-packages/urllib3/connectionpool.py\", line 719, in urlopen\n    retries = retries.increment(\n  File \"/usr/lib/python3/dist-packages/urllib3/util/retry.py\", line 436, in increment\n    raise MaxRetryError(_pool, url, error or ResponseError(cause))\nurllib3.exceptions.MaxRetryError: HTTPSConnectionPool(host='virtserver.swaggerhub.com', port=443): Max retries exceeded with url: /AAYUSHGARGBU/Simple_API/1.0.0/items/0 (Caused by NewConnectionError('<urllib3.connection.VerifiedHTTPSConnection object at 0x7fb44d1499a0>: Failed to establish a new connection: [Errno -3] Temporary failure in name resolution'))\n\nDuring handling of the above exception, another exception occurred:\n\nTraceback (most recent call last):\n  File \"/usr/local/lib/python3.8/dist-packages/schemathesis/runner/impl/core.py\", line 816, in network_test\n    response = _network_test(case, *args)\n  File \"/usr/local/lib/python3.8/dist-packages/schemathesis/runner/impl/core.py\", line 848, in _network_test\n    response = case.call(**kwargs)\n  File \"/usr/local/lib/python3.8/dist-packages/schemathesis/models.py\", line 310, in call\n    response = self.operation.schema.transport.send(\n  File \"/usr/local/lib/python3.8/dist-packages/schemathesis/transports/__init__.py\", line 143, in send\n    response = session.request(**data)  # type: ignore\n  File \"/usr/local/lib/python3.8/dist-packages/requests/sessions.py\", line 589, in request\n    resp = self.send(prep, **send_kwargs)\n  File \"/usr/local/lib/python3.8/dist-packages/requests/sessions.py\", line 703, in send\n    r = adapter.send(request, **kwargs)\n  File \"/usr/local/lib/python3.8/dist-packages/requests/adapters.py\", line 519, in send\n    raise ConnectionError(e, request=request)\nrequests.exceptions.ConnectionError: HTTPSConnectionPool(host='virtserver.swaggerhub.com', port=443): Max retries exceeded with url: /AAYUSHGARGBU/Simple_API/1.0.0/items/0 (Caused by NewConnectionError('<urllib3.connection.VerifiedHTTPSConnection object at 0x7fb44d1499a0>: Failed to establish a new connection: [Errno -3] Temporary failure in name resolution'))"}], "interactions": []}, "elapsed_time": 154.14259430009406, "correlation_id": "690fddba2bb1437db46741d25b1c1081", "thread_id": 140412414527296, "hypothesis_output": [], "event_type": "AfterExecution"}
{"method": "PUT", "path": "/AAYUSHGARGBU/Simple_API/1.0.0/items/{itemId}", "verbose_name": "PUT /AAYUSHGARGBU/Simple_API/1.0.0/items/{itemId}", "relative_path": "/items/{itemId}", "recursion_level": 0, "data_generation_method": ["positive", "negative"], "correlation_id": "a9bd35fe69154da3bfe140c028807532", "thread_id": 140412414527296, "event_type": "BeforeExecution"}
{"method": "PUT", "path": "/AAYUSHGARGBU/Simple_API/1.0.0/items/{itemId}", "relative_path": "/items/{itemId}", "verbose_name": "PUT /AAYUSHGARGBU/Simple_API/1.0.0/items/{itemId}", "status": "error", "data_generation_method": ["positive"], "result": {"method": "PUT", "path": "/AAYUSHGARGBU/Simple_API/1.0.0/items/{itemId}", "verbose_name": "PUT /AAYUSHGARGBU/Simple_API/1.0.0/items/{itemId}", "has_failures": false, "has_errors": true, "has_logs": false, "is_errored": true, "is_flaky": false, "is_skipped": false, "skip_reason": null, "seed": 256044834742398664162804879315084466152, "data_generation_method": ["P"], "checks": [], "logs": [], "errors": [{"type": "connection_other", "title": "Network Error", "message": "Connection failed", "extras": ["Failed to establish a new connection: [Errno -3] Temporary failure in name resolution"], "exception": "requests.exceptions.ConnectionError: HTTPSConnectionPool(host='virtserver.swaggerhub.com', port=443): Max retries exceeded with url: /AAYUSHGARGBU/Simple_API/1.0.0/items/0 (Caused by NewConnectionError('<urllib3.connection.VerifiedHTTPSConnection object at 0x7fb44d0ab700>: Failed to establish a new connection: [Errno -3] Temporary failure in name resolution'))", "exception_with_traceback": "Traceback (most recent call last):\n  File \"/usr/lib/python3/dist-packages/urllib3/connection.py\", line 156, in _new_conn\n    conn = connection.create_connection(\n  File \"/usr/lib/python3/dist-packages/urllib3/util/connection.py\", line 61, in create_connection\n    for res in socket.getaddrinfo(host, port, family, socket.SOCK_STREAM):\n  File \"/usr/lib/python3.8/socket.py\", line 918, in getaddrinfo\n    for res in _socket.getaddrinfo(host, port, family, type, proto, flags):\nsocket.gaierror: [Errno -3] Temporary failure in name resolution\n\nDuring handling of the above exception, another exception occurred:\n\nTraceback (most recent call last):\n  File \"/usr/lib/python3/dist-packages/urllib3/connectionpool.py\", line 665, in urlopen\n    httplib_response = self._make_request(\n  File \"/usr/lib/python3/dist-packages/urllib3/connectionpool.py\", line 376, in _make_request\n    self._validate_conn(conn)\n  File \"/usr/lib/python3/dist-packages/urllib3/connectionpool.py\", line 996, in _validate_conn\n    conn.connect()\n  File \"/usr/lib/python3/dist-packages/urllib3/connection.py\", line 300, in connect\n    conn = self._new_conn()\n  File \"/usr/lib/python3/dist-packages/urllib3/connection.py\", line 168, in _new_conn\n    raise NewConnectionError(\nurllib3.exceptions.NewConnectionError: <urllib3.connection.VerifiedHTTPSConnection object at 0x7fb44d0ab700>: Failed to establish a new connection: [Errno -3] Temporary failure in name resolution\n\nDuring handling of the above exception, another exception occurred:\n\nTraceback (most recent call last):\n  File \"/usr/local/lib/python3.8/dist-packages/requests/adapters.py\", line 486, in send\n    resp = conn.urlopen(\n  File \"/usr/lib/python3/dist-packages/urllib3/connectionpool.py\", line 719, in urlopen\n    retries = retries.increment(\n  File \"/usr/lib/python3/dist-packages/urllib3/util/retry.py\", line 436, in increment\n    raise MaxRetryError(_pool, url, error or ResponseError(cause))\nurllib3.exceptions.MaxRetryError: HTTPSConnectionPool(host='virtserver.swaggerhub.com', port=443): Max retries exceeded with url: /AAYUSHGARGBU/Simple_API/1.0.0/items/0 (Caused by NewConnectionError('<urllib3.connection.VerifiedHTTPSConnection object at 0x7fb44d0ab700>: Failed to establish a new connection: [Errno -3] Temporary failure in name resolution'))\n\nDuring handling of the above exception, another exception occurred:\n\nTraceback (most recent call last):\n  File \"/usr/local/lib/python3.8/dist-packages/schemathesis/runner/impl/core.py\", line 816, in network_test\n    response = _network_test(case, *args)\n  File \"/usr/local/lib/python3.8/dist-packages/schemathesis/runner/impl/core.py\", line 848, in _network_test\n    response = case.call(**kwargs)\n  File \"/usr/local/lib/python3.8/dist-packages/schemathesis/models.py\", line 310, in call\n    response = self.operation.schema.transport.send(\n  File \"/usr/local/lib/python3.8/dist-packages/schemathesis/transports/__init__.py\", line 143, in send\n    response = session.request(**data)  # type: ignore\n  File \"/usr/local/lib/python3.8/dist-packages/requests/sessions.py\", line 589, in request\n    resp = self.send(prep, **send_kwargs)\n  File \"/usr/local/lib/python3.8/dist-packages/requests/sessions.py\", line 703, in send\n    r = adapter.send(request, **kwargs)\n  File \"/usr/local/lib/python3.8/dist-packages/requests/adapters.py\", line 519, in send\n    raise ConnectionError(e, request=request)\nrequests.exceptions.ConnectionError: HTTPSConnectionPool(host='virtserver.swaggerhub.com', port=443): Max retries exceeded with url: /AAYUSHGARGBU/Simple_API/1.0.0/items/0 (Caused by NewConnectionError('<urllib3.connection.VerifiedHTTPSConnection object at 0x7fb44d0ab700>: Failed to establish a new connection: [Errno -3] Temporary failure in name resolution'))"}], "interactions": []}, "elapsed_time": 330.35713220003527, "correlation_id": "a9bd35fe69154da3bfe140c028807532", "thread_id": 140412414527296, "hypothesis_output": [], "event_type": "AfterExecution"}
{"method": "DELETE", "path": "/AAYUSHGARGBU/Simple_API/1.0.0/items/{itemId}", "verbose_name": "DELETE /AAYUSHGARGBU/Simple_API/1.0.0/items/{itemId}", "relative_path": "/items/{itemId}", "recursion_level": 0, "data_generation_method": ["positive", "negative"], "correlation_id": "7e6bccc8c0c04e1e9c95e434a406f8ff", "thread_id": 140412414527296, "event_type": "BeforeExecution"}
{"method": "DELETE", "path": "/AAYUSHGARGBU/Simple_API/1.0.0/items/{itemId}", "relative_path": "/items/{itemId}", "verbose_name": "DELETE /AAYUSHGARGBU/Simple_API/1.0.0/items/{itemId}", "status": "error", "data_generation_method": ["positive"], "result": {"method": "DELETE", "path": "/AAYUSHGARGBU/Simple_API/1.0.0/items/{itemId}", "verbose_name": "DELETE /AAYUSHGARGBU/Simple_API/1.0.0/items/{itemId}", "has_failures": false, "has_errors": true, "has_logs": false, "is_errored": true, "is_flaky": false, "is_skipped": false, "skip_reason": null, "seed": 256044834742398664162804879315084466152, "data_generation_method": ["P"], "checks": [], "logs": [], "errors": [{"type": "connection_other", "title": "Network Error", "message": "Connection failed", "extras": ["Failed to establish a new connection: [Errno -3] Temporary failure in name resolution"], "exception": "requests.exceptions.ConnectionError: HTTPSConnectionPool(host='virtserver.swaggerhub.com', port=443): Max retries exceeded with url: /AAYUSHGARGBU/Simple_API/1.0.0/items/0 (Caused by NewConnectionError('<urllib3.connection.VerifiedHTTPSConnection object at 0x7fb44cfea8e0>: Failed to establish a new connection: [Errno -3] Temporary failure in name resolution'))", "exception_with_traceback": "Traceback (most recent call last):\n  File \"/usr/lib/python3/dist-packages/urllib3/connection.py\", line 156, in _new_conn\n    conn = connection.create_connection(\n  File \"/usr/lib/python3/dist-packages/urllib3/util/connection.py\", line 61, in create_connection\n    for res in socket.getaddrinfo(host, port, family, socket.SOCK_STREAM):\n  File \"/usr/lib/python3.8/socket.py\", line 918, in getaddrinfo\n    for res in _socket.getaddrinfo(host, port, family, type, proto, flags):\nsocket.gaierror: [Errno -3] Temporary failure in name resolution\n\nDuring handling of the above exception, another exception occurred:\n\nTraceback (most recent call last):\n  File \"/usr/lib/python3/dist-packages/urllib3/connectionpool.py\", line 665, in urlopen\n    httplib_response = self._make_request(\n  File \"/usr/lib/python3/dist-packages/urllib3/connectionpool.py\", line 376, in _make_request\n    self._validate_conn(conn)\n  File \"/usr/lib/python3/dist-packages/urllib3/connectionpool.py\", line 996, in _validate_conn\n    conn.connect()\n  File \"/usr/lib/python3/dist-packages/urllib3/connection.py\", line 300, in connect\n    conn = self._new_conn()\n  File \"/usr/lib/python3/dist-packages/urllib3/connection.py\", line 168, in _new_conn\n    raise NewConnectionError(\nurllib3.exceptions.NewConnectionError: <urllib3.connection.VerifiedHTTPSConnection object at 0x7fb44cfea8e0>: Failed to establish a new connection: [Errno -3] Temporary failure in name resolution\n\nDuring handling of the above exception, another exception occurred:\n\nTraceback (most recent call last):\n  File \"/usr/local/lib/python3.8/dist-packages/requests/adapters.py\", line 486, in send\n    resp = conn.urlopen(\n  File \"/usr/lib/python3/dist-packages/urllib3/connectionpool.py\", line 719, in urlopen\n    retries = retries.increment(\n  File \"/usr/lib/python3/dist-packages/urllib3/util/retry.py\", line 436, in increment\n    raise MaxRetryError(_pool, url, error or ResponseError(cause))\nurllib3.exceptions.MaxRetryError: HTTPSConnectionPool(host='virtserver.swaggerhub.com', port=443): Max retries exceeded with url: /AAYUSHGARGBU/Simple_API/1.0.0/items/0 (Caused by NewConnectionError('<urllib3.connection.VerifiedHTTPSConnection object at 0x7fb44cfea8e0>: Failed to establish a new connection: [Errno -3] Temporary failure in name resolution'))\n\nDuring handling of the above exception, another exception occurred:\n\nTraceback (most recent call last):\n  File \"/usr/local/lib/python3.8/dist-packages/schemathesis/runner/impl/core.py\", line 816, in network_test\n    response = _network_test(case, *args)\n  File \"/usr/local/lib/python3.8/dist-packages/schemathesis/runner/impl/core.py\", line 848, in _network_test\n    response = case.call(**kwargs)\n  File \"/usr/local/lib/python3.8/dist-packages/schemathesis/models.py\", line 310, in call\n    response = self.operation.schema.transport.send(\n  File \"/usr/local/lib/python3.8/dist-packages/schemathesis/transports/__init__.py\", line 143, in send\n    response = session.request(**data)  # type: ignore\n  File \"/usr/local/lib/python3.8/dist-packages/requests/sessions.py\", line 589, in request\n    resp = self.send(prep, **send_kwargs)\n  File \"/usr/local/lib/python3.8/dist-packages/requests/sessions.py\", line 703, in send\n    r = adapter.send(request, **kwargs)\n  File \"/usr/local/lib/python3.8/dist-packages/requests/adapters.py\", line 519, in send\n    raise ConnectionError(e, request=request)\nrequests.exceptions.ConnectionError: HTTPSConnectionPool(host='virtserver.swaggerhub.com', port=443): Max retries exceeded with url: /AAYUSHGARGBU/Simple_API/1.0.0/items/0 (Caused by NewConnectionError('<urllib3.connection.VerifiedHTTPSConnection object at 0x7fb44cfea8e0>: Failed to establish a new connection: [Errno -3] Temporary failure in name resolution'))"}], "interactions": []}, "elapsed_time": 132.1115717999637, "correlation_id": "7e6bccc8c0c04e1e9c95e434a406f8ff", "thread_id": 140412414527296, "hypothesis_output": [], "event_type": "AfterExecution"}
{"passed_count": 0, "skipped_count": 0, "failed_count": 0, "errored_count": 5, "has_failures": false, "has_errors": true, "has_logs": false, "is_empty": false, "generic_errors": [], "warnings": [], "total": {}, "running_time": 814.8874026000267, "thread_id": 140412414527296, "event_type": "Finished"}
