{"schema": {"openapi": "3.0.0", "servers": [{"description": "SwaggerHub API Auto Mocking", "url": "https://virtserver.swaggerhub.com/AAYUSHGARGBU/api_oauth2_application/1.0.0"}], "info": {"version": "1.0.0", "title": "Sample Application Flow OAuth2 Project", "description": "This is an example of using OAuth2 Application Flow in a specification to describe security to your API."}, "security": [{"application": ["read", "write"]}], "paths": {"/example": {"get": {"summary": "Server example operation", "description": "This is an example operation to show how security is applied to the call.", "parameters": [{"in": "query", "name": "filter", "schema": {"type": "string"}, "description": "Filter the results based on a query string."}, {"in": "header", "name": "X-Request-ID", "schema": {"type": "string", "format": "uuid"}, "required": true, "description": "Unique identifier for the request."}], "responses": {"200": {"description": "OK", "content": {"application/json": {"schema": {"$ref": "#/components/schemas/ExampleResponse"}}}}}}}, "/ping": {"get": {"summary": "Server heartbeat operation", "description": "This operation shows how to override the global security defined above, as we want to open it up for all users.", "security": [], "responses": {"200": {"description": "OK"}}}}, "/users": {"post": {"summary": "Create a new user", "description": "Create a new user with the provided information.", "requestBody": {"required": true, "content": {"application/json": {"schema": {"$ref": "#/components/schemas/User"}}}}, "responses": {"201": {"description": "User created"}, "400": {"description": "Invalid user data provided"}}}, "get": {"summary": "List users", "description": "Retrieves a list of users, optionally filtered by various parameters.", "parameters": [{"in": "query", "name": "age", "schema": {"type": "integer"}, "description": "Filter users by age"}], "responses": {"200": {"description": "A list of users", "content": {"application/json": {"schema": {"type": "array", "items": {"$ref": "#/components/schemas/User"}}}}}, "404": {"description": "No users found"}}}}}, "components": {"schemas": {"User": {"type": "object", "required": ["id", "name", "email"], "properties": {"id": {"type": "string", "format": "uuid"}, "name": {"type": "string"}, "email": {"type": "string", "format": "email"}, "age": {"type": "integer"}}}, "ExampleResponse": {"type": "object", "properties": {"message": {"type": "string"}, "timestamp": {"type": "string", "format": "date-time"}}}}, "securitySchemes": {"application": {"type": "oauth2", "flows": {"clientCredentials": {"tokenUrl": "http://example.com/oauth/token", "scopes": {"write": "allows modifying resources", "read": "allows reading resources"}}}}}}}, "operations_count": 4, "links_count": 0, "location": "file:///mnt/d/ag/github/lazarus_target_apis/data/api_oauth2_application/api_oauth2_application.json", "seed": 71343992126975390739726459910754147633, "base_url": "https://virtserver.swaggerhub.com/AAYUSHGARGBU/api_oauth2_application/1.0.0", "specification_name": "Open API 3.0.0", "start_time": 516286.2270108, "started_at": "2024-05-27T23:51:05.207943+02:00", "thread_id": 140618010593088, "event_type": "Initialized"}
{"event_type": "BeforeProbing"}
{"probes": [{"name": "NULL_BYTE_IN_HEADER", "outcome": "error", "request": {"method": "GET", "uri": "https://virtserver.swaggerhub.com/AAYUSHGARGBU/api_oauth2_application/1.0.0", "body": null, "headers": {"User-Agent": ["schemathesis/3.27.1"], "Accept-Encoding": ["gzip, deflate"], "Accept": ["*/*"], "Connection": ["keep-alive"], "X-Schemathesis-Probe-Null": ["\u0000"], "X-Schemathesis-Probe": ["NULL_BYTE_IN_HEADER"]}}, "response": null, "error": "requests.exceptions.ConnectionError: HTTPSConnectionPool(host='virtserver.swaggerhub.com', port=443): Max retries exceeded with url: /AAYUSHGARGBU/api_oauth2_application/1.0.0 (Caused by NewConnectionError('<urllib3.connection.VerifiedHTTPSConnection object at 0x7fe42bba7a30>: Failed to establish a new connection: [Errno -3] Temporary failure in name resolution'))"}], "events_type": "AfterProbing"}
{"event_type": "BeforeAnalysis"}
{"analysis": null, "event_type": "AfterAnalysis"}
{"method": "GET", "path": "/AAYUSHGARGBU/api_oauth2_application/1.0.0/example", "verbose_name": "GET /AAYUSHGARGBU/api_oauth2_application/1.0.0/example", "relative_path": "/example", "recursion_level": 0, "data_generation_method": ["positive", "negative"], "correlation_id": "8fec6037f75444de905e52f6000ecfb5", "thread_id": 140618010593088, "event_type": "BeforeExecution"}
{"method": "GET", "path": "/AAYUSHGARGBU/api_oauth2_application/1.0.0/example", "relative_path": "/example", "verbose_name": "GET /AAYUSHGARGBU/api_oauth2_application/1.0.0/example", "status": "error", "data_generation_method": ["positive"], "result": {"method": "GET", "path": "/AAYUSHGARGBU/api_oauth2_application/1.0.0/example", "verbose_name": "GET /AAYUSHGARGBU/api_oauth2_application/1.0.0/example", "has_failures": false, "has_errors": true, "has_logs": false, "is_errored": true, "is_flaky": false, "is_skipped": false, "skip_reason": null, "seed": 71343992126975390739726459910754147633, "data_generation_method": ["P"], "checks": [], "logs": [], "errors": [{"type": "connection_other", "title": "Network Error", "message": "Connection failed", "extras": ["Failed to establish a new connection: [Errno -3] Temporary failure in name resolution"], "exception": "requests.exceptions.ConnectionError: HTTPSConnectionPool(host='virtserver.swaggerhub.com', port=443): Max retries exceeded with url: /AAYUSHGARGBU/api_oauth2_application/1.0.0/example (Caused by NewConnectionError('<urllib3.connection.VerifiedHTTPSConnection object at 0x7fe42ba7e5b0>: Failed to establish a new connection: [Errno -3] Temporary failure in name resolution'))", "exception_with_traceback": "Traceback (most recent call last):\n  File \"/usr/lib/python3/dist-packages/urllib3/connection.py\", line 156, in _new_conn\n    conn = connection.create_connection(\n  File \"/usr/lib/python3/dist-packages/urllib3/util/connection.py\", line 61, in create_connection\n    for res in socket.getaddrinfo(host, port, family, socket.SOCK_STREAM):\n  File \"/usr/lib/python3.8/socket.py\", line 918, in getaddrinfo\n    for res in _socket.getaddrinfo(host, port, family, type, proto, flags):\nsocket.gaierror: [Errno -3] Temporary failure in name resolution\n\nDuring handling of the above exception, another exception occurred:\n\nTraceback (most recent call last):\n  File \"/usr/lib/python3/dist-packages/urllib3/connectionpool.py\", line 665, in urlopen\n    httplib_response = self._make_request(\n  File \"/usr/lib/python3/dist-packages/urllib3/connectionpool.py\", line 376, in _make_request\n    self._validate_conn(conn)\n  File \"/usr/lib/python3/dist-packages/urllib3/connectionpool.py\", line 996, in _validate_conn\n    conn.connect()\n  File \"/usr/lib/python3/dist-packages/urllib3/connection.py\", line 300, in connect\n    conn = self._new_conn()\n  File \"/usr/lib/python3/dist-packages/urllib3/connection.py\", line 168, in _new_conn\n    raise NewConnectionError(\nurllib3.exceptions.NewConnectionError: <urllib3.connection.VerifiedHTTPSConnection object at 0x7fe42ba7e5b0>: Failed to establish a new connection: [Errno -3] Temporary failure in name resolution\n\nDuring handling of the above exception, another exception occurred:\n\nTraceback (most recent call last):\n  File \"/usr/local/lib/python3.8/dist-packages/requests/adapters.py\", line 486, in send\n    resp = conn.urlopen(\n  File \"/usr/lib/python3/dist-packages/urllib3/connectionpool.py\", line 719, in urlopen\n    retries = retries.increment(\n  File \"/usr/lib/python3/dist-packages/urllib3/util/retry.py\", line 436, in increment\n    raise MaxRetryError(_pool, url, error or ResponseError(cause))\nurllib3.exceptions.MaxRetryError: HTTPSConnectionPool(host='virtserver.swaggerhub.com', port=443): Max retries exceeded with url: /AAYUSHGARGBU/api_oauth2_application/1.0.0/example (Caused by NewConnectionError('<urllib3.connection.VerifiedHTTPSConnection object at 0x7fe42ba7e5b0>: Failed to establish a new connection: [Errno -3] Temporary failure in name resolution'))\n\nDuring handling of the above exception, another exception occurred:\n\nTraceback (most recent call last):\n  File \"/usr/local/lib/python3.8/dist-packages/schemathesis/runner/impl/core.py\", line 816, in network_test\n    response = _network_test(case, *args)\n  File \"/usr/local/lib/python3.8/dist-packages/schemathesis/runner/impl/core.py\", line 848, in _network_test\n    response = case.call(**kwargs)\n  File \"/usr/local/lib/python3.8/dist-packages/schemathesis/models.py\", line 310, in call\n    response = self.operation.schema.transport.send(\n  File \"/usr/local/lib/python3.8/dist-packages/schemathesis/transports/__init__.py\", line 143, in send\n    response = session.request(**data)  # type: ignore\n  File \"/usr/local/lib/python3.8/dist-packages/requests/sessions.py\", line 589, in request\n    resp = self.send(prep, **send_kwargs)\n  File \"/usr/local/lib/python3.8/dist-packages/requests/sessions.py\", line 703, in send\n    r = adapter.send(request, **kwargs)\n  File \"/usr/local/lib/python3.8/dist-packages/requests/adapters.py\", line 519, in send\n    raise ConnectionError(e, request=request)\nrequests.exceptions.ConnectionError: HTTPSConnectionPool(host='virtserver.swaggerhub.com', port=443): Max retries exceeded with url: /AAYUSHGARGBU/api_oauth2_application/1.0.0/example (Caused by NewConnectionError('<urllib3.connection.VerifiedHTTPSConnection object at 0x7fe42ba7e5b0>: Failed to establish a new connection: [Errno -3] Temporary failure in name resolution'))"}], "interactions": []}, "elapsed_time": 264.3906503999606, "correlation_id": "8fec6037f75444de905e52f6000ecfb5", "thread_id": 140618010593088, "hypothesis_output": [], "event_type": "AfterExecution"}
{"method": "GET", "path": "/AAYUSHGARGBU/api_oauth2_application/1.0.0/ping", "verbose_name": "GET /AAYUSHGARGBU/api_oauth2_application/1.0.0/ping", "relative_path": "/ping", "recursion_level": 0, "data_generation_method": ["positive", "negative"], "correlation_id": "8b090087bbd14a2898c0bc4b933b4cd7", "thread_id": 140618010593088, "event_type": "BeforeExecution"}
{"method": "GET", "path": "/AAYUSHGARGBU/api_oauth2_application/1.0.0/ping", "relative_path": "/ping", "verbose_name": "GET /AAYUSHGARGBU/api_oauth2_application/1.0.0/ping", "status": "error", "data_generation_method": ["positive"], "result": {"method": "GET", "path": "/AAYUSHGARGBU/api_oauth2_application/1.0.0/ping", "verbose_name": "GET /AAYUSHGARGBU/api_oauth2_application/1.0.0/ping", "has_failures": false, "has_errors": true, "has_logs": false, "is_errored": true, "is_flaky": false, "is_skipped": false, "skip_reason": null, "seed": 71343992126975390739726459910754147633, "data_generation_method": ["P"], "checks": [], "logs": [], "errors": [{"type": "connection_other", "title": "Network Error", "message": "Connection failed", "extras": ["Failed to establish a new connection: [Errno -3] Temporary failure in name resolution"], "exception": "requests.exceptions.ConnectionError: HTTPSConnectionPool(host='virtserver.swaggerhub.com', port=443): Max retries exceeded with url: /AAYUSHGARGBU/api_oauth2_application/1.0.0/ping (Caused by NewConnectionError('<urllib3.connection.VerifiedHTTPSConnection object at 0x7fe42b854c10>: Failed to establish a new connection: [Errno -3] Temporary failure in name resolution'))", "exception_with_traceback": "Traceback (most recent call last):\n  File \"/usr/lib/python3/dist-packages/urllib3/connection.py\", line 156, in _new_conn\n    conn = connection.create_connection(\n  File \"/usr/lib/python3/dist-packages/urllib3/util/connection.py\", line 61, in create_connection\n    for res in socket.getaddrinfo(host, port, family, socket.SOCK_STREAM):\n  File \"/usr/lib/python3.8/socket.py\", line 918, in getaddrinfo\n    for res in _socket.getaddrinfo(host, port, family, type, proto, flags):\nsocket.gaierror: [Errno -3] Temporary failure in name resolution\n\nDuring handling of the above exception, another exception occurred:\n\nTraceback (most recent call last):\n  File \"/usr/lib/python3/dist-packages/urllib3/connectionpool.py\", line 665, in urlopen\n    httplib_response = self._make_request(\n  File \"/usr/lib/python3/dist-packages/urllib3/connectionpool.py\", line 376, in _make_request\n    self._validate_conn(conn)\n  File \"/usr/lib/python3/dist-packages/urllib3/connectionpool.py\", line 996, in _validate_conn\n    conn.connect()\n  File \"/usr/lib/python3/dist-packages/urllib3/connection.py\", line 300, in connect\n    conn = self._new_conn()\n  File \"/usr/lib/python3/dist-packages/urllib3/connection.py\", line 168, in _new_conn\n    raise NewConnectionError(\nurllib3.exceptions.NewConnectionError: <urllib3.connection.VerifiedHTTPSConnection object at 0x7fe42b854c10>: Failed to establish a new connection: [Errno -3] Temporary failure in name resolution\n\nDuring handling of the above exception, another exception occurred:\n\nTraceback (most recent call last):\n  File \"/usr/local/lib/python3.8/dist-packages/requests/adapters.py\", line 486, in send\n    resp = conn.urlopen(\n  File \"/usr/lib/python3/dist-packages/urllib3/connectionpool.py\", line 719, in urlopen\n    retries = retries.increment(\n  File \"/usr/lib/python3/dist-packages/urllib3/util/retry.py\", line 436, in increment\n    raise MaxRetryError(_pool, url, error or ResponseError(cause))\nurllib3.exceptions.MaxRetryError: HTTPSConnectionPool(host='virtserver.swaggerhub.com', port=443): Max retries exceeded with url: /AAYUSHGARGBU/api_oauth2_application/1.0.0/ping (Caused by NewConnectionError('<urllib3.connection.VerifiedHTTPSConnection object at 0x7fe42b854c10>: Failed to establish a new connection: [Errno -3] Temporary failure in name resolution'))\n\nDuring handling of the above exception, another exception occurred:\n\nTraceback (most recent call last):\n  File \"/usr/local/lib/python3.8/dist-packages/schemathesis/runner/impl/core.py\", line 816, in network_test\n    response = _network_test(case, *args)\n  File \"/usr/local/lib/python3.8/dist-packages/schemathesis/runner/impl/core.py\", line 848, in _network_test\n    response = case.call(**kwargs)\n  File \"/usr/local/lib/python3.8/dist-packages/schemathesis/models.py\", line 310, in call\n    response = self.operation.schema.transport.send(\n  File \"/usr/local/lib/python3.8/dist-packages/schemathesis/transports/__init__.py\", line 143, in send\n    response = session.request(**data)  # type: ignore\n  File \"/usr/local/lib/python3.8/dist-packages/requests/sessions.py\", line 589, in request\n    resp = self.send(prep, **send_kwargs)\n  File \"/usr/local/lib/python3.8/dist-packages/requests/sessions.py\", line 703, in send\n    r = adapter.send(request, **kwargs)\n  File \"/usr/local/lib/python3.8/dist-packages/requests/adapters.py\", line 519, in send\n    raise ConnectionError(e, request=request)\nrequests.exceptions.ConnectionError: HTTPSConnectionPool(host='virtserver.swaggerhub.com', port=443): Max retries exceeded with url: /AAYUSHGARGBU/api_oauth2_application/1.0.0/ping (Caused by NewConnectionError('<urllib3.connection.VerifiedHTTPSConnection object at 0x7fe42b854c10>: Failed to establish a new connection: [Errno -3] Temporary failure in name resolution'))"}], "interactions": []}, "elapsed_time": 66.05383409996284, "correlation_id": "8b090087bbd14a2898c0bc4b933b4cd7", "thread_id": 140618010593088, "hypothesis_output": [], "event_type": "AfterExecution"}
{"method": "POST", "path": "/AAYUSHGARGBU/api_oauth2_application/1.0.0/users", "verbose_name": "POST /AAYUSHGARGBU/api_oauth2_application/1.0.0/users", "relative_path": "/users", "recursion_level": 0, "data_generation_method": ["positive", "negative"], "correlation_id": "6222218308ad4e8cbb3f5a3088e8167e", "thread_id": 140618010593088, "event_type": "BeforeExecution"}
{"method": "POST", "path": "/AAYUSHGARGBU/api_oauth2_application/1.0.0/users", "relative_path": "/users", "verbose_name": "POST /AAYUSHGARGBU/api_oauth2_application/1.0.0/users", "status": "error", "data_generation_method": ["positive"], "result": {"method": "POST", "path": "/AAYUSHGARGBU/api_oauth2_application/1.0.0/users", "verbose_name": "POST /AAYUSHGARGBU/api_oauth2_application/1.0.0/users", "has_failures": false, "has_errors": true, "has_logs": false, "is_errored": true, "is_flaky": false, "is_skipped": false, "skip_reason": null, "seed": 71343992126975390739726459910754147633, "data_generation_method": ["P"], "checks": [], "logs": [], "errors": [{"type": "connection_other", "title": "Network Error", "message": "Connection failed", "extras": ["Failed to establish a new connection: [Errno -3] Temporary failure in name resolution"], "exception": "requests.exceptions.ConnectionError: HTTPSConnectionPool(host='virtserver.swaggerhub.com', port=443): Max retries exceeded with url: /AAYUSHGARGBU/api_oauth2_application/1.0.0/users (Caused by NewConnectionError('<urllib3.connection.VerifiedHTTPSConnection object at 0x7fe42b809400>: Failed to establish a new connection: [Errno -3] Temporary failure in name resolution'))", "exception_with_traceback": "Traceback (most recent call last):\n  File \"/usr/lib/python3/dist-packages/urllib3/connection.py\", line 156, in _new_conn\n    conn = connection.create_connection(\n  File \"/usr/lib/python3/dist-packages/urllib3/util/connection.py\", line 61, in create_connection\n    for res in socket.getaddrinfo(host, port, family, socket.SOCK_STREAM):\n  File \"/usr/lib/python3.8/socket.py\", line 918, in getaddrinfo\n    for res in _socket.getaddrinfo(host, port, family, type, proto, flags):\nsocket.gaierror: [Errno -3] Temporary failure in name resolution\n\nDuring handling of the above exception, another exception occurred:\n\nTraceback (most recent call last):\n  File \"/usr/lib/python3/dist-packages/urllib3/connectionpool.py\", line 665, in urlopen\n    httplib_response = self._make_request(\n  File \"/usr/lib/python3/dist-packages/urllib3/connectionpool.py\", line 376, in _make_request\n    self._validate_conn(conn)\n  File \"/usr/lib/python3/dist-packages/urllib3/connectionpool.py\", line 996, in _validate_conn\n    conn.connect()\n  File \"/usr/lib/python3/dist-packages/urllib3/connection.py\", line 300, in connect\n    conn = self._new_conn()\n  File \"/usr/lib/python3/dist-packages/urllib3/connection.py\", line 168, in _new_conn\n    raise NewConnectionError(\nurllib3.exceptions.NewConnectionError: <urllib3.connection.VerifiedHTTPSConnection object at 0x7fe42b809400>: Failed to establish a new connection: [Errno -3] Temporary failure in name resolution\n\nDuring handling of the above exception, another exception occurred:\n\nTraceback (most recent call last):\n  File \"/usr/local/lib/python3.8/dist-packages/requests/adapters.py\", line 486, in send\n    resp = conn.urlopen(\n  File \"/usr/lib/python3/dist-packages/urllib3/connectionpool.py\", line 719, in urlopen\n    retries = retries.increment(\n  File \"/usr/lib/python3/dist-packages/urllib3/util/retry.py\", line 436, in increment\n    raise MaxRetryError(_pool, url, error or ResponseError(cause))\nurllib3.exceptions.MaxRetryError: HTTPSConnectionPool(host='virtserver.swaggerhub.com', port=443): Max retries exceeded with url: /AAYUSHGARGBU/api_oauth2_application/1.0.0/users (Caused by NewConnectionError('<urllib3.connection.VerifiedHTTPSConnection object at 0x7fe42b809400>: Failed to establish a new connection: [Errno -3] Temporary failure in name resolution'))\n\nDuring handling of the above exception, another exception occurred:\n\nTraceback (most recent call last):\n  File \"/usr/local/lib/python3.8/dist-packages/schemathesis/runner/impl/core.py\", line 816, in network_test\n    response = _network_test(case, *args)\n  File \"/usr/local/lib/python3.8/dist-packages/schemathesis/runner/impl/core.py\", line 848, in _network_test\n    response = case.call(**kwargs)\n  File \"/usr/local/lib/python3.8/dist-packages/schemathesis/models.py\", line 310, in call\n    response = self.operation.schema.transport.send(\n  File \"/usr/local/lib/python3.8/dist-packages/schemathesis/transports/__init__.py\", line 143, in send\n    response = session.request(**data)  # type: ignore\n  File \"/usr/local/lib/python3.8/dist-packages/requests/sessions.py\", line 589, in request\n    resp = self.send(prep, **send_kwargs)\n  File \"/usr/local/lib/python3.8/dist-packages/requests/sessions.py\", line 703, in send\n    r = adapter.send(request, **kwargs)\n  File \"/usr/local/lib/python3.8/dist-packages/requests/adapters.py\", line 519, in send\n    raise ConnectionError(e, request=request)\nrequests.exceptions.ConnectionError: HTTPSConnectionPool(host='virtserver.swaggerhub.com', port=443): Max retries exceeded with url: /AAYUSHGARGBU/api_oauth2_application/1.0.0/users (Caused by NewConnectionError('<urllib3.connection.VerifiedHTTPSConnection object at 0x7fe42b809400>: Failed to establish a new connection: [Errno -3] Temporary failure in name resolution'))"}], "interactions": []}, "elapsed_time": 242.41237239999464, "correlation_id": "6222218308ad4e8cbb3f5a3088e8167e", "thread_id": 140618010593088, "hypothesis_output": [], "event_type": "AfterExecution"}
{"method": "GET", "path": "/AAYUSHGARGBU/api_oauth2_application/1.0.0/users", "verbose_name": "GET /AAYUSHGARGBU/api_oauth2_application/1.0.0/users", "relative_path": "/users", "recursion_level": 0, "data_generation_method": ["positive", "negative"], "correlation_id": "3b02e2cefd6f499d9fc1cf34d7ebfcda", "thread_id": 140618010593088, "event_type": "BeforeExecution"}
{"method": "GET", "path": "/AAYUSHGARGBU/api_oauth2_application/1.0.0/users", "relative_path": "/users", "verbose_name": "GET /AAYUSHGARGBU/api_oauth2_application/1.0.0/users", "status": "error", "data_generation_method": ["positive"], "result": {"method": "GET", "path": "/AAYUSHGARGBU/api_oauth2_application/1.0.0/users", "verbose_name": "GET /AAYUSHGARGBU/api_oauth2_application/1.0.0/users", "has_failures": false, "has_errors": true, "has_logs": false, "is_errored": true, "is_flaky": false, "is_skipped": false, "skip_reason": null, "seed": 71343992126975390739726459910754147633, "data_generation_method": ["P"], "checks": [], "logs": [], "errors": [{"type": "connection_other", "title": "Network Error", "message": "Connection failed", "extras": ["Failed to establish a new connection: [Errno -3] Temporary failure in name resolution"], "exception": "requests.exceptions.ConnectionError: HTTPSConnectionPool(host='virtserver.swaggerhub.com', port=443): Max retries exceeded with url: /AAYUSHGARGBU/api_oauth2_application/1.0.0/users (Caused by NewConnectionError('<urllib3.connection.VerifiedHTTPSConnection object at 0x7fe42b64b940>: Failed to establish a new connection: [Errno -3] Temporary failure in name resolution'))", "exception_with_traceback": "Traceback (most recent call last):\n  File \"/usr/lib/python3/dist-packages/urllib3/connection.py\", line 156, in _new_conn\n    conn = connection.create_connection(\n  File \"/usr/lib/python3/dist-packages/urllib3/util/connection.py\", line 61, in create_connection\n    for res in socket.getaddrinfo(host, port, family, socket.SOCK_STREAM):\n  File \"/usr/lib/python3.8/socket.py\", line 918, in getaddrinfo\n    for res in _socket.getaddrinfo(host, port, family, type, proto, flags):\nsocket.gaierror: [Errno -3] Temporary failure in name resolution\n\nDuring handling of the above exception, another exception occurred:\n\nTraceback (most recent call last):\n  File \"/usr/lib/python3/dist-packages/urllib3/connectionpool.py\", line 665, in urlopen\n    httplib_response = self._make_request(\n  File \"/usr/lib/python3/dist-packages/urllib3/connectionpool.py\", line 376, in _make_request\n    self._validate_conn(conn)\n  File \"/usr/lib/python3/dist-packages/urllib3/connectionpool.py\", line 996, in _validate_conn\n    conn.connect()\n  File \"/usr/lib/python3/dist-packages/urllib3/connection.py\", line 300, in connect\n    conn = self._new_conn()\n  File \"/usr/lib/python3/dist-packages/urllib3/connection.py\", line 168, in _new_conn\n    raise NewConnectionError(\nurllib3.exceptions.NewConnectionError: <urllib3.connection.VerifiedHTTPSConnection object at 0x7fe42b64b940>: Failed to establish a new connection: [Errno -3] Temporary failure in name resolution\n\nDuring handling of the above exception, another exception occurred:\n\nTraceback (most recent call last):\n  File \"/usr/local/lib/python3.8/dist-packages/requests/adapters.py\", line 486, in send\n    resp = conn.urlopen(\n  File \"/usr/lib/python3/dist-packages/urllib3/connectionpool.py\", line 719, in urlopen\n    retries = retries.increment(\n  File \"/usr/lib/python3/dist-packages/urllib3/util/retry.py\", line 436, in increment\n    raise MaxRetryError(_pool, url, error or ResponseError(cause))\nurllib3.exceptions.MaxRetryError: HTTPSConnectionPool(host='virtserver.swaggerhub.com', port=443): Max retries exceeded with url: /AAYUSHGARGBU/api_oauth2_application/1.0.0/users (Caused by NewConnectionError('<urllib3.connection.VerifiedHTTPSConnection object at 0x7fe42b64b940>: Failed to establish a new connection: [Errno -3] Temporary failure in name resolution'))\n\nDuring handling of the above exception, another exception occurred:\n\nTraceback (most recent call last):\n  File \"/usr/local/lib/python3.8/dist-packages/schemathesis/runner/impl/core.py\", line 816, in network_test\n    response = _network_test(case, *args)\n  File \"/usr/local/lib/python3.8/dist-packages/schemathesis/runner/impl/core.py\", line 848, in _network_test\n    response = case.call(**kwargs)\n  File \"/usr/local/lib/python3.8/dist-packages/schemathesis/models.py\", line 310, in call\n    response = self.operation.schema.transport.send(\n  File \"/usr/local/lib/python3.8/dist-packages/schemathesis/transports/__init__.py\", line 143, in send\n    response = session.request(**data)  # type: ignore\n  File \"/usr/local/lib/python3.8/dist-packages/requests/sessions.py\", line 589, in request\n    resp = self.send(prep, **send_kwargs)\n  File \"/usr/local/lib/python3.8/dist-packages/requests/sessions.py\", line 703, in send\n    r = adapter.send(request, **kwargs)\n  File \"/usr/local/lib/python3.8/dist-packages/requests/adapters.py\", line 519, in send\n    raise ConnectionError(e, request=request)\nrequests.exceptions.ConnectionError: HTTPSConnectionPool(host='virtserver.swaggerhub.com', port=443): Max retries exceeded with url: /AAYUSHGARGBU/api_oauth2_application/1.0.0/users (Caused by NewConnectionError('<urllib3.connection.VerifiedHTTPSConnection object at 0x7fe42b64b940>: Failed to establish a new connection: [Errno -3] Temporary failure in name resolution'))"}], "interactions": []}, "elapsed_time": 88.06982109998353, "correlation_id": "3b02e2cefd6f499d9fc1cf34d7ebfcda", "thread_id": 140618010593088, "hypothesis_output": [], "event_type": "AfterExecution"}
{"passed_count": 0, "skipped_count": 0, "failed_count": 0, "errored_count": 4, "has_failures": false, "has_errors": true, "has_logs": false, "is_empty": false, "generic_errors": [], "warnings": [], "total": {}, "running_time": 682.9503369000158, "thread_id": 140618010593088, "event_type": "Finished"}
