{"schema": {"openapi": "3.0.0", "servers": [{"description": "SwaggerHub API Auto Mocking", "url": "https://virtserver.swaggerhub.com/AAYUSHGARGBU/api_iot/1.0.0"}], "info": {"version": "1.0.0", "title": "home-iot-api", "description": "The API for the EatBacon IOT project"}, "paths": {"/devices": {"get": {"tags": ["Device"], "description": "returns all registered devices", "operationId": "getDevices", "parameters": [{"in": "query", "name": "skip", "description": "number of records to skip", "schema": {"type": "integer", "format": "int32"}}, {"in": "query", "name": "limit", "description": "max number of records to return", "schema": {"type": "integer", "format": "int32"}}], "responses": {"200": {"description": "All the devices", "content": {"application/json": {"schema": {"type": "array", "items": {"type": "string", "format": "uri", "example": "http://10.0.0.225:8080"}}}}}}}, "post": {"tags": ["Device"], "operationId": "register", "responses": {"200": {"description": "successfully registered device"}}, "requestBody": {"content": {"application/json": {"schema": {"$ref": "#/components/schemas/DeviceRegistrationInfo"}}}}}}, "/lighting/dimmers/{deviceId}/{value}": {"post": {"tags": ["Z-Wave"], "operationId": "setDimmer", "parameters": [{"name": "deviceId", "in": "path", "required": true, "schema": {"type": "string"}}, {"name": "value", "in": "path", "required": true, "schema": {"type": "integer", "format": "int32", "minimum": 0, "maximum": 100}}], "responses": {"200": {"description": "response", "content": {"application/json": {"schema": {"$ref": "#/components/schemas/ApiResponse"}}}}}, "x-swagger-router-controller": "ZWave"}}, "/lighting/dimmers/{deviceId}/{value}/timer/{timeunit}": {"post": {"tags": ["Z-Wave"], "description": "sets a dimmer to a specific value on a timer", "operationId": "setDimmerTimer", "parameters": [{"name": "deviceId", "in": "path", "required": true, "schema": {"type": "string"}}, {"name": "value", "in": "path", "required": true, "schema": {"type": "integer", "format": "int32"}}, {"name": "timeunit", "in": "path", "required": true, "schema": {"type": "integer", "format": "int32"}}, {"name": "units", "in": "query", "required": false, "schema": {"type": "string", "enum": ["seconds", "minutes", "milliseconds"], "default": "milliseconds"}}], "responses": {"200": {"description": "response", "content": {"application/json": {"schema": {"$ref": "#/components/schemas/ApiResponse"}}}}}, "x-swagger-router-controller": "ZWave"}}, "/lighting/switches/{deviceId}": {"get": {"tags": ["Z-Wave"], "operationId": "getSwitchState", "parameters": [{"name": "deviceId", "in": "path", "required": true, "schema": {"type": "string"}}], "responses": {"200": {"description": "response", "content": {"application/json": {"schema": {"$ref": "#/components/schemas/DeviceState"}}}}}, "x-swagger-router-controller": "ZWave"}}, "/lighting/switches/{deviceId}/{value}": {"post": {"tags": ["Z-Wave"], "operationId": "setSwitch", "parameters": [{"name": "deviceId", "in": "path", "required": true, "schema": {"type": "string"}}, {"name": "value", "in": "path", "required": true, "schema": {"type": "string", "enum": [true, false]}}], "responses": {"200": {"description": "response", "content": {"application/json": {"schema": {"$ref": "#/components/schemas/ApiResponse"}}}}}, "x-swagger-router-controller": "ZWave"}}, "/lighting/switches/{deviceId}/{value}/timer/{minutes}": {"post": {"tags": ["Z-Wave"], "description": "sets a switch to a specific value on a timer", "operationId": "setSwitchTimer", "parameters": [{"name": "deviceId", "in": "path", "required": true, "schema": {"type": "string"}}, {"name": "value", "in": "path", "required": true, "schema": {"type": "string", "enum": [true, false]}}, {"name": "minutes", "in": "path", "required": true, "schema": {"type": "integer", "format": "int32"}}], "responses": {"200": {"description": "response", "content": {"application/json": {"schema": {"$ref": "#/components/schemas/ApiResponse"}}}}}, "x-swagger-router-controller": "ZWave"}}, "/lightingSummary": {"get": {"tags": ["Z-Wave"], "operationId": "getLightingSummary", "responses": {"200": {"description": "ok", "content": {"application/json": {"schema": {"$ref": "#/components/schemas/LightingSummary"}}}}}, "x-swagger-router-controller": "ZWave"}}, "/temperature": {"get": {"tags": ["Environment"], "operationId": "temperatureSummary", "responses": {"200": {"description": "ok", "content": {"application/json": {"schema": {"$ref": "#/components/schemas/TemperatureSummary"}}}}}, "x-swagger-router-controller": "Environment"}}, "/temperature/forecast/{days}": {"get": {"tags": ["Environment"], "operationId": "getForecast", "parameters": [{"name": "days", "in": "path", "required": true, "schema": {"type": "integer", "format": "int32"}}], "responses": {"200": {"description": "the forecast", "content": {"application/json": {"schema": {"$ref": "#/components/schemas/ForecastResponse"}}}}}, "x-swagger-router-controller": "Environment"}}, "/temperature/{zoneId}": {"get": {"tags": ["Environment"], "operationId": "getZoneTemperature", "parameters": [{"name": "zoneId", "in": "path", "required": true, "schema": {"type": "string"}}], "responses": {"200": {"description": "Zone temperature", "content": {"application/json": {"schema": {"$ref": "#/components/schemas/TemperatueZoneStatus"}}}}}, "x-swagger-router-controller": "Environment"}}, "/temperature/{zoneId}/heater": {"get": {"tags": ["Environment"], "description": "gets the state of the heater", "operationId": "getHeaterState", "parameters": [{"name": "zoneId", "in": "path", "required": true, "schema": {"type": "string"}}], "responses": {"200": {"description": "heater state", "content": {"application/json": {"schema": {"$ref": "#/components/schemas/HeaterState"}}}}}, "x-swagger-router-controller": "Environment"}}, "/temperature/{zoneId}/heater/{state}": {"post": {"tags": ["Environment"], "description": "turns the heater on or off", "operationId": "setHeaterState", "parameters": [{"name": "zoneId", "in": "path", "required": true, "schema": {"type": "string"}}, {"name": "state", "in": "path", "required": true, "schema": {"type": "string", "enum": [false, true]}}], "responses": {"200": {"description": "Status of the operation", "content": {"application/json": {"schema": {"$ref": "#/components/schemas/ApiResponse"}}}}}, "x-swagger-router-controller": "Environment"}}, "/zones": {"get": {"tags": ["Zones"], "operationId": "getZones", "responses": {"200": {"description": "ok", "content": {"application/json": {"schema": {"type": "array", "items": {"type": "string"}}}}}}, "x-swagger-router-controller": "Zones"}}, "/zones/{zoneId}/quiet": {"get": {"tags": ["Zones"], "operationId": "quietZone", "parameters": [{"name": "zoneId", "in": "path", "required": true, "schema": {"type": "string", "enum": ["basement", "first-floor", "second-floor"]}}], "responses": {"200": {"description": "ok"}}, "x-swagger-router-controller": "Zones"}}}, "components": {"schemas": {"LightingSummary": {"type": "object", "properties": {"zones": {"type": "array", "items": {"$ref": "#/components/schemas/LightingZone"}}, "zoneStatus": {"type": "array", "items": {"$ref": "#/components/schemas/LightingZoneStatus"}}}, "description": "ok"}, "LightingZone": {"type": "object", "properties": {"id": {"type": "string"}, "name": {"type": "string"}, "deviceId": {"type": "integer", "format": "int32"}, "deviceType": {"type": "string", "enum": ["dimmer", "switch"]}, "zone": {"type": "string"}}}, "LightingZoneStatus": {"type": "object", "properties": {"id": {"type": "string"}, "name": {"type": "string"}, "lastUpdate": {"type": "string", "format": "date-time"}, "level": {"type": "integer", "format": "int32"}}, "description": "the status of the lighting zone."}, "TemperatureSummary": {"type": "object", "properties": {"zones": {"type": "array", "items": {"$ref": "#/components/schemas/TemperatureZone"}}, "zoneStatus": {"type": "array", "items": {"$ref": "#/components/schemas/TemperatueZoneStatus"}}}, "description": "ok"}, "TemperatureZone": {"type": "object", "required": ["id", "name"], "properties": {"id": {"type": "integer", "format": "int32", "description": "the unique identifier for the zone"}, "name": {"type": "string"}, "inputPosition": {"type": "integer", "format": "int32"}, "outputPosition": {"type": "integer", "format": "int32"}, "zone": {"type": "string"}}, "description": "a single temperature zone"}, "TemperatueZoneStatus": {"type": "object", "required": ["id", "timestamp", "value"], "properties": {"id": {"type": "string", "description": "the unique identifier for the zone"}, "name": {"type": "string", "description": "the name of the zone"}, "value": {"type": "number", "format": "double", "description": "the temperature in the zone"}, "units": {"type": "string", "description": "the temperature units", "enum": ["celsius", "fahrenheit"], "default": "fahrenheit"}, "timestamp": {"type": "string", "format": "date-time", "description": "the timestamp when the temperature was measured"}}, "description": "status of a single zone"}, "ApiResponse": {"type": "object", "properties": {"code": {"type": "integer", "format": "int32"}, "message": {"type": "string", "example": "everything is ok"}}}, "HeaterState": {"type": "object", "properties": {"id": {"type": "string"}, "state": {"type": "string"}}}, "DeviceState": {"type": "object", "properties": {"id": {"type": "string"}, "name": {"type": "string"}, "lastUpdate": {"type": "string", "format": "date-time"}, "level": {"type": "integer", "format": "int32"}}}, "ForecastResponse": {"type": "object", "properties": {"city": {"$ref": "#/components/schemas/City"}, "values": {"type": "array", "items": {"$ref": "#/components/schemas/Forecast"}}}}, "Forecast": {"type": "object", "properties": {"date": {"type": "string", "format": "date-time"}, "pressure": {"type": "number", "format": "double"}, "humidity": {"type": "integer", "format": "int32"}, "windSpeed": {"type": "number", "format": "double"}, "clouds": {"type": "integer", "format": "int32"}, "temperature": {"$ref": "#/components/schemas/ForecastTemperature"}, "weather": {"$ref": "#/components/schemas/WeatherForecast"}}}, "City": {"type": "object", "properties": {"id": {"type": "integer", "format": "int64"}, "name": {"type": "string"}, "lat": {"type": "number", "format": "double"}, "lon": {"type": "number", "format": "double"}, "country": {"type": "string"}}}, "ForecastTemperature": {"type": "object", "properties": {"low": {"type": "number", "format": "double"}, "high": {"type": "number", "format": "double"}, "morning": {"type": "number", "format": "double"}, "day": {"type": "number", "format": "double"}, "evening": {"type": "number", "format": "double"}, "night": {"type": "number", "format": "double"}}}, "WeatherForecast": {"type": "object", "properties": {"summary": {"type": "string"}, "description": {"type": "string"}, "icon": {"type": "string"}}}, "DeviceRegistrationInfo": {"type": "object", "properties": {"uri": {"type": "string", "format": "uri", "example": "http://10.0.0.220:8080"}, "id": {"type": "string", "format": "uuid", "example": "0729a580-2240-11e6-9eb5-0002a5d5c51b"}}}}}}, "operations_count": 15, "links_count": 0, "location": "file:///mnt/d/ag/github/lazarus_target_apis/data/api_iot/api_iot.json", "seed": 228635117958159357331249932965970836514, "base_url": "https://virtserver.swaggerhub.com/AAYUSHGARGBU/api_iot/1.0.0", "specification_name": "Open API 3.0.0", "start_time": 539491.9223584, "started_at": "2024-05-28T06:17:51.002539+02:00", "thread_id": 140521139144512, "event_type": "Initialized"}
{"event_type": "BeforeProbing"}
{"probes": [{"name": "NULL_BYTE_IN_HEADER", "outcome": "error", "request": {"method": "GET", "uri": "https://virtserver.swaggerhub.com/AAYUSHGARGBU/api_iot/1.0.0", "body": null, "headers": {"User-Agent": ["schemathesis/3.27.1"], "Accept-Encoding": ["gzip, deflate"], "Accept": ["*/*"], "Connection": ["keep-alive"], "X-Schemathesis-Probe-Null": ["\u0000"], "X-Schemathesis-Probe": ["NULL_BYTE_IN_HEADER"]}}, "response": null, "error": "requests.exceptions.ConnectionError: HTTPSConnectionPool(host='virtserver.swaggerhub.com', port=443): Max retries exceeded with url: /AAYUSHGARGBU/api_iot/1.0.0 (Caused by NewConnectionError('<urllib3.connection.VerifiedHTTPSConnection object at 0x7fcd9db47a00>: Failed to establish a new connection: [Errno -3] Temporary failure in name resolution'))"}], "events_type": "AfterProbing"}
{"event_type": "BeforeAnalysis"}
{"analysis": null, "event_type": "AfterAnalysis"}
{"method": "GET", "path": "/AAYUSHGARGBU/api_iot/1.0.0/devices", "verbose_name": "GET /AAYUSHGARGBU/api_iot/1.0.0/devices", "relative_path": "/devices", "recursion_level": 0, "data_generation_method": ["positive", "negative"], "correlation_id": "6b94f54bbd724a9485b0ed65bd3df91f", "thread_id": 140521139144512, "event_type": "BeforeExecution"}
{"method": "GET", "path": "/AAYUSHGARGBU/api_iot/1.0.0/devices", "relative_path": "/devices", "verbose_name": "GET /AAYUSHGARGBU/api_iot/1.0.0/devices", "status": "error", "data_generation_method": ["positive"], "result": {"method": "GET", "path": "/AAYUSHGARGBU/api_iot/1.0.0/devices", "verbose_name": "GET /AAYUSHGARGBU/api_iot/1.0.0/devices", "has_failures": false, "has_errors": true, "has_logs": false, "is_errored": true, "is_flaky": false, "is_skipped": false, "skip_reason": null, "seed": 228635117958159357331249932965970836514, "data_generation_method": ["P"], "checks": [], "logs": [], "errors": [{"type": "connection_other", "title": "Network Error", "message": "Connection failed", "extras": ["Failed to establish a new connection: [Errno -3] Temporary failure in name resolution"], "exception": "requests.exceptions.ConnectionError: HTTPSConnectionPool(host='virtserver.swaggerhub.com', port=443): Max retries exceeded with url: /AAYUSHGARGBU/api_iot/1.0.0/devices (Caused by NewConnectionError('<urllib3.connection.VerifiedHTTPSConnection object at 0x7fcd9da762b0>: Failed to establish a new connection: [Errno -3] Temporary failure in name resolution'))", "exception_with_traceback": "Traceback (most recent call last):\n  File \"/usr/lib/python3/dist-packages/urllib3/connection.py\", line 156, in _new_conn\n    conn = connection.create_connection(\n  File \"/usr/lib/python3/dist-packages/urllib3/util/connection.py\", line 61, in create_connection\n    for res in socket.getaddrinfo(host, port, family, socket.SOCK_STREAM):\n  File \"/usr/lib/python3.8/socket.py\", line 918, in getaddrinfo\n    for res in _socket.getaddrinfo(host, port, family, type, proto, flags):\nsocket.gaierror: [Errno -3] Temporary failure in name resolution\n\nDuring handling of the above exception, another exception occurred:\n\nTraceback (most recent call last):\n  File \"/usr/lib/python3/dist-packages/urllib3/connectionpool.py\", line 665, in urlopen\n    httplib_response = self._make_request(\n  File \"/usr/lib/python3/dist-packages/urllib3/connectionpool.py\", line 376, in _make_request\n    self._validate_conn(conn)\n  File \"/usr/lib/python3/dist-packages/urllib3/connectionpool.py\", line 996, in _validate_conn\n    conn.connect()\n  File \"/usr/lib/python3/dist-packages/urllib3/connection.py\", line 300, in connect\n    conn = self._new_conn()\n  File \"/usr/lib/python3/dist-packages/urllib3/connection.py\", line 168, in _new_conn\n    raise NewConnectionError(\nurllib3.exceptions.NewConnectionError: <urllib3.connection.VerifiedHTTPSConnection object at 0x7fcd9da762b0>: Failed to establish a new connection: [Errno -3] Temporary failure in name resolution\n\nDuring handling of the above exception, another exception occurred:\n\nTraceback (most recent call last):\n  File \"/usr/local/lib/python3.8/dist-packages/requests/adapters.py\", line 486, in send\n    resp = conn.urlopen(\n  File \"/usr/lib/python3/dist-packages/urllib3/connectionpool.py\", line 719, in urlopen\n    retries = retries.increment(\n  File \"/usr/lib/python3/dist-packages/urllib3/util/retry.py\", line 436, in increment\n    raise MaxRetryError(_pool, url, error or ResponseError(cause))\nurllib3.exceptions.MaxRetryError: HTTPSConnectionPool(host='virtserver.swaggerhub.com', port=443): Max retries exceeded with url: /AAYUSHGARGBU/api_iot/1.0.0/devices (Caused by NewConnectionError('<urllib3.connection.VerifiedHTTPSConnection object at 0x7fcd9da762b0>: Failed to establish a new connection: [Errno -3] Temporary failure in name resolution'))\n\nDuring handling of the above exception, another exception occurred:\n\nTraceback (most recent call last):\n  File \"/usr/local/lib/python3.8/dist-packages/schemathesis/runner/impl/core.py\", line 816, in network_test\n    response = _network_test(case, *args)\n  File \"/usr/local/lib/python3.8/dist-packages/schemathesis/runner/impl/core.py\", line 848, in _network_test\n    response = case.call(**kwargs)\n  File \"/usr/local/lib/python3.8/dist-packages/schemathesis/models.py\", line 310, in call\n    response = self.operation.schema.transport.send(\n  File \"/usr/local/lib/python3.8/dist-packages/schemathesis/transports/__init__.py\", line 143, in send\n    response = session.request(**data)  # type: ignore\n  File \"/usr/local/lib/python3.8/dist-packages/requests/sessions.py\", line 589, in request\n    resp = self.send(prep, **send_kwargs)\n  File \"/usr/local/lib/python3.8/dist-packages/requests/sessions.py\", line 703, in send\n    r = adapter.send(request, **kwargs)\n  File \"/usr/local/lib/python3.8/dist-packages/requests/adapters.py\", line 519, in send\n    raise ConnectionError(e, request=request)\nrequests.exceptions.ConnectionError: HTTPSConnectionPool(host='virtserver.swaggerhub.com', port=443): Max retries exceeded with url: /AAYUSHGARGBU/api_iot/1.0.0/devices (Caused by NewConnectionError('<urllib3.connection.VerifiedHTTPSConnection object at 0x7fcd9da762b0>: Failed to establish a new connection: [Errno -3] Temporary failure in name resolution'))"}], "interactions": []}, "elapsed_time": 66.20320490002632, "correlation_id": "6b94f54bbd724a9485b0ed65bd3df91f", "thread_id": 140521139144512, "hypothesis_output": [], "event_type": "AfterExecution"}
{"method": "POST", "path": "/AAYUSHGARGBU/api_iot/1.0.0/devices", "verbose_name": "POST /AAYUSHGARGBU/api_iot/1.0.0/devices", "relative_path": "/devices", "recursion_level": 0, "data_generation_method": ["positive", "negative"], "correlation_id": "32e12f26deb04ab89708486300557df4", "thread_id": 140521139144512, "event_type": "BeforeExecution"}
{"method": "POST", "path": "/AAYUSHGARGBU/api_iot/1.0.0/devices", "relative_path": "/devices", "verbose_name": "POST /AAYUSHGARGBU/api_iot/1.0.0/devices", "status": "error", "data_generation_method": ["positive"], "result": {"method": "POST", "path": "/AAYUSHGARGBU/api_iot/1.0.0/devices", "verbose_name": "POST /AAYUSHGARGBU/api_iot/1.0.0/devices", "has_failures": false, "has_errors": true, "has_logs": false, "is_errored": true, "is_flaky": false, "is_skipped": false, "skip_reason": null, "seed": 228635117958159357331249932965970836514, "data_generation_method": ["P"], "checks": [], "logs": [], "errors": [{"type": "connection_other", "title": "Network Error", "message": "Connection failed", "extras": ["Failed to establish a new connection: [Errno -3] Temporary failure in name resolution"], "exception": "requests.exceptions.ConnectionError: HTTPSConnectionPool(host='virtserver.swaggerhub.com', port=443): Max retries exceeded with url: /AAYUSHGARGBU/api_iot/1.0.0/devices (Caused by NewConnectionError('<urllib3.connection.VerifiedHTTPSConnection object at 0x7fcd9d9dffd0>: Failed to establish a new connection: [Errno -3] Temporary failure in name resolution'))", "exception_with_traceback": "Traceback (most recent call last):\n  File \"/usr/lib/python3/dist-packages/urllib3/connection.py\", line 156, in _new_conn\n    conn = connection.create_connection(\n  File \"/usr/lib/python3/dist-packages/urllib3/util/connection.py\", line 61, in create_connection\n    for res in socket.getaddrinfo(host, port, family, socket.SOCK_STREAM):\n  File \"/usr/lib/python3.8/socket.py\", line 918, in getaddrinfo\n    for res in _socket.getaddrinfo(host, port, family, type, proto, flags):\nsocket.gaierror: [Errno -3] Temporary failure in name resolution\n\nDuring handling of the above exception, another exception occurred:\n\nTraceback (most recent call last):\n  File \"/usr/lib/python3/dist-packages/urllib3/connectionpool.py\", line 665, in urlopen\n    httplib_response = self._make_request(\n  File \"/usr/lib/python3/dist-packages/urllib3/connectionpool.py\", line 376, in _make_request\n    self._validate_conn(conn)\n  File \"/usr/lib/python3/dist-packages/urllib3/connectionpool.py\", line 996, in _validate_conn\n    conn.connect()\n  File \"/usr/lib/python3/dist-packages/urllib3/connection.py\", line 300, in connect\n    conn = self._new_conn()\n  File \"/usr/lib/python3/dist-packages/urllib3/connection.py\", line 168, in _new_conn\n    raise NewConnectionError(\nurllib3.exceptions.NewConnectionError: <urllib3.connection.VerifiedHTTPSConnection object at 0x7fcd9d9dffd0>: Failed to establish a new connection: [Errno -3] Temporary failure in name resolution\n\nDuring handling of the above exception, another exception occurred:\n\nTraceback (most recent call last):\n  File \"/usr/local/lib/python3.8/dist-packages/requests/adapters.py\", line 486, in send\n    resp = conn.urlopen(\n  File \"/usr/lib/python3/dist-packages/urllib3/connectionpool.py\", line 719, in urlopen\n    retries = retries.increment(\n  File \"/usr/lib/python3/dist-packages/urllib3/util/retry.py\", line 436, in increment\n    raise MaxRetryError(_pool, url, error or ResponseError(cause))\nurllib3.exceptions.MaxRetryError: HTTPSConnectionPool(host='virtserver.swaggerhub.com', port=443): Max retries exceeded with url: /AAYUSHGARGBU/api_iot/1.0.0/devices (Caused by NewConnectionError('<urllib3.connection.VerifiedHTTPSConnection object at 0x7fcd9d9dffd0>: Failed to establish a new connection: [Errno -3] Temporary failure in name resolution'))\n\nDuring handling of the above exception, another exception occurred:\n\nTraceback (most recent call last):\n  File \"/usr/local/lib/python3.8/dist-packages/schemathesis/runner/impl/core.py\", line 816, in network_test\n    response = _network_test(case, *args)\n  File \"/usr/local/lib/python3.8/dist-packages/schemathesis/runner/impl/core.py\", line 848, in _network_test\n    response = case.call(**kwargs)\n  File \"/usr/local/lib/python3.8/dist-packages/schemathesis/models.py\", line 310, in call\n    response = self.operation.schema.transport.send(\n  File \"/usr/local/lib/python3.8/dist-packages/schemathesis/transports/__init__.py\", line 143, in send\n    response = session.request(**data)  # type: ignore\n  File \"/usr/local/lib/python3.8/dist-packages/requests/sessions.py\", line 589, in request\n    resp = self.send(prep, **send_kwargs)\n  File \"/usr/local/lib/python3.8/dist-packages/requests/sessions.py\", line 703, in send\n    r = adapter.send(request, **kwargs)\n  File \"/usr/local/lib/python3.8/dist-packages/requests/adapters.py\", line 519, in send\n    raise ConnectionError(e, request=request)\nrequests.exceptions.ConnectionError: HTTPSConnectionPool(host='virtserver.swaggerhub.com', port=443): Max retries exceeded with url: /AAYUSHGARGBU/api_iot/1.0.0/devices (Caused by NewConnectionError('<urllib3.connection.VerifiedHTTPSConnection object at 0x7fcd9d9dffd0>: Failed to establish a new connection: [Errno -3] Temporary failure in name resolution'))"}], "interactions": []}, "elapsed_time": 22.015106300008483, "correlation_id": "32e12f26deb04ab89708486300557df4", "thread_id": 140521139144512, "hypothesis_output": [], "event_type": "AfterExecution"}
{"method": "POST", "path": "/AAYUSHGARGBU/api_iot/1.0.0/lighting/dimmers/{deviceId}/{value}", "verbose_name": "POST /AAYUSHGARGBU/api_iot/1.0.0/lighting/dimmers/{deviceId}/{value}", "relative_path": "/lighting/dimmers/{deviceId}/{value}", "recursion_level": 0, "data_generation_method": ["positive", "negative"], "correlation_id": "87a19d6c016e4aa68f9f27f2865db320", "thread_id": 140521139144512, "event_type": "BeforeExecution"}
{"method": "POST", "path": "/AAYUSHGARGBU/api_iot/1.0.0/lighting/dimmers/{deviceId}/{value}", "relative_path": "/lighting/dimmers/{deviceId}/{value}", "verbose_name": "POST /AAYUSHGARGBU/api_iot/1.0.0/lighting/dimmers/{deviceId}/{value}", "status": "error", "data_generation_method": ["positive"], "result": {"method": "POST", "path": "/AAYUSHGARGBU/api_iot/1.0.0/lighting/dimmers/{deviceId}/{value}", "verbose_name": "POST /AAYUSHGARGBU/api_iot/1.0.0/lighting/dimmers/{deviceId}/{value}", "has_failures": false, "has_errors": true, "has_logs": false, "is_errored": true, "is_flaky": false, "is_skipped": false, "skip_reason": null, "seed": 228635117958159357331249932965970836514, "data_generation_method": ["P"], "checks": [], "logs": [], "errors": [{"type": "connection_other", "title": "Network Error", "message": "Connection failed", "extras": ["Failed to establish a new connection: [Errno -3] Temporary failure in name resolution"], "exception": "requests.exceptions.ConnectionError: HTTPSConnectionPool(host='virtserver.swaggerhub.com', port=443): Max retries exceeded with url: /AAYUSHGARGBU/api_iot/1.0.0/lighting/dimmers/0/0 (Caused by NewConnectionError('<urllib3.connection.VerifiedHTTPSConnection object at 0x7fcd9d983d00>: Failed to establish a new connection: [Errno -3] Temporary failure in name resolution'))", "exception_with_traceback": "Traceback (most recent call last):\n  File \"/usr/lib/python3/dist-packages/urllib3/connection.py\", line 156, in _new_conn\n    conn = connection.create_connection(\n  File \"/usr/lib/python3/dist-packages/urllib3/util/connection.py\", line 61, in create_connection\n    for res in socket.getaddrinfo(host, port, family, socket.SOCK_STREAM):\n  File \"/usr/lib/python3.8/socket.py\", line 918, in getaddrinfo\n    for res in _socket.getaddrinfo(host, port, family, type, proto, flags):\nsocket.gaierror: [Errno -3] Temporary failure in name resolution\n\nDuring handling of the above exception, another exception occurred:\n\nTraceback (most recent call last):\n  File \"/usr/lib/python3/dist-packages/urllib3/connectionpool.py\", line 665, in urlopen\n    httplib_response = self._make_request(\n  File \"/usr/lib/python3/dist-packages/urllib3/connectionpool.py\", line 376, in _make_request\n    self._validate_conn(conn)\n  File \"/usr/lib/python3/dist-packages/urllib3/connectionpool.py\", line 996, in _validate_conn\n    conn.connect()\n  File \"/usr/lib/python3/dist-packages/urllib3/connection.py\", line 300, in connect\n    conn = self._new_conn()\n  File \"/usr/lib/python3/dist-packages/urllib3/connection.py\", line 168, in _new_conn\n    raise NewConnectionError(\nurllib3.exceptions.NewConnectionError: <urllib3.connection.VerifiedHTTPSConnection object at 0x7fcd9d983d00>: Failed to establish a new connection: [Errno -3] Temporary failure in name resolution\n\nDuring handling of the above exception, another exception occurred:\n\nTraceback (most recent call last):\n  File \"/usr/local/lib/python3.8/dist-packages/requests/adapters.py\", line 486, in send\n    resp = conn.urlopen(\n  File \"/usr/lib/python3/dist-packages/urllib3/connectionpool.py\", line 719, in urlopen\n    retries = retries.increment(\n  File \"/usr/lib/python3/dist-packages/urllib3/util/retry.py\", line 436, in increment\n    raise MaxRetryError(_pool, url, error or ResponseError(cause))\nurllib3.exceptions.MaxRetryError: HTTPSConnectionPool(host='virtserver.swaggerhub.com', port=443): Max retries exceeded with url: /AAYUSHGARGBU/api_iot/1.0.0/lighting/dimmers/0/0 (Caused by NewConnectionError('<urllib3.connection.VerifiedHTTPSConnection object at 0x7fcd9d983d00>: Failed to establish a new connection: [Errno -3] Temporary failure in name resolution'))\n\nDuring handling of the above exception, another exception occurred:\n\nTraceback (most recent call last):\n  File \"/usr/local/lib/python3.8/dist-packages/schemathesis/runner/impl/core.py\", line 816, in network_test\n    response = _network_test(case, *args)\n  File \"/usr/local/lib/python3.8/dist-packages/schemathesis/runner/impl/core.py\", line 848, in _network_test\n    response = case.call(**kwargs)\n  File \"/usr/local/lib/python3.8/dist-packages/schemathesis/models.py\", line 310, in call\n    response = self.operation.schema.transport.send(\n  File \"/usr/local/lib/python3.8/dist-packages/schemathesis/transports/__init__.py\", line 143, in send\n    response = session.request(**data)  # type: ignore\n  File \"/usr/local/lib/python3.8/dist-packages/requests/sessions.py\", line 589, in request\n    resp = self.send(prep, **send_kwargs)\n  File \"/usr/local/lib/python3.8/dist-packages/requests/sessions.py\", line 703, in send\n    r = adapter.send(request, **kwargs)\n  File \"/usr/local/lib/python3.8/dist-packages/requests/adapters.py\", line 519, in send\n    raise ConnectionError(e, request=request)\nrequests.exceptions.ConnectionError: HTTPSConnectionPool(host='virtserver.swaggerhub.com', port=443): Max retries exceeded with url: /AAYUSHGARGBU/api_iot/1.0.0/lighting/dimmers/0/0 (Caused by NewConnectionError('<urllib3.connection.VerifiedHTTPSConnection object at 0x7fcd9d983d00>: Failed to establish a new connection: [Errno -3] Temporary failure in name resolution'))"}], "interactions": []}, "elapsed_time": 418.382760199951, "correlation_id": "87a19d6c016e4aa68f9f27f2865db320", "thread_id": 140521139144512, "hypothesis_output": [], "event_type": "AfterExecution"}
{"method": "POST", "path": "/AAYUSHGARGBU/api_iot/1.0.0/lighting/dimmers/{deviceId}/{value}/timer/{timeunit}", "verbose_name": "POST /AAYUSHGARGBU/api_iot/1.0.0/lighting/dimmers/{deviceId}/{value}/timer/{timeunit}", "relative_path": "/lighting/dimmers/{deviceId}/{value}/timer/{timeunit}", "recursion_level": 0, "data_generation_method": ["positive", "negative"], "correlation_id": "6d328c6f3c4b46699e0a9b74d321b573", "thread_id": 140521139144512, "event_type": "BeforeExecution"}
{"method": "POST", "path": "/AAYUSHGARGBU/api_iot/1.0.0/lighting/dimmers/{deviceId}/{value}/timer/{timeunit}", "relative_path": "/lighting/dimmers/{deviceId}/{value}/timer/{timeunit}", "verbose_name": "POST /AAYUSHGARGBU/api_iot/1.0.0/lighting/dimmers/{deviceId}/{value}/timer/{timeunit}", "status": "error", "data_generation_method": ["positive"], "result": {"method": "POST", "path": "/AAYUSHGARGBU/api_iot/1.0.0/lighting/dimmers/{deviceId}/{value}/timer/{timeunit}", "verbose_name": "POST /AAYUSHGARGBU/api_iot/1.0.0/lighting/dimmers/{deviceId}/{value}/timer/{timeunit}", "has_failures": false, "has_errors": true, "has_logs": false, "is_errored": true, "is_flaky": false, "is_skipped": false, "skip_reason": null, "seed": 228635117958159357331249932965970836514, "data_generation_method": ["P"], "checks": [], "logs": [], "errors": [{"type": "connection_other", "title": "Network Error", "message": "Connection failed", "extras": ["Failed to establish a new connection: [Errno -3] Temporary failure in name resolution"], "exception": "requests.exceptions.ConnectionError: HTTPSConnectionPool(host='virtserver.swaggerhub.com', port=443): Max retries exceeded with url: /AAYUSHGARGBU/api_iot/1.0.0/lighting/dimmers/0/0/timer/0 (Caused by NewConnectionError('<urllib3.connection.VerifiedHTTPSConnection object at 0x7fcd9d8caaf0>: Failed to establish a new connection: [Errno -3] Temporary failure in name resolution'))", "exception_with_traceback": "Traceback (most recent call last):\n  File \"/usr/lib/python3/dist-packages/urllib3/connection.py\", line 156, in _new_conn\n    conn = connection.create_connection(\n  File \"/usr/lib/python3/dist-packages/urllib3/util/connection.py\", line 61, in create_connection\n    for res in socket.getaddrinfo(host, port, family, socket.SOCK_STREAM):\n  File \"/usr/lib/python3.8/socket.py\", line 918, in getaddrinfo\n    for res in _socket.getaddrinfo(host, port, family, type, proto, flags):\nsocket.gaierror: [Errno -3] Temporary failure in name resolution\n\nDuring handling of the above exception, another exception occurred:\n\nTraceback (most recent call last):\n  File \"/usr/lib/python3/dist-packages/urllib3/connectionpool.py\", line 665, in urlopen\n    httplib_response = self._make_request(\n  File \"/usr/lib/python3/dist-packages/urllib3/connectionpool.py\", line 376, in _make_request\n    self._validate_conn(conn)\n  File \"/usr/lib/python3/dist-packages/urllib3/connectionpool.py\", line 996, in _validate_conn\n    conn.connect()\n  File \"/usr/lib/python3/dist-packages/urllib3/connection.py\", line 300, in connect\n    conn = self._new_conn()\n  File \"/usr/lib/python3/dist-packages/urllib3/connection.py\", line 168, in _new_conn\n    raise NewConnectionError(\nurllib3.exceptions.NewConnectionError: <urllib3.connection.VerifiedHTTPSConnection object at 0x7fcd9d8caaf0>: Failed to establish a new connection: [Errno -3] Temporary failure in name resolution\n\nDuring handling of the above exception, another exception occurred:\n\nTraceback (most recent call last):\n  File \"/usr/local/lib/python3.8/dist-packages/requests/adapters.py\", line 486, in send\n    resp = conn.urlopen(\n  File \"/usr/lib/python3/dist-packages/urllib3/connectionpool.py\", line 719, in urlopen\n    retries = retries.increment(\n  File \"/usr/lib/python3/dist-packages/urllib3/util/retry.py\", line 436, in increment\n    raise MaxRetryError(_pool, url, error or ResponseError(cause))\nurllib3.exceptions.MaxRetryError: HTTPSConnectionPool(host='virtserver.swaggerhub.com', port=443): Max retries exceeded with url: /AAYUSHGARGBU/api_iot/1.0.0/lighting/dimmers/0/0/timer/0 (Caused by NewConnectionError('<urllib3.connection.VerifiedHTTPSConnection object at 0x7fcd9d8caaf0>: Failed to establish a new connection: [Errno -3] Temporary failure in name resolution'))\n\nDuring handling of the above exception, another exception occurred:\n\nTraceback (most recent call last):\n  File \"/usr/local/lib/python3.8/dist-packages/schemathesis/runner/impl/core.py\", line 816, in network_test\n    response = _network_test(case, *args)\n  File \"/usr/local/lib/python3.8/dist-packages/schemathesis/runner/impl/core.py\", line 848, in _network_test\n    response = case.call(**kwargs)\n  File \"/usr/local/lib/python3.8/dist-packages/schemathesis/models.py\", line 310, in call\n    response = self.operation.schema.transport.send(\n  File \"/usr/local/lib/python3.8/dist-packages/schemathesis/transports/__init__.py\", line 143, in send\n    response = session.request(**data)  # type: ignore\n  File \"/usr/local/lib/python3.8/dist-packages/requests/sessions.py\", line 589, in request\n    resp = self.send(prep, **send_kwargs)\n  File \"/usr/local/lib/python3.8/dist-packages/requests/sessions.py\", line 703, in send\n    r = adapter.send(request, **kwargs)\n  File \"/usr/local/lib/python3.8/dist-packages/requests/adapters.py\", line 519, in send\n    raise ConnectionError(e, request=request)\nrequests.exceptions.ConnectionError: HTTPSConnectionPool(host='virtserver.swaggerhub.com', port=443): Max retries exceeded with url: /AAYUSHGARGBU/api_iot/1.0.0/lighting/dimmers/0/0/timer/0 (Caused by NewConnectionError('<urllib3.connection.VerifiedHTTPSConnection object at 0x7fcd9d8caaf0>: Failed to establish a new connection: [Errno -3] Temporary failure in name resolution'))"}], "interactions": []}, "elapsed_time": 308.27259109995794, "correlation_id": "6d328c6f3c4b46699e0a9b74d321b573", "thread_id": 140521139144512, "hypothesis_output": [], "event_type": "AfterExecution"}
{"method": "GET", "path": "/AAYUSHGARGBU/api_iot/1.0.0/lighting/switches/{deviceId}", "verbose_name": "GET /AAYUSHGARGBU/api_iot/1.0.0/lighting/switches/{deviceId}", "relative_path": "/lighting/switches/{deviceId}", "recursion_level": 0, "data_generation_method": ["positive", "negative"], "correlation_id": "3ed455db242e4c7394ebc32855a7e103", "thread_id": 140521139144512, "event_type": "BeforeExecution"}
{"method": "GET", "path": "/AAYUSHGARGBU/api_iot/1.0.0/lighting/switches/{deviceId}", "relative_path": "/lighting/switches/{deviceId}", "verbose_name": "GET /AAYUSHGARGBU/api_iot/1.0.0/lighting/switches/{deviceId}", "status": "error", "data_generation_method": ["positive"], "result": {"method": "GET", "path": "/AAYUSHGARGBU/api_iot/1.0.0/lighting/switches/{deviceId}", "verbose_name": "GET /AAYUSHGARGBU/api_iot/1.0.0/lighting/switches/{deviceId}", "has_failures": false, "has_errors": true, "has_logs": false, "is_errored": true, "is_flaky": false, "is_skipped": false, "skip_reason": null, "seed": 228635117958159357331249932965970836514, "data_generation_method": ["P"], "checks": [], "logs": [], "errors": [{"type": "connection_other", "title": "Network Error", "message": "Connection failed", "extras": ["Failed to establish a new connection: [Errno -3] Temporary failure in name resolution"], "exception": "requests.exceptions.ConnectionError: HTTPSConnectionPool(host='virtserver.swaggerhub.com', port=443): Max retries exceeded with url: /AAYUSHGARGBU/api_iot/1.0.0/lighting/switches/0 (Caused by NewConnectionError('<urllib3.connection.VerifiedHTTPSConnection object at 0x7fcd9d847a90>: Failed to establish a new connection: [Errno -3] Temporary failure in name resolution'))", "exception_with_traceback": "Traceback (most recent call last):\n  File \"/usr/lib/python3/dist-packages/urllib3/connection.py\", line 156, in _new_conn\n    conn = connection.create_connection(\n  File \"/usr/lib/python3/dist-packages/urllib3/util/connection.py\", line 61, in create_connection\n    for res in socket.getaddrinfo(host, port, family, socket.SOCK_STREAM):\n  File \"/usr/lib/python3.8/socket.py\", line 918, in getaddrinfo\n    for res in _socket.getaddrinfo(host, port, family, type, proto, flags):\nsocket.gaierror: [Errno -3] Temporary failure in name resolution\n\nDuring handling of the above exception, another exception occurred:\n\nTraceback (most recent call last):\n  File \"/usr/lib/python3/dist-packages/urllib3/connectionpool.py\", line 665, in urlopen\n    httplib_response = self._make_request(\n  File \"/usr/lib/python3/dist-packages/urllib3/connectionpool.py\", line 376, in _make_request\n    self._validate_conn(conn)\n  File \"/usr/lib/python3/dist-packages/urllib3/connectionpool.py\", line 996, in _validate_conn\n    conn.connect()\n  File \"/usr/lib/python3/dist-packages/urllib3/connection.py\", line 300, in connect\n    conn = self._new_conn()\n  File \"/usr/lib/python3/dist-packages/urllib3/connection.py\", line 168, in _new_conn\n    raise NewConnectionError(\nurllib3.exceptions.NewConnectionError: <urllib3.connection.VerifiedHTTPSConnection object at 0x7fcd9d847a90>: Failed to establish a new connection: [Errno -3] Temporary failure in name resolution\n\nDuring handling of the above exception, another exception occurred:\n\nTraceback (most recent call last):\n  File \"/usr/local/lib/python3.8/dist-packages/requests/adapters.py\", line 486, in send\n    resp = conn.urlopen(\n  File \"/usr/lib/python3/dist-packages/urllib3/connectionpool.py\", line 719, in urlopen\n    retries = retries.increment(\n  File \"/usr/lib/python3/dist-packages/urllib3/util/retry.py\", line 436, in increment\n    raise MaxRetryError(_pool, url, error or ResponseError(cause))\nurllib3.exceptions.MaxRetryError: HTTPSConnectionPool(host='virtserver.swaggerhub.com', port=443): Max retries exceeded with url: /AAYUSHGARGBU/api_iot/1.0.0/lighting/switches/0 (Caused by NewConnectionError('<urllib3.connection.VerifiedHTTPSConnection object at 0x7fcd9d847a90>: Failed to establish a new connection: [Errno -3] Temporary failure in name resolution'))\n\nDuring handling of the above exception, another exception occurred:\n\nTraceback (most recent call last):\n  File \"/usr/local/lib/python3.8/dist-packages/schemathesis/runner/impl/core.py\", line 816, in network_test\n    response = _network_test(case, *args)\n  File \"/usr/local/lib/python3.8/dist-packages/schemathesis/runner/impl/core.py\", line 848, in _network_test\n    response = case.call(**kwargs)\n  File \"/usr/local/lib/python3.8/dist-packages/schemathesis/models.py\", line 310, in call\n    response = self.operation.schema.transport.send(\n  File \"/usr/local/lib/python3.8/dist-packages/schemathesis/transports/__init__.py\", line 143, in send\n    response = session.request(**data)  # type: ignore\n  File \"/usr/local/lib/python3.8/dist-packages/requests/sessions.py\", line 589, in request\n    resp = self.send(prep, **send_kwargs)\n  File \"/usr/local/lib/python3.8/dist-packages/requests/sessions.py\", line 703, in send\n    r = adapter.send(request, **kwargs)\n  File \"/usr/local/lib/python3.8/dist-packages/requests/adapters.py\", line 519, in send\n    raise ConnectionError(e, request=request)\nrequests.exceptions.ConnectionError: HTTPSConnectionPool(host='virtserver.swaggerhub.com', port=443): Max retries exceeded with url: /AAYUSHGARGBU/api_iot/1.0.0/lighting/switches/0 (Caused by NewConnectionError('<urllib3.connection.VerifiedHTTPSConnection object at 0x7fcd9d847a90>: Failed to establish a new connection: [Errno -3] Temporary failure in name resolution'))"}], "interactions": []}, "elapsed_time": 396.33990749996156, "correlation_id": "3ed455db242e4c7394ebc32855a7e103", "thread_id": 140521139144512, "hypothesis_output": [], "event_type": "AfterExecution"}
{"method": "POST", "path": "/AAYUSHGARGBU/api_iot/1.0.0/lighting/switches/{deviceId}/{value}", "verbose_name": "POST /AAYUSHGARGBU/api_iot/1.0.0/lighting/switches/{deviceId}/{value}", "relative_path": "/lighting/switches/{deviceId}/{value}", "recursion_level": 0, "data_generation_method": ["positive", "negative"], "correlation_id": "0e455aed75744595b043bb548f710eed", "thread_id": 140521139144512, "event_type": "BeforeExecution"}
{"method": "POST", "path": "/AAYUSHGARGBU/api_iot/1.0.0/lighting/switches/{deviceId}/{value}", "relative_path": "/lighting/switches/{deviceId}/{value}", "verbose_name": "POST /AAYUSHGARGBU/api_iot/1.0.0/lighting/switches/{deviceId}/{value}", "status": "error", "data_generation_method": ["negative"], "result": {"method": "POST", "path": "/AAYUSHGARGBU/api_iot/1.0.0/lighting/switches/{deviceId}/{value}", "verbose_name": "POST /AAYUSHGARGBU/api_iot/1.0.0/lighting/switches/{deviceId}/{value}", "has_failures": false, "has_errors": true, "has_logs": false, "is_errored": true, "is_flaky": false, "is_skipped": false, "skip_reason": null, "seed": 228635117958159357331249932965970836514, "data_generation_method": ["N"], "checks": [], "logs": [], "errors": [{"type": "connection_other", "title": "Network Error", "message": "Connection failed", "extras": ["Failed to establish a new connection: [Errno -3] Temporary failure in name resolution"], "exception": "requests.exceptions.ConnectionError: HTTPSConnectionPool(host='virtserver.swaggerhub.com', port=443): Max retries exceeded with url: /AAYUSHGARGBU/api_iot/1.0.0/lighting/switches/false/false (Caused by NewConnectionError('<urllib3.connection.VerifiedHTTPSConnection object at 0x7fcd9d737040>: Failed to establish a new connection: [Errno -3] Temporary failure in name resolution'))", "exception_with_traceback": "Traceback (most recent call last):\n  File \"/usr/lib/python3/dist-packages/urllib3/connection.py\", line 156, in _new_conn\n    conn = connection.create_connection(\n  File \"/usr/lib/python3/dist-packages/urllib3/util/connection.py\", line 61, in create_connection\n    for res in socket.getaddrinfo(host, port, family, socket.SOCK_STREAM):\n  File \"/usr/lib/python3.8/socket.py\", line 918, in getaddrinfo\n    for res in _socket.getaddrinfo(host, port, family, type, proto, flags):\nsocket.gaierror: [Errno -3] Temporary failure in name resolution\n\nDuring handling of the above exception, another exception occurred:\n\nTraceback (most recent call last):\n  File \"/usr/lib/python3/dist-packages/urllib3/connectionpool.py\", line 665, in urlopen\n    httplib_response = self._make_request(\n  File \"/usr/lib/python3/dist-packages/urllib3/connectionpool.py\", line 376, in _make_request\n    self._validate_conn(conn)\n  File \"/usr/lib/python3/dist-packages/urllib3/connectionpool.py\", line 996, in _validate_conn\n    conn.connect()\n  File \"/usr/lib/python3/dist-packages/urllib3/connection.py\", line 300, in connect\n    conn = self._new_conn()\n  File \"/usr/lib/python3/dist-packages/urllib3/connection.py\", line 168, in _new_conn\n    raise NewConnectionError(\nurllib3.exceptions.NewConnectionError: <urllib3.connection.VerifiedHTTPSConnection object at 0x7fcd9d737040>: Failed to establish a new connection: [Errno -3] Temporary failure in name resolution\n\nDuring handling of the above exception, another exception occurred:\n\nTraceback (most recent call last):\n  File \"/usr/local/lib/python3.8/dist-packages/requests/adapters.py\", line 486, in send\n    resp = conn.urlopen(\n  File \"/usr/lib/python3/dist-packages/urllib3/connectionpool.py\", line 719, in urlopen\n    retries = retries.increment(\n  File \"/usr/lib/python3/dist-packages/urllib3/util/retry.py\", line 436, in increment\n    raise MaxRetryError(_pool, url, error or ResponseError(cause))\nurllib3.exceptions.MaxRetryError: HTTPSConnectionPool(host='virtserver.swaggerhub.com', port=443): Max retries exceeded with url: /AAYUSHGARGBU/api_iot/1.0.0/lighting/switches/false/false (Caused by NewConnectionError('<urllib3.connection.VerifiedHTTPSConnection object at 0x7fcd9d737040>: Failed to establish a new connection: [Errno -3] Temporary failure in name resolution'))\n\nDuring handling of the above exception, another exception occurred:\n\nTraceback (most recent call last):\n  File \"/usr/local/lib/python3.8/dist-packages/schemathesis/runner/impl/core.py\", line 816, in network_test\n    response = _network_test(case, *args)\n  File \"/usr/local/lib/python3.8/dist-packages/schemathesis/runner/impl/core.py\", line 848, in _network_test\n    response = case.call(**kwargs)\n  File \"/usr/local/lib/python3.8/dist-packages/schemathesis/models.py\", line 310, in call\n    response = self.operation.schema.transport.send(\n  File \"/usr/local/lib/python3.8/dist-packages/schemathesis/transports/__init__.py\", line 143, in send\n    response = session.request(**data)  # type: ignore\n  File \"/usr/local/lib/python3.8/dist-packages/requests/sessions.py\", line 589, in request\n    resp = self.send(prep, **send_kwargs)\n  File \"/usr/local/lib/python3.8/dist-packages/requests/sessions.py\", line 703, in send\n    r = adapter.send(request, **kwargs)\n  File \"/usr/local/lib/python3.8/dist-packages/requests/adapters.py\", line 519, in send\n    raise ConnectionError(e, request=request)\nrequests.exceptions.ConnectionError: HTTPSConnectionPool(host='virtserver.swaggerhub.com', port=443): Max retries exceeded with url: /AAYUSHGARGBU/api_iot/1.0.0/lighting/switches/false/false (Caused by NewConnectionError('<urllib3.connection.VerifiedHTTPSConnection object at 0x7fcd9d737040>: Failed to establish a new connection: [Errno -3] Temporary failure in name resolution'))"}], "interactions": []}, "elapsed_time": 264.3096775000449, "correlation_id": "0e455aed75744595b043bb548f710eed", "thread_id": 140521139144512, "hypothesis_output": [], "event_type": "AfterExecution"}
{"method": "POST", "path": "/AAYUSHGARGBU/api_iot/1.0.0/lighting/switches/{deviceId}/{value}/timer/{minutes}", "verbose_name": "POST /AAYUSHGARGBU/api_iot/1.0.0/lighting/switches/{deviceId}/{value}/timer/{minutes}", "relative_path": "/lighting/switches/{deviceId}/{value}/timer/{minutes}", "recursion_level": 0, "data_generation_method": ["positive", "negative"], "correlation_id": "7c5c01c607d04f539775477153c18941", "thread_id": 140521139144512, "event_type": "BeforeExecution"}
{"method": "POST", "path": "/AAYUSHGARGBU/api_iot/1.0.0/lighting/switches/{deviceId}/{value}/timer/{minutes}", "relative_path": "/lighting/switches/{deviceId}/{value}/timer/{minutes}", "verbose_name": "POST /AAYUSHGARGBU/api_iot/1.0.0/lighting/switches/{deviceId}/{value}/timer/{minutes}", "status": "error", "data_generation_method": ["negative"], "result": {"method": "POST", "path": "/AAYUSHGARGBU/api_iot/1.0.0/lighting/switches/{deviceId}/{value}/timer/{minutes}", "verbose_name": "POST /AAYUSHGARGBU/api_iot/1.0.0/lighting/switches/{deviceId}/{value}/timer/{minutes}", "has_failures": false, "has_errors": true, "has_logs": false, "is_errored": true, "is_flaky": false, "is_skipped": false, "skip_reason": null, "seed": 228635117958159357331249932965970836514, "data_generation_method": ["N"], "checks": [], "logs": [], "errors": [{"type": "connection_other", "title": "Network Error", "message": "Connection failed", "extras": ["Failed to establish a new connection: [Errno -3] Temporary failure in name resolution"], "exception": "requests.exceptions.ConnectionError: HTTPSConnectionPool(host='virtserver.swaggerhub.com', port=443): Max retries exceeded with url: /AAYUSHGARGBU/api_iot/1.0.0/lighting/switches/0/-524927271/timer/43 (Caused by NewConnectionError('<urllib3.connection.VerifiedHTTPSConnection object at 0x7fcd9d6e18e0>: Failed to establish a new connection: [Errno -3] Temporary failure in name resolution'))", "exception_with_traceback": "Traceback (most recent call last):\n  File \"/usr/lib/python3/dist-packages/urllib3/connection.py\", line 156, in _new_conn\n    conn = connection.create_connection(\n  File \"/usr/lib/python3/dist-packages/urllib3/util/connection.py\", line 61, in create_connection\n    for res in socket.getaddrinfo(host, port, family, socket.SOCK_STREAM):\n  File \"/usr/lib/python3.8/socket.py\", line 918, in getaddrinfo\n    for res in _socket.getaddrinfo(host, port, family, type, proto, flags):\nsocket.gaierror: [Errno -3] Temporary failure in name resolution\n\nDuring handling of the above exception, another exception occurred:\n\nTraceback (most recent call last):\n  File \"/usr/lib/python3/dist-packages/urllib3/connectionpool.py\", line 665, in urlopen\n    httplib_response = self._make_request(\n  File \"/usr/lib/python3/dist-packages/urllib3/connectionpool.py\", line 376, in _make_request\n    self._validate_conn(conn)\n  File \"/usr/lib/python3/dist-packages/urllib3/connectionpool.py\", line 996, in _validate_conn\n    conn.connect()\n  File \"/usr/lib/python3/dist-packages/urllib3/connection.py\", line 300, in connect\n    conn = self._new_conn()\n  File \"/usr/lib/python3/dist-packages/urllib3/connection.py\", line 168, in _new_conn\n    raise NewConnectionError(\nurllib3.exceptions.NewConnectionError: <urllib3.connection.VerifiedHTTPSConnection object at 0x7fcd9d6e18e0>: Failed to establish a new connection: [Errno -3] Temporary failure in name resolution\n\nDuring handling of the above exception, another exception occurred:\n\nTraceback (most recent call last):\n  File \"/usr/local/lib/python3.8/dist-packages/requests/adapters.py\", line 486, in send\n    resp = conn.urlopen(\n  File \"/usr/lib/python3/dist-packages/urllib3/connectionpool.py\", line 719, in urlopen\n    retries = retries.increment(\n  File \"/usr/lib/python3/dist-packages/urllib3/util/retry.py\", line 436, in increment\n    raise MaxRetryError(_pool, url, error or ResponseError(cause))\nurllib3.exceptions.MaxRetryError: HTTPSConnectionPool(host='virtserver.swaggerhub.com', port=443): Max retries exceeded with url: /AAYUSHGARGBU/api_iot/1.0.0/lighting/switches/0/-524927271/timer/43 (Caused by NewConnectionError('<urllib3.connection.VerifiedHTTPSConnection object at 0x7fcd9d6e18e0>: Failed to establish a new connection: [Errno -3] Temporary failure in name resolution'))\n\nDuring handling of the above exception, another exception occurred:\n\nTraceback (most recent call last):\n  File \"/usr/local/lib/python3.8/dist-packages/schemathesis/runner/impl/core.py\", line 816, in network_test\n    response = _network_test(case, *args)\n  File \"/usr/local/lib/python3.8/dist-packages/schemathesis/runner/impl/core.py\", line 848, in _network_test\n    response = case.call(**kwargs)\n  File \"/usr/local/lib/python3.8/dist-packages/schemathesis/models.py\", line 310, in call\n    response = self.operation.schema.transport.send(\n  File \"/usr/local/lib/python3.8/dist-packages/schemathesis/transports/__init__.py\", line 143, in send\n    response = session.request(**data)  # type: ignore\n  File \"/usr/local/lib/python3.8/dist-packages/requests/sessions.py\", line 589, in request\n    resp = self.send(prep, **send_kwargs)\n  File \"/usr/local/lib/python3.8/dist-packages/requests/sessions.py\", line 703, in send\n    r = adapter.send(request, **kwargs)\n  File \"/usr/local/lib/python3.8/dist-packages/requests/adapters.py\", line 519, in send\n    raise ConnectionError(e, request=request)\nrequests.exceptions.ConnectionError: HTTPSConnectionPool(host='virtserver.swaggerhub.com', port=443): Max retries exceeded with url: /AAYUSHGARGBU/api_iot/1.0.0/lighting/switches/0/-524927271/timer/43 (Caused by NewConnectionError('<urllib3.connection.VerifiedHTTPSConnection object at 0x7fcd9d6e18e0>: Failed to establish a new connection: [Errno -3] Temporary failure in name resolution'))"}], "interactions": []}, "elapsed_time": 353.45160979998764, "correlation_id": "7c5c01c607d04f539775477153c18941", "thread_id": 140521139144512, "hypothesis_output": [], "event_type": "AfterExecution"}
{"method": "GET", "path": "/AAYUSHGARGBU/api_iot/1.0.0/lightingSummary", "verbose_name": "GET /AAYUSHGARGBU/api_iot/1.0.0/lightingSummary", "relative_path": "/lightingSummary", "recursion_level": 0, "data_generation_method": ["positive", "negative"], "correlation_id": "15d2fb7b61454470bb902dfbebab91da", "thread_id": 140521139144512, "event_type": "BeforeExecution"}
{"method": "GET", "path": "/AAYUSHGARGBU/api_iot/1.0.0/lightingSummary", "relative_path": "/lightingSummary", "verbose_name": "GET /AAYUSHGARGBU/api_iot/1.0.0/lightingSummary", "status": "error", "data_generation_method": ["positive"], "result": {"method": "GET", "path": "/AAYUSHGARGBU/api_iot/1.0.0/lightingSummary", "verbose_name": "GET /AAYUSHGARGBU/api_iot/1.0.0/lightingSummary", "has_failures": false, "has_errors": true, "has_logs": false, "is_errored": true, "is_flaky": false, "is_skipped": false, "skip_reason": null, "seed": 228635117958159357331249932965970836514, "data_generation_method": ["P"], "checks": [], "logs": [], "errors": [{"type": "connection_other", "title": "Network Error", "message": "Connection failed", "extras": ["Failed to establish a new connection: [Errno -3] Temporary failure in name resolution"], "exception": "requests.exceptions.ConnectionError: HTTPSConnectionPool(host='virtserver.swaggerhub.com', port=443): Max retries exceeded with url: /AAYUSHGARGBU/api_iot/1.0.0/lightingSummary (Caused by NewConnectionError('<urllib3.connection.VerifiedHTTPSConnection object at 0x7fcd9d4fc700>: Failed to establish a new connection: [Errno -3] Temporary failure in name resolution'))", "exception_with_traceback": "Traceback (most recent call last):\n  File \"/usr/lib/python3/dist-packages/urllib3/connection.py\", line 156, in _new_conn\n    conn = connection.create_connection(\n  File \"/usr/lib/python3/dist-packages/urllib3/util/connection.py\", line 61, in create_connection\n    for res in socket.getaddrinfo(host, port, family, socket.SOCK_STREAM):\n  File \"/usr/lib/python3.8/socket.py\", line 918, in getaddrinfo\n    for res in _socket.getaddrinfo(host, port, family, type, proto, flags):\nsocket.gaierror: [Errno -3] Temporary failure in name resolution\n\nDuring handling of the above exception, another exception occurred:\n\nTraceback (most recent call last):\n  File \"/usr/lib/python3/dist-packages/urllib3/connectionpool.py\", line 665, in urlopen\n    httplib_response = self._make_request(\n  File \"/usr/lib/python3/dist-packages/urllib3/connectionpool.py\", line 376, in _make_request\n    self._validate_conn(conn)\n  File \"/usr/lib/python3/dist-packages/urllib3/connectionpool.py\", line 996, in _validate_conn\n    conn.connect()\n  File \"/usr/lib/python3/dist-packages/urllib3/connection.py\", line 300, in connect\n    conn = self._new_conn()\n  File \"/usr/lib/python3/dist-packages/urllib3/connection.py\", line 168, in _new_conn\n    raise NewConnectionError(\nurllib3.exceptions.NewConnectionError: <urllib3.connection.VerifiedHTTPSConnection object at 0x7fcd9d4fc700>: Failed to establish a new connection: [Errno -3] Temporary failure in name resolution\n\nDuring handling of the above exception, another exception occurred:\n\nTraceback (most recent call last):\n  File \"/usr/local/lib/python3.8/dist-packages/requests/adapters.py\", line 486, in send\n    resp = conn.urlopen(\n  File \"/usr/lib/python3/dist-packages/urllib3/connectionpool.py\", line 719, in urlopen\n    retries = retries.increment(\n  File \"/usr/lib/python3/dist-packages/urllib3/util/retry.py\", line 436, in increment\n    raise MaxRetryError(_pool, url, error or ResponseError(cause))\nurllib3.exceptions.MaxRetryError: HTTPSConnectionPool(host='virtserver.swaggerhub.com', port=443): Max retries exceeded with url: /AAYUSHGARGBU/api_iot/1.0.0/lightingSummary (Caused by NewConnectionError('<urllib3.connection.VerifiedHTTPSConnection object at 0x7fcd9d4fc700>: Failed to establish a new connection: [Errno -3] Temporary failure in name resolution'))\n\nDuring handling of the above exception, another exception occurred:\n\nTraceback (most recent call last):\n  File \"/usr/local/lib/python3.8/dist-packages/schemathesis/runner/impl/core.py\", line 816, in network_test\n    response = _network_test(case, *args)\n  File \"/usr/local/lib/python3.8/dist-packages/schemathesis/runner/impl/core.py\", line 848, in _network_test\n    response = case.call(**kwargs)\n  File \"/usr/local/lib/python3.8/dist-packages/schemathesis/models.py\", line 310, in call\n    response = self.operation.schema.transport.send(\n  File \"/usr/local/lib/python3.8/dist-packages/schemathesis/transports/__init__.py\", line 143, in send\n    response = session.request(**data)  # type: ignore\n  File \"/usr/local/lib/python3.8/dist-packages/requests/sessions.py\", line 589, in request\n    resp = self.send(prep, **send_kwargs)\n  File \"/usr/local/lib/python3.8/dist-packages/requests/sessions.py\", line 703, in send\n    r = adapter.send(request, **kwargs)\n  File \"/usr/local/lib/python3.8/dist-packages/requests/adapters.py\", line 519, in send\n    raise ConnectionError(e, request=request)\nrequests.exceptions.ConnectionError: HTTPSConnectionPool(host='virtserver.swaggerhub.com', port=443): Max retries exceeded with url: /AAYUSHGARGBU/api_iot/1.0.0/lightingSummary (Caused by NewConnectionError('<urllib3.connection.VerifiedHTTPSConnection object at 0x7fcd9d4fc700>: Failed to establish a new connection: [Errno -3] Temporary failure in name resolution'))"}], "interactions": []}, "elapsed_time": 66.05246689997148, "correlation_id": "15d2fb7b61454470bb902dfbebab91da", "thread_id": 140521139144512, "hypothesis_output": [], "event_type": "AfterExecution"}
{"method": "GET", "path": "/AAYUSHGARGBU/api_iot/1.0.0/temperature", "verbose_name": "GET /AAYUSHGARGBU/api_iot/1.0.0/temperature", "relative_path": "/temperature", "recursion_level": 0, "data_generation_method": ["positive", "negative"], "correlation_id": "02c53c0bd1cc431b97516155cdd1ae29", "thread_id": 140521139144512, "event_type": "BeforeExecution"}
{"method": "GET", "path": "/AAYUSHGARGBU/api_iot/1.0.0/temperature", "relative_path": "/temperature", "verbose_name": "GET /AAYUSHGARGBU/api_iot/1.0.0/temperature", "status": "error", "data_generation_method": ["positive"], "result": {"method": "GET", "path": "/AAYUSHGARGBU/api_iot/1.0.0/temperature", "verbose_name": "GET /AAYUSHGARGBU/api_iot/1.0.0/temperature", "has_failures": false, "has_errors": true, "has_logs": false, "is_errored": true, "is_flaky": false, "is_skipped": false, "skip_reason": null, "seed": 228635117958159357331249932965970836514, "data_generation_method": ["P"], "checks": [], "logs": [], "errors": [{"type": "connection_other", "title": "Network Error", "message": "Connection failed", "extras": ["Failed to establish a new connection: [Errno -3] Temporary failure in name resolution"], "exception": "requests.exceptions.ConnectionError: HTTPSConnectionPool(host='virtserver.swaggerhub.com', port=443): Max retries exceeded with url: /AAYUSHGARGBU/api_iot/1.0.0/temperature (Caused by NewConnectionError('<urllib3.connection.VerifiedHTTPSConnection object at 0x7fcd9d4b7ac0>: Failed to establish a new connection: [Errno -3] Temporary failure in name resolution'))", "exception_with_traceback": "Traceback (most recent call last):\n  File \"/usr/lib/python3/dist-packages/urllib3/connection.py\", line 156, in _new_conn\n    conn = connection.create_connection(\n  File \"/usr/lib/python3/dist-packages/urllib3/util/connection.py\", line 61, in create_connection\n    for res in socket.getaddrinfo(host, port, family, socket.SOCK_STREAM):\n  File \"/usr/lib/python3.8/socket.py\", line 918, in getaddrinfo\n    for res in _socket.getaddrinfo(host, port, family, type, proto, flags):\nsocket.gaierror: [Errno -3] Temporary failure in name resolution\n\nDuring handling of the above exception, another exception occurred:\n\nTraceback (most recent call last):\n  File \"/usr/lib/python3/dist-packages/urllib3/connectionpool.py\", line 665, in urlopen\n    httplib_response = self._make_request(\n  File \"/usr/lib/python3/dist-packages/urllib3/connectionpool.py\", line 376, in _make_request\n    self._validate_conn(conn)\n  File \"/usr/lib/python3/dist-packages/urllib3/connectionpool.py\", line 996, in _validate_conn\n    conn.connect()\n  File \"/usr/lib/python3/dist-packages/urllib3/connection.py\", line 300, in connect\n    conn = self._new_conn()\n  File \"/usr/lib/python3/dist-packages/urllib3/connection.py\", line 168, in _new_conn\n    raise NewConnectionError(\nurllib3.exceptions.NewConnectionError: <urllib3.connection.VerifiedHTTPSConnection object at 0x7fcd9d4b7ac0>: Failed to establish a new connection: [Errno -3] Temporary failure in name resolution\n\nDuring handling of the above exception, another exception occurred:\n\nTraceback (most recent call last):\n  File \"/usr/local/lib/python3.8/dist-packages/requests/adapters.py\", line 486, in send\n    resp = conn.urlopen(\n  File \"/usr/lib/python3/dist-packages/urllib3/connectionpool.py\", line 719, in urlopen\n    retries = retries.increment(\n  File \"/usr/lib/python3/dist-packages/urllib3/util/retry.py\", line 436, in increment\n    raise MaxRetryError(_pool, url, error or ResponseError(cause))\nurllib3.exceptions.MaxRetryError: HTTPSConnectionPool(host='virtserver.swaggerhub.com', port=443): Max retries exceeded with url: /AAYUSHGARGBU/api_iot/1.0.0/temperature (Caused by NewConnectionError('<urllib3.connection.VerifiedHTTPSConnection object at 0x7fcd9d4b7ac0>: Failed to establish a new connection: [Errno -3] Temporary failure in name resolution'))\n\nDuring handling of the above exception, another exception occurred:\n\nTraceback (most recent call last):\n  File \"/usr/local/lib/python3.8/dist-packages/schemathesis/runner/impl/core.py\", line 816, in network_test\n    response = _network_test(case, *args)\n  File \"/usr/local/lib/python3.8/dist-packages/schemathesis/runner/impl/core.py\", line 848, in _network_test\n    response = case.call(**kwargs)\n  File \"/usr/local/lib/python3.8/dist-packages/schemathesis/models.py\", line 310, in call\n    response = self.operation.schema.transport.send(\n  File \"/usr/local/lib/python3.8/dist-packages/schemathesis/transports/__init__.py\", line 143, in send\n    response = session.request(**data)  # type: ignore\n  File \"/usr/local/lib/python3.8/dist-packages/requests/sessions.py\", line 589, in request\n    resp = self.send(prep, **send_kwargs)\n  File \"/usr/local/lib/python3.8/dist-packages/requests/sessions.py\", line 703, in send\n    r = adapter.send(request, **kwargs)\n  File \"/usr/local/lib/python3.8/dist-packages/requests/adapters.py\", line 519, in send\n    raise ConnectionError(e, request=request)\nrequests.exceptions.ConnectionError: HTTPSConnectionPool(host='virtserver.swaggerhub.com', port=443): Max retries exceeded with url: /AAYUSHGARGBU/api_iot/1.0.0/temperature (Caused by NewConnectionError('<urllib3.connection.VerifiedHTTPSConnection object at 0x7fcd9d4b7ac0>: Failed to establish a new connection: [Errno -3] Temporary failure in name resolution'))"}], "interactions": []}, "elapsed_time": 66.0531358999433, "correlation_id": "02c53c0bd1cc431b97516155cdd1ae29", "thread_id": 140521139144512, "hypothesis_output": [], "event_type": "AfterExecution"}
{"method": "GET", "path": "/AAYUSHGARGBU/api_iot/1.0.0/temperature/forecast/{days}", "verbose_name": "GET /AAYUSHGARGBU/api_iot/1.0.0/temperature/forecast/{days}", "relative_path": "/temperature/forecast/{days}", "recursion_level": 0, "data_generation_method": ["positive", "negative"], "correlation_id": "3847ca77e3e1436f9867f96bff6f6dc1", "thread_id": 140521139144512, "event_type": "BeforeExecution"}
{"method": "GET", "path": "/AAYUSHGARGBU/api_iot/1.0.0/temperature/forecast/{days}", "relative_path": "/temperature/forecast/{days}", "verbose_name": "GET /AAYUSHGARGBU/api_iot/1.0.0/temperature/forecast/{days}", "status": "error", "data_generation_method": ["positive"], "result": {"method": "GET", "path": "/AAYUSHGARGBU/api_iot/1.0.0/temperature/forecast/{days}", "verbose_name": "GET /AAYUSHGARGBU/api_iot/1.0.0/temperature/forecast/{days}", "has_failures": false, "has_errors": true, "has_logs": false, "is_errored": true, "is_flaky": false, "is_skipped": false, "skip_reason": null, "seed": 228635117958159357331249932965970836514, "data_generation_method": ["P"], "checks": [], "logs": [], "errors": [{"type": "connection_other", "title": "Network Error", "message": "Connection failed", "extras": ["Failed to establish a new connection: [Errno -3] Temporary failure in name resolution"], "exception": "requests.exceptions.ConnectionError: HTTPSConnectionPool(host='virtserver.swaggerhub.com', port=443): Max retries exceeded with url: /AAYUSHGARGBU/api_iot/1.0.0/temperature/forecast/0 (Caused by NewConnectionError('<urllib3.connection.VerifiedHTTPSConnection object at 0x7fcd9d4f5ac0>: Failed to establish a new connection: [Errno -3] Temporary failure in name resolution'))", "exception_with_traceback": "Traceback (most recent call last):\n  File \"/usr/lib/python3/dist-packages/urllib3/connection.py\", line 156, in _new_conn\n    conn = connection.create_connection(\n  File \"/usr/lib/python3/dist-packages/urllib3/util/connection.py\", line 61, in create_connection\n    for res in socket.getaddrinfo(host, port, family, socket.SOCK_STREAM):\n  File \"/usr/lib/python3.8/socket.py\", line 918, in getaddrinfo\n    for res in _socket.getaddrinfo(host, port, family, type, proto, flags):\nsocket.gaierror: [Errno -3] Temporary failure in name resolution\n\nDuring handling of the above exception, another exception occurred:\n\nTraceback (most recent call last):\n  File \"/usr/lib/python3/dist-packages/urllib3/connectionpool.py\", line 665, in urlopen\n    httplib_response = self._make_request(\n  File \"/usr/lib/python3/dist-packages/urllib3/connectionpool.py\", line 376, in _make_request\n    self._validate_conn(conn)\n  File \"/usr/lib/python3/dist-packages/urllib3/connectionpool.py\", line 996, in _validate_conn\n    conn.connect()\n  File \"/usr/lib/python3/dist-packages/urllib3/connection.py\", line 300, in connect\n    conn = self._new_conn()\n  File \"/usr/lib/python3/dist-packages/urllib3/connection.py\", line 168, in _new_conn\n    raise NewConnectionError(\nurllib3.exceptions.NewConnectionError: <urllib3.connection.VerifiedHTTPSConnection object at 0x7fcd9d4f5ac0>: Failed to establish a new connection: [Errno -3] Temporary failure in name resolution\n\nDuring handling of the above exception, another exception occurred:\n\nTraceback (most recent call last):\n  File \"/usr/local/lib/python3.8/dist-packages/requests/adapters.py\", line 486, in send\n    resp = conn.urlopen(\n  File \"/usr/lib/python3/dist-packages/urllib3/connectionpool.py\", line 719, in urlopen\n    retries = retries.increment(\n  File \"/usr/lib/python3/dist-packages/urllib3/util/retry.py\", line 436, in increment\n    raise MaxRetryError(_pool, url, error or ResponseError(cause))\nurllib3.exceptions.MaxRetryError: HTTPSConnectionPool(host='virtserver.swaggerhub.com', port=443): Max retries exceeded with url: /AAYUSHGARGBU/api_iot/1.0.0/temperature/forecast/0 (Caused by NewConnectionError('<urllib3.connection.VerifiedHTTPSConnection object at 0x7fcd9d4f5ac0>: Failed to establish a new connection: [Errno -3] Temporary failure in name resolution'))\n\nDuring handling of the above exception, another exception occurred:\n\nTraceback (most recent call last):\n  File \"/usr/local/lib/python3.8/dist-packages/schemathesis/runner/impl/core.py\", line 816, in network_test\n    response = _network_test(case, *args)\n  File \"/usr/local/lib/python3.8/dist-packages/schemathesis/runner/impl/core.py\", line 848, in _network_test\n    response = case.call(**kwargs)\n  File \"/usr/local/lib/python3.8/dist-packages/schemathesis/models.py\", line 310, in call\n    response = self.operation.schema.transport.send(\n  File \"/usr/local/lib/python3.8/dist-packages/schemathesis/transports/__init__.py\", line 143, in send\n    response = session.request(**data)  # type: ignore\n  File \"/usr/local/lib/python3.8/dist-packages/requests/sessions.py\", line 589, in request\n    resp = self.send(prep, **send_kwargs)\n  File \"/usr/local/lib/python3.8/dist-packages/requests/sessions.py\", line 703, in send\n    r = adapter.send(request, **kwargs)\n  File \"/usr/local/lib/python3.8/dist-packages/requests/adapters.py\", line 519, in send\n    raise ConnectionError(e, request=request)\nrequests.exceptions.ConnectionError: HTTPSConnectionPool(host='virtserver.swaggerhub.com', port=443): Max retries exceeded with url: /AAYUSHGARGBU/api_iot/1.0.0/temperature/forecast/0 (Caused by NewConnectionError('<urllib3.connection.VerifiedHTTPSConnection object at 0x7fcd9d4f5ac0>: Failed to establish a new connection: [Errno -3] Temporary failure in name resolution'))"}], "interactions": []}, "elapsed_time": 66.05677350005135, "correlation_id": "3847ca77e3e1436f9867f96bff6f6dc1", "thread_id": 140521139144512, "hypothesis_output": [], "event_type": "AfterExecution"}
{"method": "GET", "path": "/AAYUSHGARGBU/api_iot/1.0.0/temperature/{zoneId}", "verbose_name": "GET /AAYUSHGARGBU/api_iot/1.0.0/temperature/{zoneId}", "relative_path": "/temperature/{zoneId}", "recursion_level": 0, "data_generation_method": ["positive", "negative"], "correlation_id": "9e9b023cdc88464db4a7e01fb2f78a62", "thread_id": 140521139144512, "event_type": "BeforeExecution"}
{"method": "GET", "path": "/AAYUSHGARGBU/api_iot/1.0.0/temperature/{zoneId}", "relative_path": "/temperature/{zoneId}", "verbose_name": "GET /AAYUSHGARGBU/api_iot/1.0.0/temperature/{zoneId}", "status": "error", "data_generation_method": ["positive"], "result": {"method": "GET", "path": "/AAYUSHGARGBU/api_iot/1.0.0/temperature/{zoneId}", "verbose_name": "GET /AAYUSHGARGBU/api_iot/1.0.0/temperature/{zoneId}", "has_failures": false, "has_errors": true, "has_logs": false, "is_errored": true, "is_flaky": false, "is_skipped": false, "skip_reason": null, "seed": 228635117958159357331249932965970836514, "data_generation_method": ["P"], "checks": [], "logs": [], "errors": [{"type": "connection_other", "title": "Network Error", "message": "Connection failed", "extras": ["Failed to establish a new connection: [Errno -3] Temporary failure in name resolution"], "exception": "requests.exceptions.ConnectionError: HTTPSConnectionPool(host='virtserver.swaggerhub.com', port=443): Max retries exceeded with url: /AAYUSHGARGBU/api_iot/1.0.0/temperature/0 (Caused by NewConnectionError('<urllib3.connection.VerifiedHTTPSConnection object at 0x7fcd9d4a98e0>: Failed to establish a new connection: [Errno -3] Temporary failure in name resolution'))", "exception_with_traceback": "Traceback (most recent call last):\n  File \"/usr/lib/python3/dist-packages/urllib3/connection.py\", line 156, in _new_conn\n    conn = connection.create_connection(\n  File \"/usr/lib/python3/dist-packages/urllib3/util/connection.py\", line 61, in create_connection\n    for res in socket.getaddrinfo(host, port, family, socket.SOCK_STREAM):\n  File \"/usr/lib/python3.8/socket.py\", line 918, in getaddrinfo\n    for res in _socket.getaddrinfo(host, port, family, type, proto, flags):\nsocket.gaierror: [Errno -3] Temporary failure in name resolution\n\nDuring handling of the above exception, another exception occurred:\n\nTraceback (most recent call last):\n  File \"/usr/lib/python3/dist-packages/urllib3/connectionpool.py\", line 665, in urlopen\n    httplib_response = self._make_request(\n  File \"/usr/lib/python3/dist-packages/urllib3/connectionpool.py\", line 376, in _make_request\n    self._validate_conn(conn)\n  File \"/usr/lib/python3/dist-packages/urllib3/connectionpool.py\", line 996, in _validate_conn\n    conn.connect()\n  File \"/usr/lib/python3/dist-packages/urllib3/connection.py\", line 300, in connect\n    conn = self._new_conn()\n  File \"/usr/lib/python3/dist-packages/urllib3/connection.py\", line 168, in _new_conn\n    raise NewConnectionError(\nurllib3.exceptions.NewConnectionError: <urllib3.connection.VerifiedHTTPSConnection object at 0x7fcd9d4a98e0>: Failed to establish a new connection: [Errno -3] Temporary failure in name resolution\n\nDuring handling of the above exception, another exception occurred:\n\nTraceback (most recent call last):\n  File \"/usr/local/lib/python3.8/dist-packages/requests/adapters.py\", line 486, in send\n    resp = conn.urlopen(\n  File \"/usr/lib/python3/dist-packages/urllib3/connectionpool.py\", line 719, in urlopen\n    retries = retries.increment(\n  File \"/usr/lib/python3/dist-packages/urllib3/util/retry.py\", line 436, in increment\n    raise MaxRetryError(_pool, url, error or ResponseError(cause))\nurllib3.exceptions.MaxRetryError: HTTPSConnectionPool(host='virtserver.swaggerhub.com', port=443): Max retries exceeded with url: /AAYUSHGARGBU/api_iot/1.0.0/temperature/0 (Caused by NewConnectionError('<urllib3.connection.VerifiedHTTPSConnection object at 0x7fcd9d4a98e0>: Failed to establish a new connection: [Errno -3] Temporary failure in name resolution'))\n\nDuring handling of the above exception, another exception occurred:\n\nTraceback (most recent call last):\n  File \"/usr/local/lib/python3.8/dist-packages/schemathesis/runner/impl/core.py\", line 816, in network_test\n    response = _network_test(case, *args)\n  File \"/usr/local/lib/python3.8/dist-packages/schemathesis/runner/impl/core.py\", line 848, in _network_test\n    response = case.call(**kwargs)\n  File \"/usr/local/lib/python3.8/dist-packages/schemathesis/models.py\", line 310, in call\n    response = self.operation.schema.transport.send(\n  File \"/usr/local/lib/python3.8/dist-packages/schemathesis/transports/__init__.py\", line 143, in send\n    response = session.request(**data)  # type: ignore\n  File \"/usr/local/lib/python3.8/dist-packages/requests/sessions.py\", line 589, in request\n    resp = self.send(prep, **send_kwargs)\n  File \"/usr/local/lib/python3.8/dist-packages/requests/sessions.py\", line 703, in send\n    r = adapter.send(request, **kwargs)\n  File \"/usr/local/lib/python3.8/dist-packages/requests/adapters.py\", line 519, in send\n    raise ConnectionError(e, request=request)\nrequests.exceptions.ConnectionError: HTTPSConnectionPool(host='virtserver.swaggerhub.com', port=443): Max retries exceeded with url: /AAYUSHGARGBU/api_iot/1.0.0/temperature/0 (Caused by NewConnectionError('<urllib3.connection.VerifiedHTTPSConnection object at 0x7fcd9d4a98e0>: Failed to establish a new connection: [Errno -3] Temporary failure in name resolution'))"}], "interactions": []}, "elapsed_time": 286.23347779992037, "correlation_id": "9e9b023cdc88464db4a7e01fb2f78a62", "thread_id": 140521139144512, "hypothesis_output": [], "event_type": "AfterExecution"}
{"method": "GET", "path": "/AAYUSHGARGBU/api_iot/1.0.0/temperature/{zoneId}/heater", "verbose_name": "GET /AAYUSHGARGBU/api_iot/1.0.0/temperature/{zoneId}/heater", "relative_path": "/temperature/{zoneId}/heater", "recursion_level": 0, "data_generation_method": ["positive", "negative"], "correlation_id": "1e517605e88a4aee8f827683c67d177b", "thread_id": 140521139144512, "event_type": "BeforeExecution"}
{"method": "GET", "path": "/AAYUSHGARGBU/api_iot/1.0.0/temperature/{zoneId}/heater", "relative_path": "/temperature/{zoneId}/heater", "verbose_name": "GET /AAYUSHGARGBU/api_iot/1.0.0/temperature/{zoneId}/heater", "status": "error", "data_generation_method": ["positive"], "result": {"method": "GET", "path": "/AAYUSHGARGBU/api_iot/1.0.0/temperature/{zoneId}/heater", "verbose_name": "GET /AAYUSHGARGBU/api_iot/1.0.0/temperature/{zoneId}/heater", "has_failures": false, "has_errors": true, "has_logs": false, "is_errored": true, "is_flaky": false, "is_skipped": false, "skip_reason": null, "seed": 228635117958159357331249932965970836514, "data_generation_method": ["P"], "checks": [], "logs": [], "errors": [{"type": "connection_other", "title": "Network Error", "message": "Connection failed", "extras": ["Failed to establish a new connection: [Errno -3] Temporary failure in name resolution"], "exception": "requests.exceptions.ConnectionError: HTTPSConnectionPool(host='virtserver.swaggerhub.com', port=443): Max retries exceeded with url: /AAYUSHGARGBU/api_iot/1.0.0/temperature/0/heater (Caused by NewConnectionError('<urllib3.connection.VerifiedHTTPSConnection object at 0x7fcd9d410610>: Failed to establish a new connection: [Errno -3] Temporary failure in name resolution'))", "exception_with_traceback": "Traceback (most recent call last):\n  File \"/usr/lib/python3/dist-packages/urllib3/connection.py\", line 156, in _new_conn\n    conn = connection.create_connection(\n  File \"/usr/lib/python3/dist-packages/urllib3/util/connection.py\", line 61, in create_connection\n    for res in socket.getaddrinfo(host, port, family, socket.SOCK_STREAM):\n  File \"/usr/lib/python3.8/socket.py\", line 918, in getaddrinfo\n    for res in _socket.getaddrinfo(host, port, family, type, proto, flags):\nsocket.gaierror: [Errno -3] Temporary failure in name resolution\n\nDuring handling of the above exception, another exception occurred:\n\nTraceback (most recent call last):\n  File \"/usr/lib/python3/dist-packages/urllib3/connectionpool.py\", line 665, in urlopen\n    httplib_response = self._make_request(\n  File \"/usr/lib/python3/dist-packages/urllib3/connectionpool.py\", line 376, in _make_request\n    self._validate_conn(conn)\n  File \"/usr/lib/python3/dist-packages/urllib3/connectionpool.py\", line 996, in _validate_conn\n    conn.connect()\n  File \"/usr/lib/python3/dist-packages/urllib3/connection.py\", line 300, in connect\n    conn = self._new_conn()\n  File \"/usr/lib/python3/dist-packages/urllib3/connection.py\", line 168, in _new_conn\n    raise NewConnectionError(\nurllib3.exceptions.NewConnectionError: <urllib3.connection.VerifiedHTTPSConnection object at 0x7fcd9d410610>: Failed to establish a new connection: [Errno -3] Temporary failure in name resolution\n\nDuring handling of the above exception, another exception occurred:\n\nTraceback (most recent call last):\n  File \"/usr/local/lib/python3.8/dist-packages/requests/adapters.py\", line 486, in send\n    resp = conn.urlopen(\n  File \"/usr/lib/python3/dist-packages/urllib3/connectionpool.py\", line 719, in urlopen\n    retries = retries.increment(\n  File \"/usr/lib/python3/dist-packages/urllib3/util/retry.py\", line 436, in increment\n    raise MaxRetryError(_pool, url, error or ResponseError(cause))\nurllib3.exceptions.MaxRetryError: HTTPSConnectionPool(host='virtserver.swaggerhub.com', port=443): Max retries exceeded with url: /AAYUSHGARGBU/api_iot/1.0.0/temperature/0/heater (Caused by NewConnectionError('<urllib3.connection.VerifiedHTTPSConnection object at 0x7fcd9d410610>: Failed to establish a new connection: [Errno -3] Temporary failure in name resolution'))\n\nDuring handling of the above exception, another exception occurred:\n\nTraceback (most recent call last):\n  File \"/usr/local/lib/python3.8/dist-packages/schemathesis/runner/impl/core.py\", line 816, in network_test\n    response = _network_test(case, *args)\n  File \"/usr/local/lib/python3.8/dist-packages/schemathesis/runner/impl/core.py\", line 848, in _network_test\n    response = case.call(**kwargs)\n  File \"/usr/local/lib/python3.8/dist-packages/schemathesis/models.py\", line 310, in call\n    response = self.operation.schema.transport.send(\n  File \"/usr/local/lib/python3.8/dist-packages/schemathesis/transports/__init__.py\", line 143, in send\n    response = session.request(**data)  # type: ignore\n  File \"/usr/local/lib/python3.8/dist-packages/requests/sessions.py\", line 589, in request\n    resp = self.send(prep, **send_kwargs)\n  File \"/usr/local/lib/python3.8/dist-packages/requests/sessions.py\", line 703, in send\n    r = adapter.send(request, **kwargs)\n  File \"/usr/local/lib/python3.8/dist-packages/requests/adapters.py\", line 519, in send\n    raise ConnectionError(e, request=request)\nrequests.exceptions.ConnectionError: HTTPSConnectionPool(host='virtserver.swaggerhub.com', port=443): Max retries exceeded with url: /AAYUSHGARGBU/api_iot/1.0.0/temperature/0/heater (Caused by NewConnectionError('<urllib3.connection.VerifiedHTTPSConnection object at 0x7fcd9d410610>: Failed to establish a new connection: [Errno -3] Temporary failure in name resolution'))"}], "interactions": []}, "elapsed_time": 198.16067659994587, "correlation_id": "1e517605e88a4aee8f827683c67d177b", "thread_id": 140521139144512, "hypothesis_output": [], "event_type": "AfterExecution"}
{"method": "POST", "path": "/AAYUSHGARGBU/api_iot/1.0.0/temperature/{zoneId}/heater/{state}", "verbose_name": "POST /AAYUSHGARGBU/api_iot/1.0.0/temperature/{zoneId}/heater/{state}", "relative_path": "/temperature/{zoneId}/heater/{state}", "recursion_level": 0, "data_generation_method": ["positive", "negative"], "correlation_id": "58e74550353c4c528def904f5b9ed5e4", "thread_id": 140521139144512, "event_type": "BeforeExecution"}
{"method": "POST", "path": "/AAYUSHGARGBU/api_iot/1.0.0/temperature/{zoneId}/heater/{state}", "relative_path": "/temperature/{zoneId}/heater/{state}", "verbose_name": "POST /AAYUSHGARGBU/api_iot/1.0.0/temperature/{zoneId}/heater/{state}", "status": "error", "data_generation_method": ["negative"], "result": {"method": "POST", "path": "/AAYUSHGARGBU/api_iot/1.0.0/temperature/{zoneId}/heater/{state}", "verbose_name": "POST /AAYUSHGARGBU/api_iot/1.0.0/temperature/{zoneId}/heater/{state}", "has_failures": false, "has_errors": true, "has_logs": false, "is_errored": true, "is_flaky": false, "is_skipped": false, "skip_reason": null, "seed": 228635117958159357331249932965970836514, "data_generation_method": ["N"], "checks": [], "logs": [], "errors": [{"type": "connection_other", "title": "Network Error", "message": "Connection failed", "extras": ["Failed to establish a new connection: [Errno -3] Temporary failure in name resolution"], "exception": "requests.exceptions.ConnectionError: HTTPSConnectionPool(host='virtserver.swaggerhub.com', port=443): Max retries exceeded with url: /AAYUSHGARGBU/api_iot/1.0.0/temperature/0/heater/0 (Caused by NewConnectionError('<urllib3.connection.VerifiedHTTPSConnection object at 0x7fcd9d372220>: Failed to establish a new connection: [Errno -3] Temporary failure in name resolution'))", "exception_with_traceback": "Traceback (most recent call last):\n  File \"/usr/lib/python3/dist-packages/urllib3/connection.py\", line 156, in _new_conn\n    conn = connection.create_connection(\n  File \"/usr/lib/python3/dist-packages/urllib3/util/connection.py\", line 61, in create_connection\n    for res in socket.getaddrinfo(host, port, family, socket.SOCK_STREAM):\n  File \"/usr/lib/python3.8/socket.py\", line 918, in getaddrinfo\n    for res in _socket.getaddrinfo(host, port, family, type, proto, flags):\nsocket.gaierror: [Errno -3] Temporary failure in name resolution\n\nDuring handling of the above exception, another exception occurred:\n\nTraceback (most recent call last):\n  File \"/usr/lib/python3/dist-packages/urllib3/connectionpool.py\", line 665, in urlopen\n    httplib_response = self._make_request(\n  File \"/usr/lib/python3/dist-packages/urllib3/connectionpool.py\", line 376, in _make_request\n    self._validate_conn(conn)\n  File \"/usr/lib/python3/dist-packages/urllib3/connectionpool.py\", line 996, in _validate_conn\n    conn.connect()\n  File \"/usr/lib/python3/dist-packages/urllib3/connection.py\", line 300, in connect\n    conn = self._new_conn()\n  File \"/usr/lib/python3/dist-packages/urllib3/connection.py\", line 168, in _new_conn\n    raise NewConnectionError(\nurllib3.exceptions.NewConnectionError: <urllib3.connection.VerifiedHTTPSConnection object at 0x7fcd9d372220>: Failed to establish a new connection: [Errno -3] Temporary failure in name resolution\n\nDuring handling of the above exception, another exception occurred:\n\nTraceback (most recent call last):\n  File \"/usr/local/lib/python3.8/dist-packages/requests/adapters.py\", line 486, in send\n    resp = conn.urlopen(\n  File \"/usr/lib/python3/dist-packages/urllib3/connectionpool.py\", line 719, in urlopen\n    retries = retries.increment(\n  File \"/usr/lib/python3/dist-packages/urllib3/util/retry.py\", line 436, in increment\n    raise MaxRetryError(_pool, url, error or ResponseError(cause))\nurllib3.exceptions.MaxRetryError: HTTPSConnectionPool(host='virtserver.swaggerhub.com', port=443): Max retries exceeded with url: /AAYUSHGARGBU/api_iot/1.0.0/temperature/0/heater/0 (Caused by NewConnectionError('<urllib3.connection.VerifiedHTTPSConnection object at 0x7fcd9d372220>: Failed to establish a new connection: [Errno -3] Temporary failure in name resolution'))\n\nDuring handling of the above exception, another exception occurred:\n\nTraceback (most recent call last):\n  File \"/usr/local/lib/python3.8/dist-packages/schemathesis/runner/impl/core.py\", line 816, in network_test\n    response = _network_test(case, *args)\n  File \"/usr/local/lib/python3.8/dist-packages/schemathesis/runner/impl/core.py\", line 848, in _network_test\n    response = case.call(**kwargs)\n  File \"/usr/local/lib/python3.8/dist-packages/schemathesis/models.py\", line 310, in call\n    response = self.operation.schema.transport.send(\n  File \"/usr/local/lib/python3.8/dist-packages/schemathesis/transports/__init__.py\", line 143, in send\n    response = session.request(**data)  # type: ignore\n  File \"/usr/local/lib/python3.8/dist-packages/requests/sessions.py\", line 589, in request\n    resp = self.send(prep, **send_kwargs)\n  File \"/usr/local/lib/python3.8/dist-packages/requests/sessions.py\", line 703, in send\n    r = adapter.send(request, **kwargs)\n  File \"/usr/local/lib/python3.8/dist-packages/requests/adapters.py\", line 519, in send\n    raise ConnectionError(e, request=request)\nrequests.exceptions.ConnectionError: HTTPSConnectionPool(host='virtserver.swaggerhub.com', port=443): Max retries exceeded with url: /AAYUSHGARGBU/api_iot/1.0.0/temperature/0/heater/0 (Caused by NewConnectionError('<urllib3.connection.VerifiedHTTPSConnection object at 0x7fcd9d372220>: Failed to establish a new connection: [Errno -3] Temporary failure in name resolution'))"}], "interactions": []}, "elapsed_time": 572.6555332000135, "correlation_id": "58e74550353c4c528def904f5b9ed5e4", "thread_id": 140521139144512, "hypothesis_output": ["WARNING: Hypothesis has spent more than five minutes working to shrink a failing example, and stopped because it is making very slow progress.  When you re-run your tests, shrinking will resume and may take this long before aborting again.\nPLEASE REPORT THIS if you can provide a reproducing example, so that we can improve shrinking performance for everyone."], "event_type": "AfterExecution"}
{"method": "GET", "path": "/AAYUSHGARGBU/api_iot/1.0.0/zones", "verbose_name": "GET /AAYUSHGARGBU/api_iot/1.0.0/zones", "relative_path": "/zones", "recursion_level": 0, "data_generation_method": ["positive", "negative"], "correlation_id": "c69ed1c0ed3947f282dfbe8af75d8d32", "thread_id": 140521139144512, "event_type": "BeforeExecution"}
{"method": "GET", "path": "/AAYUSHGARGBU/api_iot/1.0.0/zones", "relative_path": "/zones", "verbose_name": "GET /AAYUSHGARGBU/api_iot/1.0.0/zones", "status": "error", "data_generation_method": ["positive"], "result": {"method": "GET", "path": "/AAYUSHGARGBU/api_iot/1.0.0/zones", "verbose_name": "GET /AAYUSHGARGBU/api_iot/1.0.0/zones", "has_failures": false, "has_errors": true, "has_logs": false, "is_errored": true, "is_flaky": false, "is_skipped": false, "skip_reason": null, "seed": 228635117958159357331249932965970836514, "data_generation_method": ["P"], "checks": [], "logs": [], "errors": [{"type": "connection_other", "title": "Network Error", "message": "Connection failed", "extras": ["Failed to establish a new connection: [Errno -3] Temporary failure in name resolution"], "exception": "requests.exceptions.ConnectionError: HTTPSConnectionPool(host='virtserver.swaggerhub.com', port=443): Max retries exceeded with url: /AAYUSHGARGBU/api_iot/1.0.0/zones (Caused by NewConnectionError('<urllib3.connection.VerifiedHTTPSConnection object at 0x7fcd9d2a9e50>: Failed to establish a new connection: [Errno -3] Temporary failure in name resolution'))", "exception_with_traceback": "Traceback (most recent call last):\n  File \"/usr/lib/python3/dist-packages/urllib3/connection.py\", line 156, in _new_conn\n    conn = connection.create_connection(\n  File \"/usr/lib/python3/dist-packages/urllib3/util/connection.py\", line 61, in create_connection\n    for res in socket.getaddrinfo(host, port, family, socket.SOCK_STREAM):\n  File \"/usr/lib/python3.8/socket.py\", line 918, in getaddrinfo\n    for res in _socket.getaddrinfo(host, port, family, type, proto, flags):\nsocket.gaierror: [Errno -3] Temporary failure in name resolution\n\nDuring handling of the above exception, another exception occurred:\n\nTraceback (most recent call last):\n  File \"/usr/lib/python3/dist-packages/urllib3/connectionpool.py\", line 665, in urlopen\n    httplib_response = self._make_request(\n  File \"/usr/lib/python3/dist-packages/urllib3/connectionpool.py\", line 376, in _make_request\n    self._validate_conn(conn)\n  File \"/usr/lib/python3/dist-packages/urllib3/connectionpool.py\", line 996, in _validate_conn\n    conn.connect()\n  File \"/usr/lib/python3/dist-packages/urllib3/connection.py\", line 300, in connect\n    conn = self._new_conn()\n  File \"/usr/lib/python3/dist-packages/urllib3/connection.py\", line 168, in _new_conn\n    raise NewConnectionError(\nurllib3.exceptions.NewConnectionError: <urllib3.connection.VerifiedHTTPSConnection object at 0x7fcd9d2a9e50>: Failed to establish a new connection: [Errno -3] Temporary failure in name resolution\n\nDuring handling of the above exception, another exception occurred:\n\nTraceback (most recent call last):\n  File \"/usr/local/lib/python3.8/dist-packages/requests/adapters.py\", line 486, in send\n    resp = conn.urlopen(\n  File \"/usr/lib/python3/dist-packages/urllib3/connectionpool.py\", line 719, in urlopen\n    retries = retries.increment(\n  File \"/usr/lib/python3/dist-packages/urllib3/util/retry.py\", line 436, in increment\n    raise MaxRetryError(_pool, url, error or ResponseError(cause))\nurllib3.exceptions.MaxRetryError: HTTPSConnectionPool(host='virtserver.swaggerhub.com', port=443): Max retries exceeded with url: /AAYUSHGARGBU/api_iot/1.0.0/zones (Caused by NewConnectionError('<urllib3.connection.VerifiedHTTPSConnection object at 0x7fcd9d2a9e50>: Failed to establish a new connection: [Errno -3] Temporary failure in name resolution'))\n\nDuring handling of the above exception, another exception occurred:\n\nTraceback (most recent call last):\n  File \"/usr/local/lib/python3.8/dist-packages/schemathesis/runner/impl/core.py\", line 816, in network_test\n    response = _network_test(case, *args)\n  File \"/usr/local/lib/python3.8/dist-packages/schemathesis/runner/impl/core.py\", line 848, in _network_test\n    response = case.call(**kwargs)\n  File \"/usr/local/lib/python3.8/dist-packages/schemathesis/models.py\", line 310, in call\n    response = self.operation.schema.transport.send(\n  File \"/usr/local/lib/python3.8/dist-packages/schemathesis/transports/__init__.py\", line 143, in send\n    response = session.request(**data)  # type: ignore\n  File \"/usr/local/lib/python3.8/dist-packages/requests/sessions.py\", line 589, in request\n    resp = self.send(prep, **send_kwargs)\n  File \"/usr/local/lib/python3.8/dist-packages/requests/sessions.py\", line 703, in send\n    r = adapter.send(request, **kwargs)\n  File \"/usr/local/lib/python3.8/dist-packages/requests/adapters.py\", line 519, in send\n    raise ConnectionError(e, request=request)\nrequests.exceptions.ConnectionError: HTTPSConnectionPool(host='virtserver.swaggerhub.com', port=443): Max retries exceeded with url: /AAYUSHGARGBU/api_iot/1.0.0/zones (Caused by NewConnectionError('<urllib3.connection.VerifiedHTTPSConnection object at 0x7fcd9d2a9e50>: Failed to establish a new connection: [Errno -3] Temporary failure in name resolution'))"}], "interactions": []}, "elapsed_time": 66.05290760006756, "correlation_id": "c69ed1c0ed3947f282dfbe8af75d8d32", "thread_id": 140521139144512, "hypothesis_output": [], "event_type": "AfterExecution"}
{"method": "GET", "path": "/AAYUSHGARGBU/api_iot/1.0.0/zones/{zoneId}/quiet", "verbose_name": "GET /AAYUSHGARGBU/api_iot/1.0.0/zones/{zoneId}/quiet", "relative_path": "/zones/{zoneId}/quiet", "recursion_level": 0, "data_generation_method": ["positive", "negative"], "correlation_id": "7f0fb1ecdad64ce8aebaffb33aa3461e", "thread_id": 140521139144512, "event_type": "BeforeExecution"}
{"method": "GET", "path": "/AAYUSHGARGBU/api_iot/1.0.0/zones/{zoneId}/quiet", "relative_path": "/zones/{zoneId}/quiet", "verbose_name": "GET /AAYUSHGARGBU/api_iot/1.0.0/zones/{zoneId}/quiet", "status": "error", "data_generation_method": ["positive"], "result": {"method": "GET", "path": "/AAYUSHGARGBU/api_iot/1.0.0/zones/{zoneId}/quiet", "verbose_name": "GET /AAYUSHGARGBU/api_iot/1.0.0/zones/{zoneId}/quiet", "has_failures": false, "has_errors": true, "has_logs": false, "is_errored": true, "is_flaky": false, "is_skipped": false, "skip_reason": null, "seed": 228635117958159357331249932965970836514, "data_generation_method": ["P"], "checks": [], "logs": [], "errors": [{"type": "connection_other", "title": "Network Error", "message": "Connection failed", "extras": ["Failed to establish a new connection: [Errno -3] Temporary failure in name resolution"], "exception": "requests.exceptions.ConnectionError: HTTPSConnectionPool(host='virtserver.swaggerhub.com', port=443): Max retries exceeded with url: /AAYUSHGARGBU/api_iot/1.0.0/zones/basement/quiet (Caused by NewConnectionError('<urllib3.connection.VerifiedHTTPSConnection object at 0x7fcd9d26d250>: Failed to establish a new connection: [Errno -3] Temporary failure in name resolution'))", "exception_with_traceback": "Traceback (most recent call last):\n  File \"/usr/lib/python3/dist-packages/urllib3/connection.py\", line 156, in _new_conn\n    conn = connection.create_connection(\n  File \"/usr/lib/python3/dist-packages/urllib3/util/connection.py\", line 61, in create_connection\n    for res in socket.getaddrinfo(host, port, family, socket.SOCK_STREAM):\n  File \"/usr/lib/python3.8/socket.py\", line 918, in getaddrinfo\n    for res in _socket.getaddrinfo(host, port, family, type, proto, flags):\nsocket.gaierror: [Errno -3] Temporary failure in name resolution\n\nDuring handling of the above exception, another exception occurred:\n\nTraceback (most recent call last):\n  File \"/usr/lib/python3/dist-packages/urllib3/connectionpool.py\", line 665, in urlopen\n    httplib_response = self._make_request(\n  File \"/usr/lib/python3/dist-packages/urllib3/connectionpool.py\", line 376, in _make_request\n    self._validate_conn(conn)\n  File \"/usr/lib/python3/dist-packages/urllib3/connectionpool.py\", line 996, in _validate_conn\n    conn.connect()\n  File \"/usr/lib/python3/dist-packages/urllib3/connection.py\", line 300, in connect\n    conn = self._new_conn()\n  File \"/usr/lib/python3/dist-packages/urllib3/connection.py\", line 168, in _new_conn\n    raise NewConnectionError(\nurllib3.exceptions.NewConnectionError: <urllib3.connection.VerifiedHTTPSConnection object at 0x7fcd9d26d250>: Failed to establish a new connection: [Errno -3] Temporary failure in name resolution\n\nDuring handling of the above exception, another exception occurred:\n\nTraceback (most recent call last):\n  File \"/usr/local/lib/python3.8/dist-packages/requests/adapters.py\", line 486, in send\n    resp = conn.urlopen(\n  File \"/usr/lib/python3/dist-packages/urllib3/connectionpool.py\", line 719, in urlopen\n    retries = retries.increment(\n  File \"/usr/lib/python3/dist-packages/urllib3/util/retry.py\", line 436, in increment\n    raise MaxRetryError(_pool, url, error or ResponseError(cause))\nurllib3.exceptions.MaxRetryError: HTTPSConnectionPool(host='virtserver.swaggerhub.com', port=443): Max retries exceeded with url: /AAYUSHGARGBU/api_iot/1.0.0/zones/basement/quiet (Caused by NewConnectionError('<urllib3.connection.VerifiedHTTPSConnection object at 0x7fcd9d26d250>: Failed to establish a new connection: [Errno -3] Temporary failure in name resolution'))\n\nDuring handling of the above exception, another exception occurred:\n\nTraceback (most recent call last):\n  File \"/usr/local/lib/python3.8/dist-packages/schemathesis/runner/impl/core.py\", line 816, in network_test\n    response = _network_test(case, *args)\n  File \"/usr/local/lib/python3.8/dist-packages/schemathesis/runner/impl/core.py\", line 848, in _network_test\n    response = case.call(**kwargs)\n  File \"/usr/local/lib/python3.8/dist-packages/schemathesis/models.py\", line 310, in call\n    response = self.operation.schema.transport.send(\n  File \"/usr/local/lib/python3.8/dist-packages/schemathesis/transports/__init__.py\", line 143, in send\n    response = session.request(**data)  # type: ignore\n  File \"/usr/local/lib/python3.8/dist-packages/requests/sessions.py\", line 589, in request\n    resp = self.send(prep, **send_kwargs)\n  File \"/usr/local/lib/python3.8/dist-packages/requests/sessions.py\", line 703, in send\n    r = adapter.send(request, **kwargs)\n  File \"/usr/local/lib/python3.8/dist-packages/requests/adapters.py\", line 519, in send\n    raise ConnectionError(e, request=request)\nrequests.exceptions.ConnectionError: HTTPSConnectionPool(host='virtserver.swaggerhub.com', port=443): Max retries exceeded with url: /AAYUSHGARGBU/api_iot/1.0.0/zones/basement/quiet (Caused by NewConnectionError('<urllib3.connection.VerifiedHTTPSConnection object at 0x7fcd9d26d250>: Failed to establish a new connection: [Errno -3] Temporary failure in name resolution'))"}], "interactions": []}, "elapsed_time": 220.21943990001455, "correlation_id": "7f0fb1ecdad64ce8aebaffb33aa3461e", "thread_id": 140521139144512, "hypothesis_output": [], "event_type": "AfterExecution"}
{"passed_count": 0, "skipped_count": 0, "failed_count": 0, "errored_count": 15, "has_failures": false, "has_errors": true, "has_logs": false, "is_empty": false, "generic_errors": [], "warnings": [], "total": {}, "running_time": 3392.5000545000657, "thread_id": 140521139144512, "event_type": "Finished"}
